Workbook

Sheet 選手
B1: チーム | C1: No. | D1: 氏名 | E1: 性別
B2: 春日井A | C2: 1 | D2: 峯 徹 | E2: 男
B3: 春日井A | C3: =C2+1 -> 2 | D3: 伊藤 恭浩 | E3: 男
B4: 春日井A | C4: =C3+1 -> 3 | D4: 大嶋 啓嗣 | E4: 男
B5: 春日井A | C5: =C4+1 -> 4 | D5: 田井 泰 | E5: 男
B6: 春日井B | C6: =C5+1 -> 5 | D6: 佃 弘美 | E6: 女
B7: 春日井B | C7: =C6+1 -> 6 | D7: 渡會 あすか | E7: 女
B8: 春日井B | C8: =C7+1 -> 7 | D8: 片桐 志保 | E8: 女
B9: 春日井B | C9: =C8+1 -> 8 | D9: 伊藤 洋子 | E9: 女
B10: 豊明A | C10: =C9+1 -> 9 | D10: 近藤 雄介 | E10: 男
B11: 豊明A | C11: =C10+1 -> 10 | D11: 近藤 治 | E11: 男
B12: 豊明A | C12: =C11+1 -> 11 | D12: 外山 康彦 | E12: 男
B13: 豊明A | C13: =C12+1 -> 12 | D13: 榊原 隆一 | E13: 男
B14: 豊明B | C14: =C13+1 -> 13 | D14: 堀井 恵美子 | E14: 女
... B61: 瀬戸B | C61: =C60+1 -> 60 | D61: 原 由美子 | E61: 女
B62: ダミーA | C62: =C61+1 -> 61
C63: =C62+1 -> 62
C64: =C63+1 -> 63
C65: =C64+1 -> 64

Sheet 記録
B2: =選手!B22 -> 日進B | F2: =選手!B18 -> 日進A | J2: =選手!B14 -> 豊明B | N2: =選手!B10 -> 豊明A | R2: =選手!B6 -> 春日井B | V2: =選手!B2 -> 春日井A | Z2: チーム
B3: =SUM(B5:E5) -> 17 | F3: =SUM(F5:I5) -> 15 | J3: =SUM(J5:M5) -> 14 | N3: =SUM(N5:Q5) -> 12 | R3: =SUM(R5:U5) -> 15 | V3: =SUM(V5:Y5) -> 21 | Z3: チーム合計
B4: =B5+0.1+(IF(B15="〇",1,0)*0.01)+(IF(B14="〇",1,0)*0.001)+(IF(B13="〇",1,0)*0.0001)+(IF(B12="〇",1,0)*0.00001)+(IF(B10="〇",1,0)*0.000001)+(IF(B9="〇",1,0)*0.0000001)+(IF(B8="〇",1,0)*0.00000001)+(IF(B7="〇",1,0)*0.000000001) -> 6.101111 | C4: =C5+0.1+(IF(C15="〇",1,0)*0.01)+(IF(C14="〇",1,0)*0.001)+(IF(C13="〇",1,0)*0.0001)+(IF(C12="〇",1,0)*0.00001)+(IF(C10="〇",1,0)*0.000001)+(IF(C9="〇",1,0)*0.0000001)+(IF(C8="〇",1,0)*0.00000001)+(IF(C7="〇",1,0)*0.000000001) -> 3.101 | D4: =D5+0.1+(IF(D15="〇",1,0)*0.01)+(IF(D14="〇",1,0)*0.001)+(IF(D13="〇",1,0)*0.0001)+(IF(D12="〇",1,0)*0.00001)+(IF(D10="〇",1,0)*0.000001)+(IF(D9="〇",1,0)*0.0000001)+(IF(D8="〇",1,0)*0.00000001)+(IF(D7="〇",1,0)*0.000000001) -> 4.1101011 | E4: =E5+0.1+(IF(E15="〇",1,0)*0.01)+(IF(E14="〇",1,0)*0.001)+(IF(E13="〇",1,0)*0.0001)+(IF(E12="〇",1,0)*0.00001)+(IF(E10="〇",1,0)*0.000001)+(IF(E9="〇",1,0)*0.0000001)+(IF(E8="〇",1,0)*0.00000001)+(IF(E7="〇",1,0)*0.000000001) -> 4.1100101 | F4: =F5+0.1+(IF(F15="〇",1,0)*0.01)+(IF(F14="〇",1,0)*0.001)+(IF(F13="〇",1,0)*0.0001)+(IF(F12="〇",1,0)*0.00001)+(IF(F10="〇",1,0)*0.000001)+(IF(F9="〇",1,0)*0.0000001)+(IF(F8="〇",1,0)*0.00000001)+(IF(F7="〇",1,0)*0.000000001) -> 5.1101011 | G4: =G5+0.1+(IF(G15="〇",1,0)*0.01)+(IF(G14="〇",1,0)*0.001)+(IF(G13="〇",1,0)*0.0001)+(IF(G12="〇",1,0)*0.00001)+(IF(G10="〇",1,0)*0.000001)+(IF(G9="〇",1,0)*0.0000001)+(IF(G8="〇",1,0)*0.00000001)+(IF(G7="〇",1,0)*0.000000001) -> 3.11001 | H4: =H5+0.1+(IF(H15="〇",1,0)*0.01)+(IF(H14="〇",1,0)*0.001)+(IF(H13="〇",1,0)*0.0001)+(IF(H12="〇",1,0)*0.00001)+(IF(H10="〇",1,0)*0.000001)+(IF(H9="〇",1,0)*0.0000001)+(IF(H8="〇",1,0)*0.00000001)+(IF(H7="〇",1,0)*0.000000001) -> 3.100101 | I4: =I5+0.1+(IF(I15="〇",1,0)*0.01)+(IF(I14="〇",1,0)*0.001)+(IF(I13="〇",1,0)*0.0001)+(IF(I12="〇",1,0)*0.00001)+(IF(I10="〇",1,0)*0.000001)+(IF(I9="〇",1,0)*0.0000001)+(IF(I8="〇",1,0)*0.00000001)+(IF(I7="〇",1,0)*0.000000001) -> 4.1001011 | ... Y4: =Y5+0.1+(IF(Y15="〇",1,0)*0.01)+(IF(Y14="〇",1,0)*0.001)+(IF(Y13="〇",1,0)*0.0001)+(IF(Y12="〇",1,0)*0.00001)+(IF(Y10="〇",1,0)*0.000001)+(IF(Y9="〇",1,0)*0.0000001)+(IF(Y8="〇",1,0)*0.00000001)+(IF(Y7="〇",1,0)*0.000000001) -> 5.101101 | Z4: 個人順位用
B5: =B6+B11 -> 6 | C5: =C6+C11 -> 3 | D5: =D6+D11 -> 4 | E5: =E6+E11 -> 4 | F5: =F6+F11 -> 5 | G5: =G6+G11 -> 3 | H5: =H6+H11 -> 3 | I5: =I6+I11 -> 4 | ... Y5: =Y6+Y11 -> 5 | Z5: 個人合計
B6: =COUNTIF(B7:B10,"〇") -> 3 | C6: =COUNTIF(C7:C10,"〇") -> 2 | D6: =COUNTIF(D7:D10,"〇") -> 2 | E6: =COUNTIF(E7:E10,"〇") -> 2 | F6: =COUNTIF(F7:F10,"〇") -> 3 | G6: =COUNTIF(G7:G10,"〇") -> 1 | H6: =COUNTIF(H7:H10,"〇") -> 2 | I6: =COUNTIF(I7:I10,"〇") -> 3 | ... Y6: =COUNTIF(Y7:Y10,"〇") -> 3 | Z6: 2立目 合計
B7: 〇 | C7: 〇 | G7: 〇 | I7: 〇 | K7: 〇 | M7: 〇 | N7: 〇 | O7: 〇 | Q7: 〇 | R7: 〇 | S7: 〇 | V7: 〇 | X7: 〇 | Y7: 〇 | Z7: 4射
B8: 〇 | C8: 〇 | E8: 〇 | F8: 〇 | H8: 〇 | J8: 〇 | L8: 〇 | R8: 〇 | S8: 〇 | U8: 〇 | V8: 〇 | W8: 〇 | X8: 〇 | Y8: 〇 | Z8: 3射
D9: 〇 | E9: 〇 | F9: 〇 | I9: 〇 | K9: 〇 | M9: 〇 | P9: 〇 | S9: 〇 | T9: 〇 | U9: 〇 | V9: 〇 | X9: 〇 | Y9: × | Z9: 2射
B10: 〇 | D10: 〇 | F10: 〇 | H10: 〇 | I10: 〇 | K10: 〇 | N10: 〇 | O10: 〇 | V10: 〇 | Y10: 〇 | Z10: 1射
B11: =COUNTIF(B12:B15,"〇") -> 3 | C11: =COUNTIF(C12:C15,"〇") -> 1 | D11: =COUNTIF(D12:D15,"〇") -> 2 | E11: =COUNTIF(E12:E15,"〇") -> 2 | F11: =COUNTIF(F12:F15,"〇") -> 2 | G11: =COUNTIF(G12:G15,"〇") -> 2 | H11: =COUNTIF(H12:H15,"〇") -> 1 | I11: =COUNTIF(I12:I15,"〇") -> 1 | ... Y11: =COUNTIF(Y12:Y15,"〇") -> 2 | Z11: 1立目 合計
B12: 〇 | E12: 〇 | G12: 〇 | L12: 〇 | M12: 〇 | P12: 〇 | S12: 〇 | U12: 〇 | W12: 〇 | X12: 〇 | Z12: 4射
B13: 〇 | D13: 〇 | F13: 〇 | H13: 〇 | I13: 〇 | J13: 〇 | K13: 〇 | N13: 〇 | R13: 〇 | T13: 〇 | V13: 〇 | X13: 〇 | Y13: 〇 | Z13: 3射
B14: 〇 | C14: 〇 | K14: 〇 | L14: 〇 | P14: 〇 | Q14: 〇 | U14: 〇 | V14: 〇 | W14: 〇 | X14: 〇 | Y14: 〇 | Z14: 2射
D15: 〇 | E15: 〇 | F15: 〇 | G15: 〇 | M15: 〇 | O15: 〇 | Q15: 〇 | R15: 〇 | S15: 〇 | V15: 〇 | Z15: 1射
B16: =IF(選手!C25<>"",選手!C25,"") -> 24 | C16: =IF(選手!C24<>"",選手!C24,"") -> 23 | D16: =IF(選手!C23<>"",選手!C23,"") -> 22 | E16: =IF(選手!C22<>"",選手!C22,"") -> 21 | F16: =IF(選手!C21<>"",選手!C21,"") -> 20 | G16: =IF(選手!C20<>"",選手!C20,"") -> 19 | H16: =IF(選手!C19<>"",選手!C19,"") -> 18 | I16: =IF(選手!C18<>"",選手!C18,"") -> 17 | J16: =IF(選手!C17<>"",選手!C17,"") -> 16 | K16: =IF(選手!C16<>"",選手!C16,"") -> 15 | L16: =IF(選手!C15<>"",選手!C15,"") -> 14 | M16: =IF(選手!C14<>"",選手!C14,"") -> 13 | N16: =IF(選手!C13<>"",選手!C13,"") -> 12 | O16: =IF(選手!C12<>"",選手!C12,"") -> 11 | P16: =IF(選手!C11<>"",選手!C11,"") -> 10 | Q16: =IF(選手!C10<>"",選手!C10,"") -> 9 | R16: =IF(選手!C9<>"",選手!C9,"") -> 8 | S16: =IF(選手!C8<>"",選手!C8,"") -> 7 | T16: =IF(選手!C7<>"",選手!C7,"") -> 6 | U16: =IF(選手!C6<>"",選手!C6,"") -> 5 | V16: =IF(選手!C5<>"",選手!C5,"") -> 4 | W16: =IF(選手!C4<>"",選手!C4,"") -> 3 | X16: =IF(選手!C3<>"",選手!C3,"") -> 2 | Y16: =IF(選手!C2<>"",選手!C2,"") -> 1 | Z16: No.
B17: =IF(選手!E25<>"",選手!E25,"") -> 女 | C17: =IF(選手!E24<>"",選手!E24,"") -> 女 | D17: =IF(選手!E23<>"",選手!E23,"") -> 女 | E17: =IF(選手!E22<>"",選手!E22,"") -> 女 | F17: =IF(選手!E21<>"",選手!E21,"") -> 男 | G17: =IF(選手!E20<>"",選手!E20,"") -> 男 | H17: =IF(選手!E19<>"",選手!E19,"") -> 男 | I17: =IF(選手!E18<>"",選手!E18,"") -> 男 | J17: =IF(選手!E17<>"",選手!E17,"") -> 女 | K17: =IF(選手!E16<>"",選手!E16,"") -> 女 | L17: =IF(選手!E15<>"",選手!E15,"") -> 女 | M17: =IF(選手!E14<>"",選手!E14,"") -> 女 | N17: =IF(選手!E13<>"",選手!E13,"") -> 男 | O17: =IF(選手!E12<>"",選手!E12,"") -> 男 | P17: =IF(選手!E11<>"",選手!E11,"") -> 男 | Q17: =IF(選手!E10<>"",選手!E10,"") -> 男 | R17: =IF(選手!E9<>"",選手!E9,"") -> 女 | S17: =IF(選手!E8<>"",選手!E8,"") -> 女 | T17: =IF(選手!E7<>"",選手!E7,"") -> 女 | U17: =IF(選手!E6<>"",選手!E6,"") -> 女 | V17: =IF(選手!E5<>"",選手!E5,"") -> 男 | W17: =IF(選手!E4<>"",選手!E4,"") -> 男 | X17: =IF(選手!E3<>"",選手!E3,"") -> 男 | Y17: =IF(選手!E2<>"",選手!E2,"") -> 男 | Z17: 性別
B18: =IF(選手!D25<>"",選手!D25,"") -> 谷口 洋子 | C18: =IF(選手!D24<>"",選手!D24,"") -> 入江 美讃 | D18: =IF(選手!D23<>"",選手!D23,"") -> 越後 奈緒美 | E18: =IF(選手!D22<>"",選手!D22,"") -> 後藤 徳子 | F18: =IF(選手!D21<>"",選手!D21,"") -> 志手 俊二 | G18: =IF(選手!D20<>"",選手!D20,"") -> 谷田 直樹 | H18: =IF(選手!D19<>"",選手!D19,"") -> 笠井 大督 | I18: =IF(選手!D18<>"",選手!D18,"") -> 新美 友治 | J18: =IF(選手!D17<>"",選手!D17,"") -> 谷口 祥子 | K18: =IF(選手!D16<>"",選手!D16,"") -> 樋田 良子 | L18: =IF(選手!D15<>"",選手!D15,"") -> 深見 裕子 | M18: =IF(選手!D14<>"",選手!D14,"") -> 堀井 恵美子 | N18: =IF(選手!D13<>"",選手!D13,"") -> 榊原 隆一 | O18: =IF(選手!D12<>"",選手!D12,"") -> 外山 康彦 | P18: =IF(選手!D11<>"",選手!D11,"") -> 近藤 治 | Q18: =IF(選手!D10<>"",選手!D10,"") -> 近藤 雄介 | R18: =IF(選手!D9<>"",選手!D9,"") -> 伊藤 洋子 | S18: =IF(選手!D8<>"",選手!D8,"") -> 片桐 志保 | T18: =IF(選手!D7<>"",選手!D7,"") -> 渡會 あすか | U18: =IF(選手!D6<>"",選手!D6,"") -> 佃 弘美 | V18: =IF(選手!D5<>"",選手!D5,"") -> 田井 泰 | W18: =IF(選手!D4<>"",選手!D4,"") -> 大嶋 啓嗣 | X18: =IF(選手!D3<>"",選手!D3,"") -> 伊藤 恭浩 | Y18: =IF(選手!D2<>"",選手!D2,"") -> 峯 徹 | Z18: 氏 名
J20: =選手!B38 -> 尾張旭B | N20: =選手!B34 -> 尾張旭A | R20: =選手!B30 -> 長久手B | V20: =選手!B26 -> 長久手A | Z20: チーム
J21: =SUM(J23:M23) -> 10 | N21: =SUM(N23:Q23) -> 17 | R21: =SUM(R23:U23) -> 16 | V21: =SUM(V23:Y23) -> 20 | Z21: チーム合計
J22: =J23+0.1+(IF(J33="〇",1,0)*0.01)+(IF(J32="〇",1,0)*0.001)+(IF(J31="〇",1,0)*0.0001)+(IF(J30="〇",1,0)*0.00001)+(IF(J28="〇",1,0)*0.000001)+(IF(J27="〇",1,0)*0.0000001)+(IF(J26="〇",1,0)*0.00000001)+(IF(J25="〇",1,0)*0.000000001) -> 2.11001 | K22: =K23+0.1+(IF(K33="〇",1,0)*0.01)+(IF(K32="〇",1,0)*0.001)+(IF(K31="〇",1,0)*0.0001)+(IF(K30="〇",1,0)*0.00001)+(IF(K28="〇",1,0)*0.000001)+(IF(K27="〇",1,0)*0.0000001)+(IF(K26="〇",1,0)*0.00000001)+(IF(K25="〇",1,0)*0.000000001) -> 3.1010101 | L22: =L23+0.1+(IF(L33="〇",1,0)*0.01)+(IF(L32="〇",1,0)*0.001)+(IF(L31="〇",1,0)*0.0001)+(IF(L30="〇",1,0)*0.00001)+(IF(L28="〇",1,0)*0.000001)+(IF(L27="〇",1,0)*0.0000001)+(IF(L26="〇",1,0)*0.00000001)+(IF(L25="〇",1,0)*0.000000001) -> 3.1101 | M22: =M23+0.1+(IF(M33="〇",1,0)*0.01)+(IF(M32="〇",1,0)*0.001)+(IF(M31="〇",1,0)*0.0001)+(IF(M30="〇",1,0)*0.00001)+(IF(M28="〇",1,0)*0.000001)+(IF(M27="〇",1,0)*0.0000001)+(IF(M26="〇",1,0)*0.00000001)+(IF(M25="〇",1,0)*0.000000001) -> 2.1011 | N22: =N23+0.1+(IF(N33="〇",1,0)*0.01)+(IF(N32="〇",1,0)*0.001)+(IF(N31="〇",1,0)*0.0001)+(IF(N30="〇",1,0)*0.00001)+(IF(N28="〇",1,0)*0.000001)+(IF(N27="〇",1,0)*0.0000001)+(IF(N26="〇",1,0)*0.00000001)+(IF(N25="〇",1,0)*0.000000001) -> 4.1011001 | O22: =O23+0.1+(IF(O33="〇",1,0)*0.01)+(IF(O32="〇",1,0)*0.001)+(IF(O31="〇",1,0)*0.0001)+(IF(O30="〇",1,0)*0.00001)+(IF(O28="〇",1,0)*0.000001)+(IF(O27="〇",1,0)*0.0000001)+(IF(O26="〇",1,0)*0.00000001)+(IF(O25="〇",1,0)*0.000000001) -> 4.1100101 | P22: =P23+0.1+(IF(P33="〇",1,0)*0.01)+(IF(P32="〇",1,0)*0.001)+(IF(P31="〇",1,0)*0.0001)+(IF(P30="〇",1,0)*0.00001)+(IF(P28="〇",1,0)*0.000001)+(IF(P27="〇",1,0)*0.0000001)+(IF(P26="〇",1,0)*0.00000001)+(IF(P25="〇",1,0)*0.000000001) -> 4.101101 | Q22: =Q23+0.1+(IF(Q33="〇",1,0)*0.01)+(IF(Q32="〇",1,0)*0.001)+(IF(Q31="〇",1,0)*0.0001)+(IF(Q30="〇",1,0)*0.00001)+(IF(Q28="〇",1,0)*0.000001)+(IF(Q27="〇",1,0)*0.0000001)+(IF(Q26="〇",1,0)*0.00000001)+(IF(Q25="〇",1,0)*0.000000001) -> 5.101111 | ... Y22: =Y23+0.1+(IF(Y33="〇",1,0)*0.01)+(IF(Y32="〇",1,0)*0.001)+(IF(Y31="〇",1,0)*0.0001)+(IF(Y30="〇",1,0)*0.00001)+(IF(Y28="〇",1,0)*0.000001)+(IF(Y27="〇",1,0)*0.0000001)+(IF(Y26="〇",1,0)*0.00000001)+(IF(Y25="〇",1,0)*0.000000001) -> 5.11011 | Z22: 個人順位用
J23: =J24+J29 -> 2 | K23: =K24+K29 -> 3 | L23: =L24+L29 -> 3 | M23: =M24+M29 -> 2 | N23: =N24+N29 -> 4 | O23: =O24+O29 -> 4 | P23: =P24+P29 -> 4 | Q23: =Q24+Q29 -> 5 | ... Y23: =Y24+Y29 -> 5 | Z23: 個人合計
K24: =COUNTIF(K25:K28,"〇") -> 1 | L24: =COUNTIF(L25:L28,"〇") -> 1 | M24: =COUNTIF(M25:M28,"〇") -> 0 | N24: =COUNTIF(N25:N28,"〇") -> 2 | O24: =COUNTIF(O25:O28,"〇") -> 2 | P24: =COUNTIF(P25:P28,"〇") -> 2 | Q24: =COUNTIF(Q25:Q28,"〇") -> 2 | R24: =COUNTIF(R25:R28,"〇") -> 4 | ... Y24: =COUNTIF(Y25:Y28,"〇") -> 2 | Z24: 2立目 合計
N25: 〇 | Q25: 〇 | R25: 〇 | T25: 〇 | W25: 〇 | Y25: 〇 | Z25: 4射
J26: 〇 | L26: 〇 | O26: 〇 | P26: 〇 | R26: 〇 | U26: 〇 | V26: 〇 | W26: 〇 | X26: 〇 | Y26: 〇 | Z26: 3射
K27: 〇 | N27: 〇 | O27: 〇 | R27: 〇 | T27: 〇 | V27: 〇 | W27: 〇 | Z27: 2射
P28: 〇 | Q28: 〇 | R28: 〇 | S28: 〇 | W28: 〇 | X28: 〇 | Z28: 1射
J29: =COUNTIF(J30:J33,"〇") -> 2 | K29: =COUNTIF(K30:K33,"〇") -> 2 | L29: =COUNTIF(L30:L33,"〇") -> 2 | M29: =COUNTIF(M30:M33,"〇") -> 2 | N29: =COUNTIF(N30:N33,"〇") -> 2 | O29: =COUNTIF(O30:O33,"〇") -> 2 | P29: =COUNTIF(P30:P33,"〇") -> 2 | Q29: =COUNTIF(Q30:Q33,"〇") -> 3 | ... Y29: =COUNTIF(Y30:Y33,"〇") -> 3 | Z29: 1立目 合計
J30: 〇 | K30: 〇 | O30: 〇 | Q30: 〇 | R30: 〇 | T30: 〇 | U30: 〇 | W30: 〇 | X30: 〇 | Y30: 〇 | Z30: 4射
L31: 〇 | M31: 〇 | N31: 〇 | P31: 〇 | Q31: 〇 | R31: 〇 | S31: 〇 | V31: 〇 | W31: 〇 | Y31: 〇 | Z31: 3射
K32: 〇 | M32: 〇 | N32: 〇 | P32: 〇 | Q32: 〇 | R32: 〇 | U32: 〇 | V32: 〇 | X32: 〇 | Z32: 2射
J33: 〇 | L33: 〇 | O33: 〇 | T33: 〇 | W33: 〇 | Y33: 〇 | Z33: 1射
J34: =IF(選手!C41<>"",選手!C41,"") -> 40 | K34: =IF(選手!C40<>"",選手!C40,"") -> 39 | L34: =IF(選手!C39<>"",選手!C39,"") -> 38 | M34: =IF(選手!C38<>"",選手!C38,"") -> 37 | N34: =IF(選手!C37<>"",選手!C37,"") -> 36 | O34: =IF(選手!C36<>"",選手!C36,"") -> 35 | P34: =IF(選手!C35<>"",選手!C35,"") -> 34 | Q34: =IF(選手!C34<>"",選手!C34,"") -> 33 | R34: =IF(選手!C33<>"",選手!C33,"") -> 32 | S34: =IF(選手!C32<>"",選手!C32,"") -> 31 | T34: =IF(選手!C31<>"",選手!C31,"") -> 30 | U34: =IF(選手!C30<>"",選手!C30,"") -> 29 | V34: =IF(選手!C29<>"",選手!C29,"") -> 28 | W34: =IF(選手!C28<>"",選手!C28,"") -> 27 | X34: =IF(選手!C27<>"",選手!C27,"") -> 26 | Y34: =IF(選手!C26<>"",選手!C26,"") -> 25 | Z34: No.
J35: =IF(選手!E41<>"",選手!E41,"") -> 女 | K35: =IF(選手!E40<>"",選手!E40,"") -> 女 | L35: =IF(選手!E39<>"",選手!E39,"") -> 女 | M35: =IF(選手!E38<>"",選手!E38,"") -> 女 | N35: =IF(選手!E37<>"",選手!E37,"") -> 男 | O35: =IF(選手!E36<>"",選手!E36,"") -> 男 | P35: =IF(選手!E35<>"",選手!E35,"") -> 男 | Q35: =IF(選手!E34<>"",選手!E34,"") -> 男 | R35: =IF(選手!E33<>"",選手!E33,"") -> 女 | S35: =IF(選手!E32<>"",選手!E32,"") -> 女 | T35: =IF(選手!E31<>"",選手!E31,"") -> 女 | U35: =IF(選手!E30<>"",選手!E30,"") -> 女 | V35: =IF(選手!E29<>"",選手!E29,"") -> 男 | W35: =IF(選手!E28<>"",選手!E28,"") -> 男 | X35: =IF(選手!E27<>"",選手!E27,"") -> 男 | Y35: =IF(選手!E26<>"",選手!E26,"") -> 男 | Z35: 性別
J36: =IF(選手!D41<>"",選手!D41,"") -> 加藤 康子 | K36: =IF(選手!D40<>"",選手!D40,"") -> 安達 初枝 | L36: =IF(選手!D39<>"",選手!D39,"") -> 北川 裕希子 | M36: =IF(選手!D38<>"",選手!D38,"") -> 田中 沙紀子 | N36: =IF(選手!D37<>"",選手!D37,"") -> 山田 英治 | O36: =IF(選手!D36<>"",選手!D36,"") -> 大竹 誠 | P36: =IF(選手!D35<>"",選手!D35,"") -> 角谷 昌紀 | Q36: =IF(選手!D34<>"",選手!D34,"") -> 西尾 雅司 | R36: =IF(選手!D33<>"",選手!D33,"") -> 野々垣 奈緒子 | S36: =IF(選手!D32<>"",選手!D32,"") -> 水野 三穂 | T36: =IF(選手!D31<>"",選手!D31,"") -> 上平 佳織 | U36: =IF(選手!D30<>"",選手!D30,"") -> 澤田 圭子 | V36: =IF(選手!D27<>"",選手!D27,"") -> 松永 安太郎 | W36: =IF(選手!D29<>"",選手!D29,"") -> 芝田 典久 | X36: =IF(選手!D28<>"",選手!D28,"") -> 山本 三郎 | Y36: =IF(選手!D26<>"",選手!D26,"") -> 葛西 裕文 | Z36: 氏 名
F38: =選手!B58 -> 瀬戸B | J38: =選手!B54 -> 瀬戸A | N38: =選手!B50 -> 愛知A | R38: =選手!B46 -> 西春日井B | V38: =選手!B42 -> 西春日井A | Z38: チーム
F39: =SUM(F41:I41) -> 15 | J39: =SUM(J41:M41) -> 14 | N39: =SUM(N41:Q41) -> 19 | R39: =SUM(R41:U41) -> 13 | V39: =SUM(V41:Y41) -> 7 | Z39: チーム合計
F40: =F41+0.1+(IF(F51="〇",1,0)*0.01)+(IF(F50="〇",1,0)*0.001)+(IF(F49="〇",1,0)*0.0001)+(IF(F48="〇",1,0)*0.00001)+(IF(F46="〇",1,0)*0.000001)+(IF(F45="〇",1,0)*0.0000001)+(IF(F44="〇",1,0)*0.00000001)+(IF(F43="〇",1,0)*0.000000001) -> 3.100101 | G40: =G41+0.1+(IF(G51="〇",1,0)*0.01)+(IF(G50="〇",1,0)*0.001)+(IF(G49="〇",1,0)*0.0001)+(IF(G48="〇",1,0)*0.00001)+(IF(G46="〇",1,0)*0.000001)+(IF(G45="〇",1,0)*0.0000001)+(IF(G44="〇",1,0)*0.00000001)+(IF(G43="〇",1,0)*0.000000001) -> 5.1110101 | H40: =H41+0.1+(IF(H51="〇",1,0)*0.01)+(IF(H50="〇",1,0)*0.001)+(IF(H49="〇",1,0)*0.0001)+(IF(H48="〇",1,0)*0.00001)+(IF(H46="〇",1,0)*0.000001)+(IF(H45="〇",1,0)*0.0000001)+(IF(H44="〇",1,0)*0.00000001)+(IF(H43="〇",1,0)*0.000000001) -> 4.1011001 | I40: =I41+0.1+(IF(I51="〇",1,0)*0.01)+(IF(I50="〇",1,0)*0.001)+(IF(I49="〇",1,0)*0.0001)+(IF(I48="〇",1,0)*0.00001)+(IF(I46="〇",1,0)*0.000001)+(IF(I45="〇",1,0)*0.0000001)+(IF(I44="〇",1,0)*0.00000001)+(IF(I43="〇",1,0)*0.000000001) -> 3.110001 | J40: =J41+0.1+(IF(J51="〇",1,0)*0.01)+(IF(J50="〇",1,0)*0.001)+(IF(J49="〇",1,0)*0.0001)+(IF(J48="〇",1,0)*0.00001)+(IF(J46="〇",1,0)*0.000001)+(IF(J45="〇",1,0)*0.0000001)+(IF(J44="〇",1,0)*0.00000001)+(IF(J43="〇",1,0)*0.000000001) -> 3.1001001 | K40: =K41+0.1+(IF(K51="〇",1,0)*0.01)+(IF(K50="〇",1,0)*0.001)+(IF(K49="〇",1,0)*0.0001)+(IF(K48="〇",1,0)*0.00001)+(IF(K46="〇",1,0)*0.000001)+(IF(K45="〇",1,0)*0.0000001)+(IF(K44="〇",1,0)*0.00000001)+(IF(K43="〇",1,0)*0.000000001) -> 3.10101 | L40: =L41+0.1+(IF(L51="〇",1,0)*0.01)+(IF(L50="〇",1,0)*0.001)+(IF(L49="〇",1,0)*0.0001)+(IF(L48="〇",1,0)*0.00001)+(IF(L46="〇",1,0)*0.000001)+(IF(L45="〇",1,0)*0.0000001)+(IF(L44="〇",1,0)*0.00000001)+(IF(L43="〇",1,0)*0.000000001) -> 6.1111011 | M40: =M41+0.1+(IF(M51="〇",1,0)*0.01)+(IF(M50="〇",1,0)*0.001)+(IF(M49="〇",1,0)*0.0001)+(IF(M48="〇",1,0)*0.00001)+(IF(M46="〇",1,0)*0.000001)+(IF(M45="〇",1,0)*0.0000001)+(IF(M44="〇",1,0)*0.00000001)+(IF(M43="〇",1,0)*0.000000001) -> 2.11 | ... Y40: =Y41+0.1+(IF(Y51="〇",1,0)*0.01)+(IF(Y50="〇",1,0)*0.001)+(IF(Y49="〇",1,0)*0.0001)+(IF(Y48="〇",1,0)*0.00001)+(IF(Y46="〇",1,0)*0.000001)+(IF(Y45="〇",1,0)*0.0000001)+(IF(Y44="〇",1,0)*0.00000001)+(IF(Y43="〇",1,0)*0.000000001) -> 2.1001 | Z40: 個人順位用
F41: =F42+F47 -> 3 | G41: =G42+G47 -> 5 | H41: =H42+H47 -> 4 | I41: =I42+I47 -> 3 | J41: =J42+J47 -> 3 | K41: =K42+K47 -> 3 | L41: =L42+L47 -> 6 | M41: =M42+M47 -> 2 | ... Y41: =Y42+Y47 -> 2 | Z41: 個人合計
F42: =COUNTIF(F43:F46,"〇") -> 2 | G42: =COUNTIF(G43:G46,"〇") -> 2 | H42: =COUNTIF(H43:H46,"〇") -> 2 | I42: =COUNTIF(I43:I46,"〇") -> 2 | J42: =COUNTIF(J43:J46,"〇") -> 2 | K42: =COUNTIF(K43:K46,"〇") -> 1 | L42: =COUNTIF(L43:L46,"〇") -> 3 | M42: =COUNTIF(M43:M46,"〇") -> 1 | ... Y42: =COUNTIF(Y43:Y46,"〇") -> 1 | Z42: 2立目 合計
F43: 〇 | I43: 〇 | J43: 〇 | M43: 〇 | N43: 〇 | O43: 〇 | S43: 〇 | U43: 〇 | Y43: 〇 | Z43: 4射
...

Sheet 成績　団体
C2: チーム順位表：総合 | J2: チーム順位表：男子 | O2: チーム順位表：女子 | T2: チーム成績
C3: 順位 | D3: チーム名 | E3: 総本数 | F3: 男女 | G3: 列2 | H3: 列3 | J3: 順位 | K3: チーム名 | L3: 総本数 | M3: 列1 | O3: 順位 | P3: チーム名 | Q3: 総本数 | R3: 列1 | T3: チーム名 | U3: 男女区別 | V3: 並び順位 | W3: 表示順位 | X3: 総本数 | Y3: 大前 | Z3: ２的 | AA3: ３的 | AB3: 落ち | AC3: 順位計算
B4: =SMALL(V4:V19, 1) -> 1 | C4: =SMALL(W4:W19, 1) -> 1 | D4: =INDEX(T:T,MATCH(B4,V:V,0)) -> 春日井A | E4: =IF(D4="","",INDEX(X:X,MATCH(D4,T:T,0))) -> 21 | F4: =IF(D4="","",INDEX(U:U,MATCH(D4,T:T,0))) -> 男 | G4: =IF($F4="男",ROW(),"") -> 4 | H4: =IF($F4="女",ROW(),"") | J4: =IF(K4="","",_xlfn.RANK.EQ(M4,M4:M19)) -> 1 | K4: =IF(COUNT(G:G)<ROW(A1),"",INDEX(D:D,SMALL(G:G,ROW(A1)))) -> 春日井A | L4: =IF(K4="","",INDEX(E:E,MATCH(K4,D:D,0))) -> 21 | M4: =IF(K4="","",INDEX(AC:AC,MATCH(K4,T:T,0))) -> 21.5637 | O4: =IF(P4="","",_xlfn.RANK.EQ(R4,R4:R19)) -> 1 | P4: =IF(COUNT(H:H)<ROW(A1),"",INDEX(D:D,SMALL(H:H,ROW(A1)))) -> 日進B | Q4: =IF(P4="","",INDEX(E:E,MATCH(P4,D:D,0))) -> 17 | R4: =IF(P4="","",INDEX(AC:AC,MATCH(P4,T:T,0))) -> 17.4436 | T4: =IF(選手!B2="","",選手!B2) -> 春日井A | U4: =IF(COUNTIF(選手!E2:E5,"男")>0,"男","女") -> 男 | V4: =W4 -> 1 | W4: =_xlfn.RANK.EQ(AC4,AC4:AC19) -> 1 | X4: =SUM(Y4:AB4) -> 21 | Y4: =記録!Y5 -> 5 | Z4: =記録!X5 -> 6 | AA4: =記録!W5 -> 3 | AB4: =記録!V5 -> 7 | AC4: =X4+Y4*0.1+Z4*0.01+AA4*0.001+AB4*0.0001 -> 21.5637
B5: =SMALL(V4:V19, 2) -> 2 | C5: =SMALL(W4:W19, 2) -> 2 | D5: =INDEX(T:T,MATCH(B5,V:V,0)) -> 長久手A | E5: =IF(D5="","",INDEX(X:X,MATCH(D5,T:T,0))) -> 20 | F5: =IF(D5="","",INDEX(U:U,MATCH(D5,T:T,0))) -> 男 | G5: =IF($F5="男",ROW(),"") -> 5 | H5: =IF($F5="女",ROW(),"") | J5: =IF(K5="","",_xlfn.RANK.EQ(M5,M4:M19)) -> 2 | K5: =IF(COUNT(G:G)<ROW(A2),"",INDEX(D:D,SMALL(G:G,ROW(A2)))) -> 長久手A | L5: =IF(K5="","",INDEX(E:E,MATCH(K5,D:D,0))) -> 20 | M5: =IF(K5="","",INDEX(AC:AC,MATCH(K5,T:T,0))) -> 20.5474 | O5: =IF(P5="","",_xlfn.RANK.EQ(R5,R4:R19)) -> 2 | P5: =IF(COUNT(H:H)<ROW(A2),"",INDEX(D:D,SMALL(H:H,ROW(A2)))) -> 長久手B | Q5: =IF(P5="","",INDEX(E:E,MATCH(P5,D:D,0))) -> 16 | R5: =IF(P5="","",INDEX(AC:AC,MATCH(P5,T:T,0))) -> 16.3427 | T5: =IF(選手!B6="","",選手!B6) -> 春日井B | U5: =IF(COUNTIF(選手!E6:E9,"男")>0,"男","女") -> 女 | V5: =W5+COUNTIF(W4:W5,W5)-1 -> 8 | W5: =_xlfn.RANK.EQ(AC5,AC4:AC19) -> 8 | X5: =SUM(Y5:AB5) -> 15 | Y5: =記録!U5 -> 4 | Z5: =記録!T5 -> 2 | AA5: =記録!S5 -> 5 | AB5: =記録!R5 -> 4 | AC5: =X5+Y5*0.1+Z5*0.01+AA5*0.001+AB5*0.0001 -> 15.4254
B6: =SMALL(V4:V19, 3) -> 3 | C6: =SMALL(W4:W19, 3) -> 3 | D6: =INDEX(T:T,MATCH(B6,V:V,0)) -> 愛知A | E6: =IF(D6="","",INDEX(X:X,MATCH(D6,T:T,0))) -> 19 | F6: =IF(D6="","",INDEX(U:U,MATCH(D6,T:T,0))) -> 男 | G6: =IF($F6="男",ROW(),"") -> 6 | H6: =IF($F6="女",ROW(),"") | J6: =IF(K6="","",_xlfn.RANK.EQ(M6,M4:M19)) -> 3 | K6: =IF(COUNT(G:G)<ROW(A3),"",INDEX(D:D,SMALL(G:G,ROW(A3)))) -> 愛知A | L6: =IF(K6="","",INDEX(E:E,MATCH(K6,D:D,0))) -> 19 | M6: =IF(K6="","",INDEX(AC:AC,MATCH(K6,T:T,0))) -> 19.4456 | O6: =IF(P6="","",_xlfn.RANK.EQ(R6,R4:R19)) -> 3 | P6: =IF(COUNT(H:H)<ROW(A3),"",INDEX(D:D,SMALL(H:H,ROW(A3)))) -> 春日井B | Q6: =IF(P6="","",INDEX(E:E,MATCH(P6,D:D,0))) -> 15 | R6: =IF(P6="","",INDEX(AC:AC,MATCH(P6,T:T,0))) -> 15.4254 | T6: =IF(選手!B10="","",選手!B10) -> 豊明A | U6: =IF(COUNTIF(選手!E10:E13,"男")>0,"男","女") -> 男 | V6: =W6+COUNTIF(W4:W6,W6)-1 -> 13 | W6: =_xlfn.RANK.EQ(AC6,AC4:AC19) -> 13 | X6: =SUM(Y6:AB6) -> 12 | Y6: =記録!Q5 -> 3 | Z6: =記録!P5 -> 3 | AA6: =記録!O5 -> 3 | AB6: =記録!N5 -> 3 | AC6: =X6+Y6*0.1+Z6*0.01+AA6*0.001+AB6*0.0001 -> 12.3333
B7: =SMALL(V4:V19, 4) -> 4 | C7: =SMALL(W4:W19, 4) -> 4 | D7: =INDEX(T:T,MATCH(B7,V:V,0)) -> 尾張旭A | E7: =IF(D7="","",INDEX(X:X,MATCH(D7,T:T,0))) -> 17 | F7: =IF(D7="","",INDEX(U:U,MATCH(D7,T:T,0))) -> 男 | G7: =IF($F7="男",ROW(),"") -> 7 | H7: =IF($F7="女",ROW(),"") | J7: =IF(K7="","",_xlfn.RANK.EQ(M7,M4:M19)) -> 4 | K7: =IF(COUNT(G:G)<ROW(A4),"",INDEX(D:D,SMALL(G:G,ROW(A4)))) -> 尾張旭A | L7: =IF(K7="","",INDEX(E:E,MATCH(K7,D:D,0))) -> 17 | M7: =IF(K7="","",INDEX(AC:AC,MATCH(K7,T:T,0))) -> 17.5444 | O7: =IF(P7="","",_xlfn.RANK.EQ(R7,R4:R19)) -> 4 | P7: =IF(COUNT(H:H)<ROW(A4),"",INDEX(D:D,SMALL(H:H,ROW(A4)))) -> 瀬戸B | Q7: =IF(P7="","",INDEX(E:E,MATCH(P7,D:D,0))) -> 15 | R7: =IF(P7="","",INDEX(AC:AC,MATCH(P7,T:T,0))) -> 15.3453 | T7: =IF(選手!B14="","",選手!B14) -> 豊明B | U7: =IF(COUNTIF(選手!E14:E17,"男")>0,"男","女") -> 女 | V7: =W7+COUNTIF(W4:W7,W7)-1 -> 10 | W7: =_xlfn.RANK.EQ(AC7,AC4:AC19) -> 10 | X7: =SUM(Y7:AB7) -> 14 | Y7: =記録!M5 -> 4 | Z7: =記録!L5 -> 3 | AA7: =記録!K5 -> 5 | AB7: =記録!J5 -> 2 | AC7: =X7+Y7*0.1+Z7*0.01+AA7*0.001+AB7*0.0001 -> 14.4352
B8: =SMALL(V4:V19, 5) -> 5 | C8: =SMALL(W4:W19, 5) -> 5 | D8: =INDEX(T:T,MATCH(B8,V:V,0)) -> 日進B | E8: =IF(D8="","",INDEX(X:X,MATCH(D8,T:T,0))) -> 17 | F8: =IF(D8="","",INDEX(U:U,MATCH(D8,T:T,0))) -> 女 | G8: =IF($F8="男",ROW(),"") | H8: =IF($F8="女",ROW(),"") -> 8 | J8: =IF(K8="","",_xlfn.RANK.EQ(M8,M4:M19)) -> 5 | K8: =IF(COUNT(G:G)<ROW(A5),"",INDEX(D:D,SMALL(G:G,ROW(A5)))) -> 日進A | L8: =IF(K8="","",INDEX(E:E,MATCH(K8,D:D,0))) -> 15 | M8: =IF(K8="","",INDEX(AC:AC,MATCH(K8,T:T,0))) -> 15.4335 | O8: =IF(P8="","",_xlfn.RANK.EQ(R8,R4:R19)) -> 5 | P8: =IF(COUNT(H:H)<ROW(A5),"",INDEX(D:D,SMALL(H:H,ROW(A5)))) -> 豊明B | Q8: =IF(P8="","",INDEX(E:E,MATCH(P8,D:D,0))) -> 14 | R8: =IF(P8="","",INDEX(AC:AC,MATCH(P8,T:T,0))) -> 14.4352 | T8: =IF(選手!B1="","",選手!B18) -> 日進A | U8: =IF(COUNTIF(選手!E18:E21,"男")>0,"男","女") -> 男 | V8: =W8+COUNTIF(W4:W8,W8)-1 -> 7 | W8: =_xlfn.RANK.EQ(AC8,AC4:AC19) -> 7 | X8: =SUM(Y8:AB8) -> 15 | Y8: =記録!I5 -> 4 | Z8: =記録!H5 -> 3 | AA8: =記録!G5 -> 3 | AB8: =記録!F5 -> 5 | AC8: =X8+Y8*0.1+Z8*0.01+AA8*0.001+AB8*0.0001 -> 15.4335
B9: =SMALL(V4:V19, 6) -> 6 | C9: =SMALL(W4:W19, 6) -> 6 | D9: =INDEX(T:T,MATCH(B9,V:V,0)) -> 長久手B | E9: =IF(D9="","",INDEX(X:X,MATCH(D9,T:T,0))) -> 16 | F9: =IF(D9="","",INDEX(U:U,MATCH(D9,T:T,0))) -> 女 | G9: =IF($F9="男",ROW(),"") | H9: =IF($F9="女",ROW(),"") -> 9 | J9: =IF(K9="","",_xlfn.RANK.EQ(M9,M4:M19)) -> 6 | K9: =IF(COUNT(G:G)<ROW(A6),"",INDEX(D:D,SMALL(G:G,ROW(A6)))) -> 瀬戸A | L9: =IF(K9="","",INDEX(E:E,MATCH(K9,D:D,0))) -> 14 | M9: =IF(K9="","",INDEX(AC:AC,MATCH(K9,T:T,0))) -> 14.2633 | O9: =IF(P9="","",_xlfn.RANK.EQ(R9,R4:R19)) -> 6 | P9: =IF(COUNT(H:H)<ROW(A6),"",INDEX(D:D,SMALL(H:H,ROW(A6)))) -> 西春日井B | Q9: =IF(P9="","",INDEX(E:E,MATCH(P9,D:D,0))) -> 13 | R9: =IF(P9="","",INDEX(AC:AC,MATCH(P9,T:T,0))) -> 13.5341 | T9: =IF(選手!B22="","",選手!B22) -> 日進B | U9: =IF(COUNTIF(選手!E22:E25,"男")>0,"男","女") -> 女 | V9: =W9+COUNTIF(W4:W9,W9)-1 -> 5 | W9: =_xlfn.RANK.EQ(AC9,AC4:AC19) -> 5 | X9: =SUM(Y9:AB9) -> 17 | Y9: =記録!E5 -> 4 | Z9: =記録!D5 -> 4 | AA9: =記録!C5 -> 3 | AB9: =記録!B5 -> 6 | AC9: =X9+Y9*0.1+Z9*0.01+AA9*0.001+AB9*0.0001 -> 17.4436
B10: =SMALL(V4:V19, 7) -> 7 | C10: =SMALL(W4:W19, 7) -> 7 | D10: =INDEX(T:T,MATCH(B10,V:V,0)) -> 日進A | E10: =IF(D10="","",INDEX(X:X,MATCH(D10,T:T,0))) -> 15 | F10: =IF(D10="","",INDEX(U:U,MATCH(D10,T:T,0))) -> 男 | G10: =IF($F10="男",ROW(),"") -> 10 | H10: =IF($F10="女",ROW(),"") | J10: =IF(K10="","",_xlfn.RANK.EQ(M10,M4:M19)) -> 7 | K10: =IF(COUNT(G:G)<ROW(A7),"",INDEX(D:D,SMALL(G:G,ROW(A7)))) -> 豊明A | L10: =IF(K10="","",INDEX(E:E,MATCH(K10,D:D,0))) -> 12 | M10: =IF(K10="","",INDEX(AC:AC,MATCH(K10,T:T,0))) -> 12.3333 | O10: =IF(P10="","",_xlfn.RANK.EQ(R10,R4:R19)) -> 7 | P10: =IF(COUNT(H:H)<ROW(A7),"",INDEX(D:D,SMALL(H:H,ROW(A7)))) -> 尾張旭B | Q10: =IF(P10="","",INDEX(E:E,MATCH(P10,D:D,0))) -> 10 | R10: =IF(P10="","",INDEX(AC:AC,MATCH(P10,T:T,0))) -> 10.2332 | T10: =IF(選手!B26="","",選手!B26) -> 長久手A | U10: =IF(COUNTIF(選手!E26:E29,"男")>0,"男","女") -> 男 | V10: =W10+COUNTIF(W4:W10,W10)-1 -> 2 | W10: =_xlfn.RANK.EQ(AC10,AC4:AC19) -> 2 | X10: =SUM(Y10:AB10) -> 20 | Y10: =記録!Y23 -> 5 | Z10: =記録!X23 -> 4 | AA10: =記録!W23 -> 7 | AB10: =記録!V23 -> 4 | AC10: =X10+Y10*0.1+Z10*0.01+AA10*0.001+AB10*0.0001 -> 20.5474
B11: =SMALL(V4:V19, 8) -> 8 | C11: =SMALL(W4:W19, 8) -> 8 | D11: =INDEX(T:T,MATCH(B11,V:V,0)) -> 春日井B | E11: =IF(D11="","",INDEX(X:X,MATCH(D11,T:T,0))) -> 15 | F11: =IF(D11="","",INDEX(U:U,MATCH(D11,T:T,0))) -> 女 | G11: =IF($F11="男",ROW(),"") | H11: =IF($F11="女",ROW(),"") -> 11 | J11: =IF(K11="","",_xlfn.RANK.EQ(M11,M4:M19)) -> 8 | K11: =IF(COUNT(G:G)<ROW(A8),"",INDEX(D:D,SMALL(G:G,ROW(A8)))) -> 西春日井A | L11: =IF(K11="","",INDEX(E:E,MATCH(K11,D:D,0))) -> 7 | M11: =IF(K11="","",INDEX(AC:AC,MATCH(K11,T:T,0))) -> 7.2221 | O11: =IF(P11="","",_xlfn.RANK.EQ(R11,R4:R19)) | P11: =IF(COUNT(H:H)<ROW(A8),"",INDEX(D:D,SMALL(H:H,ROW(A8)))) | Q11: =IF(P11="","",INDEX(E:E,MATCH(P11,D:D,0))) | R11: =IF(P11="","",INDEX(AC:AC,MATCH(P11,T:T,0))) | T11: =IF(選手!B30="","",選手!B30) -> 長久手B | U11: =IF(COUNTIF(選手!E30:E33,"男")>0,"男","女") -> 女 | V11: =W11+COUNTIF(W4:W11,W11)-1 -> 6 | W11: =_xlfn.RANK.EQ(AC11,AC4:AC19) -> 6 | X11: =SUM(Y11:AB11) -> 16 | Y11: =記録!U23 -> 3 | Z11: =記録!T23 -> 4 | AA11: =記録!S23 -> 2 | AB11: =記録!R23 -> 7 | AC11: =X11+Y11*0.1+Z11*0.01+AA11*0.001+AB11*0.0001 -> 16.3427
B12: =SMALL(V4:V19, 9) -> 9 | C12: =SMALL(W4:W19, 9) -> 9 | D12: =INDEX(T:T,MATCH(B12,V:V,0)) -> 瀬戸B | E12: =IF(D12="","",INDEX(X:X,MATCH(D12,T:T,0))) -> 15 | F12: =IF(D12="","",INDEX(U:U,MATCH(D12,T:T,0))) -> 女 | G12: =IF($F12="男",ROW(),"") | H12: =IF($F12="女",ROW(),"") -> 12 | J12: =IF(K12="","",_xlfn.RANK.EQ(M12,M4:M19)) | K12: =IF(COUNT(G:G)<ROW(A9),"",INDEX(D:D,SMALL(G:G,ROW(A9)))) | L12: =IF(K12="","",INDEX(E:E,MATCH(K12,D:D,0))) | M12: =IF(K12="","",INDEX(AC:AC,MATCH(K12,T:T,0))) | O12: =IF(P12="","",_xlfn.RANK.EQ(R12,R4:R19)) | P12: =IF(COUNT(H:H)<ROW(A9),"",INDEX(D:D,SMALL(H:H,ROW(A9)))) | Q12: =IF(P12="","",INDEX(E:E,MATCH(P12,D:D,0))) | R12: =IF(P12="","",INDEX(AC:AC,MATCH(P12,T:T,0))) | T12: =IF(選手!B34="","",選手!B34) -> 尾張旭A | U12: =IF(COUNTIF(選手!E34:E37,"男")>0,"男","女") -> 男 | V12: =W12+COUNTIF(W4:W12,W12)-1 -> 4 | W12: =_xlfn.RANK.EQ(AC12,AC4:AC19) -> 4 | X12: =SUM(Y12:AB12) -> 17 | Y12: =記録!Q23 -> 5 | Z12: =記録!P23 -> 4 | AA12: =記録!O23 -> 4 | AB12: =記録!N23 -> 4 | AC12: =X12+Y12*0.1+Z12*0.01+AA12*0.001+AB12*0.0001 -> 17.5444
B13: =SMALL(V4:V19, 10) -> 10 | C13: =SMALL(W4:W19, 10) -> 10 | D13: =INDEX(T:T,MATCH(B13,V:V,0)) -> 豊明B | E13: =IF(D13="","",INDEX(X:X,MATCH(D13,T:T,0))) -> 14 | F13: =IF(D13="","",INDEX(U:U,MATCH(D13,T:T,0))) -> 女 | G13: =IF($F13="男",ROW(),"") | H13: =IF($F13="女",ROW(),"") -> 13 | J13: =IF(K13="","",_xlfn.RANK.EQ(M13,M4:M19)) | K13: =IF(COUNT(G:G)<ROW(A10),"",INDEX(D:D,SMALL(G:G,ROW(A10)))) | L13: =IF(K13="","",INDEX(E:E,MATCH(K13,D:D,0))) | M13: =IF(K13="","",INDEX(AC:AC,MATCH(K13,T:T,0))) | O13: =IF(P13="","",_xlfn.RANK.EQ(R13,R4:R19)) | P13: =IF(COUNT(H:H)<ROW(A10),"",INDEX(D:D,SMALL(H:H,ROW(A10)))) | Q13: =IF(P13="","",INDEX(E:E,MATCH(P13,D:D,0))) | R13: =IF(P13="","",INDEX(AC:AC,MATCH(P13,T:T,0))) | T13: =IF(選手!B38="","",選手!B38) -> 尾張旭B | U13: =IF(COUNTIF(選手!E38:E41,"男")>0,"男","女") -> 女 | V13: =W13+COUNTIF(W4:W13,W13)-1 -> 14 | W13: =_xlfn.RANK.EQ(AC13,AC4:AC19) -> 14 | X13: =SUM(Y13:AB13) -> 10 | Y13: =記録!M23 -> 2 | Z13: =記録!L23 -> 3 | AA13: =記録!K23 -> 3 | AB13: =記録!J23 -> 2 | AC13: =X13+Y13*0.1+Z13*0.01+AA13*0.001+AB13*0.0001 -> 10.2332
B14: =SMALL(V4:V19, 11) -> 11 | C14: =SMALL(W4:W19, 11) -> 11 | D14: =INDEX(T:T,MATCH(B14,V:V,0)) -> 瀬戸A | E14: =IF(D14="","",INDEX(X:X,MATCH(D14,T:T,0))) -> 14 | F14: =IF(D14="","",INDEX(U:U,MATCH(D14,T:T,0))) -> 男 | G14: =IF($F14="男",ROW(),"") -> 14 | H14: =IF($F14="女",ROW(),"") | J14: =IF(K14="","",_xlfn.RANK.EQ(M14,M4:M19)) | K14: =IF(COUNT(G:G)<ROW(A11),"",INDEX(D:D,SMALL(G:G,ROW(A11)))) | L14: =IF(K14="","",INDEX(E:E,MATCH(K14,D:D,0))) | M14: =IF(K14="","",INDEX(AC:AC,MATCH(K14,T:T,0))) | O14: =IF(P14="","",_xlfn.RANK.EQ(R14,R4:R19)) | P14: =IF(COUNT(H:H)<ROW(A11),"",INDEX(D:D,SMALL(H:H,ROW(A11)))) | Q14: =IF(P14="","",INDEX(E:E,MATCH(P14,D:D,0))) | R14: =IF(P14="","",INDEX(AC:AC,MATCH(P14,T:T,0))) | T14: =IF(選手!B42="","",選手!B42) -> 西春日井A | U14: =IF(COUNTIF(選手!E42:E45,"男")>0,"男","女") -> 男 | V14: =W14+COUNTIF(W4:W14,W14)-1 -> 15 | W14: =_xlfn.RANK.EQ(AC14,AC4:AC19) -> 15 | X14: =SUM(Y14:AB14) -> 7 | Y14: =記録!Y41 -> 2 | Z14: =記録!X41 -> 2 | AA14: =記録!W41 -> 2 | AB14: =記録!V41 -> 1 | AC14: =X14+Y14*0.1+Z14*0.01+AA14*0.001+AB14*0.0001 -> 7.2221
B15: =SMALL(V4:V19, 12) -> 12 | C15: =SMALL(W4:W19, 12) -> 12 | D15: =INDEX(T:T,MATCH(B15,V:V,0)) -> 西春日井B | E15: =IF(D15="","",INDEX(X:X,MATCH(D15,T:T,0))) -> 13 | F15: =IF(D15="","",INDEX(U:U,MATCH(D15,T:T,0))) -> 女 | G15: =IF($F15="男",ROW(),"") | H15: =IF($F15="女",ROW(),"") -> 15 | J15: =IF(K15="","",_xlfn.RANK.EQ(M15,M4:M19)) | K15: =IF(COUNT(G:G)<ROW(A12),"",INDEX(D:D,SMALL(G:G,ROW(A12)))) | L15: =IF(K15="","",INDEX(E:E,MATCH(K15,D:D,0))) | M15: =IF(K15="","",INDEX(AC:AC,MATCH(K15,T:T,0))) | O15: =IF(P15="","",_xlfn.RANK.EQ(R15,R4:R19)) | P15: =IF(COUNT(H:H)<ROW(A12),"",INDEX(D:D,SMALL(H:H,ROW(A12)))) | Q15: =IF(P15="","",INDEX(E:E,MATCH(P15,D:D,0))) | R15: =IF(P15="","",INDEX(AC:AC,MATCH(P15,T:T,0))) | T15: =IF(選手!B46="","",選手!B46) -> 西春日井B | U15: =IF(COUNTIF(選手!E46:E49,"男")>0,"男","女") -> 女 | V15: =W15+COUNTIF(W4:W15,W15)-1 -> 12 | W15: =_xlfn.RANK.EQ(AC15,AC4:AC19) -> 12 | X15: =SUM(Y15:AB15) -> 13 | Y15: =記録!U41 -> 5 | Z15: =記録!T41 -> 3 | AA15: =記録!S41 -> 4 | AB15: =記録!R41 -> 1 | AC15: =X15+Y15*0.1+Z15*0.01+AA15*0.001+AB15*0.0001 -> 13.5341
B16: =SMALL(V4:V19, 13) -> 13 | C16: =SMALL(W4:W19, 13) -> 13 | D16: =INDEX(T:T,MATCH(B16,V:V,0)) -> 豊明A | E16: =IF(D16="","",INDEX(X:X,MATCH(D16,T:T,0))) -> 12 | F16: =IF(D16="","",INDEX(U:U,MATCH(D16,T:T,0))) -> 男 | G16: =IF($F16="男",ROW(),"") -> 16 | H16: =IF($F16="女",ROW(),"") | J16: =IF(K16="","",_xlfn.RANK.EQ(M16,M4:M19)) | K16: =IF(COUNT(G:G)<ROW(A13),"",INDEX(D:D,SMALL(G:G,ROW(A13)))) | L16: =IF(K16="","",INDEX(E:E,MATCH(K16,D:D,0))) | M16: =IF(K16="","",INDEX(AC:AC,MATCH(K16,T:T,0))) | O16: =IF(P16="","",_xlfn.RANK.EQ(R16,R4:R19)) | P16: =IF(COUNT(H:H)<ROW(A13),"",INDEX(D:D,SMALL(H:H,ROW(A13)))) | Q16: =IF(P16="","",INDEX(E:E,MATCH(P16,D:D,0))) | R16: =IF(P16="","",INDEX(AC:AC,MATCH(P16,T:T,0))) | T16: =IF(選手!B50="","",選手!B50) -> 愛知A | U16: =IF(COUNTIF(選手!E50:E53,"男")>0,"男","女") -> 男 | V16: =W16+COUNTIF(W4:W16,W16)-1 -> 3 | W16: =_xlfn.RANK.EQ(AC16,AC4:AC19) -> 3 | X16: =SUM(Y16:AB16) -> 19 | Y16: =記録!Q41 -> 4 | Z16: =記録!P41 -> 4 | AA16: =記録!O41 -> 5 | AB16: =記録!N41 -> 6 | AC16: =X16+Y16*0.1+Z16*0.01+AA16*0.001+AB16*0.0001 -> 19.4456
B17: =SMALL(V4:V19, 14) -> 14 | C17: =SMALL(W4:W19, 14) -> 14 | D17: =INDEX(T:T,MATCH(B17,V:V,0)) -> 尾張旭B | E17: =IF(D17="","",INDEX(X:X,MATCH(D17,T:T,0))) -> 10 | F17: =IF(D17="","",INDEX(U:U,MATCH(D17,T:T,0))) -> 女 | G17: =IF($F17="男",ROW(),"") | H17: =IF($F17="女",ROW(),"") -> 17 | J17: =IF(K17="","",_xlfn.RANK.EQ(M17,M4:M19)) | K17: =IF(COUNT(G:G)<ROW(A14),"",INDEX(D:D,SMALL(G:G,ROW(A14)))) | L17: =IF(K17="","",INDEX(E:E,MATCH(K17,D:D,0))) | M17: =IF(K17="","",INDEX(AC:AC,MATCH(K17,T:T,0))) | O17: =IF(P17="","",_xlfn.RANK.EQ(R17,R4:R19)) | P17: =IF(COUNT(H:H)<ROW(A14),"",INDEX(D:D,SMALL(H:H,ROW(A14)))) | Q17: =IF(P17="","",INDEX(E:E,MATCH(P17,D:D,0))) | R17: =IF(P17="","",INDEX(AC:AC,MATCH(P17,T:T,0))) | T17: =IF(選手!B54="","",選手!B54) -> 瀬戸A | U17: =IF(COUNTIF(選手!E54:E57,"男")>0,"男","女") -> 男 | V17: =W17+COUNTIF(W4:W17,W17)-1 -> 11 | W17: =_xlfn.RANK.EQ(AC17,AC4:AC19) -> 11 | X17: =SUM(Y17:AB17) -> 14 | Y17: =記録!M41 -> 2 | Z17: =記録!L41 -> 6 | AA17: =記録!K41 -> 3 | AB17: =記録!J41 -> 3 | AC17: =X17+Y17*0.1+Z17*0.01+AA17*0.001+AB17*0.0001 -> 14.2633
B18: =SMALL(V4:V19, 15) -> 15 | C18: =SMALL(W4:W19, 15) -> 15 | D18: =INDEX(T:T,MATCH(B18,V:V,0)) -> 西春日井A | E18: =IF(D18="","",INDEX(X:X,MATCH(D18,T:T,0))) -> 7 | F18: =IF(D18="","",INDEX(U:U,MATCH(D18,T:T,0))) -> 男 | G18: =IF($F18="男",ROW(),"") -> 18 | H18: =IF($F18="女",ROW(),"") | J18: =IF(K18="","",_xlfn.RANK.EQ(M18,M4:M19)) | K18: =IF(COUNT(G:G)<ROW(A15),"",INDEX(D:D,SMALL(G:G,ROW(A15)))) | L18: =IF(K18="","",INDEX(E:E,MATCH(K18,D:D,0))) | M18: =IF(K18="","",INDEX(AC:AC,MATCH(K18,T:T,0))) | O18: =IF(P18="","",_xlfn.RANK.EQ(R18,R4:R19)) | P18: =IF(COUNT(H:H)<ROW(A15),"",INDEX(D:D,SMALL(H:H,ROW(A15)))) | Q18: =IF(P18="","",INDEX(E:E,MATCH(P18,D:D,0))) | R18: =IF(P18="","",INDEX(AC:AC,MATCH(P18,T:T,0))) | T18: =IF(選手!B58="","",選手!B58) -> 瀬戸B | U18: =IF(COUNTIF(選手!E58:E61,"男")>0,"男","女") -> 女 | V18: =W18+COUNTIF(W4:W18,W18)-1 -> 9 | W18: =_xlfn.RANK.EQ(AC18,AC4:AC19) -> 9 | X18: =SUM(Y18:AB18) -> 15 | Y18: =記録!I41 -> 3 | Z18: =記録!H41 -> 4 | AA18: =記録!G41 -> 5 | AB18: =記録!F41 -> 3 | AC18: =X18+Y18*0.1+Z18*0.01+AA18*0.001+AB18*0.0001 -> 15.3453
B19: =SMALL(V4:V19, 16) -> 16 | C19: =SMALL(W4:W19, 16) -> 16 | D19: =INDEX(T:T,MATCH(B19,V:V,0)) -> ダミーA | E19: =IF(D19="","",INDEX(X:X,MATCH(D19,T:T,0))) -> 0 | F19: =IF(D19="","",INDEX(U:U,MATCH(D19,T:T,0))) -> 0 | G19: =IF($F19="男",ROW(),"") | H19: =IF($F19="女",ROW(),"") | J19: =IF(K19="","",_xlfn.RANK.EQ(M19,M4:M19)) | K19: =IF(COUNT(G:G)<ROW(A16),"",INDEX(D:D,SMALL(G:G,ROW(A16)))) | L19: =IF(K19="","",INDEX(E:E,MATCH(K19,D:D,0))) | M19: =IF(K19="","",INDEX(AC:AC,MATCH(K19,T:T,0))) | O19: =IF(P19="","",_xlfn.RANK.EQ(R19,R4:R19)) | P19: =IF(COUNT(H:H)<ROW(A16),"",INDEX(D:D,SMALL(H:H,ROW(A16)))) | Q19: =IF(P19="","",INDEX(E:E,MATCH(P19,D:D,0))) | R19: =IF(P19="","",INDEX(AC:AC,MATCH(P19,T:T,0))) | T19: =IF(選手!B62="","",選手!B62) -> ダミーA | V19: =W19+COUNTIF(W4:W19,W19)-1 -> 16 | W19: =_xlfn.RANK.EQ(AC19,AC4:AC19) -> 16 | X19: =SUM(Y19:AB19) -> 0 | Y19: =記録!E59 -> 0 | Z19: =記録!D59 -> 0 | AA19: =記録!C59 -> 0 | AB19: =記録!B59 -> 0 | AC19: =X19+Y19*0.1+Z19*0.01+AA19*0.001+AB19*0.0001 -> 0

Sheet 成績　個人
C1: 個人順位表：男女混合 | L1: 個人順位表：男性 | S1: 個人順位表：女性
C2: 順位 | D2: チーム | E2: No. | F2: 氏名 | G2: 性別 | H2: 総本数 | L2: 順位 | M2: チーム | N2: No. | O2: 氏名 | P2: 総本数 | S2: 順位 | T2: チーム | U2: No. | V2: 氏名 | W2: 総本数 | Z2: チーム | AA2: No. | AB2: 氏名 | AC2: 性別 | AD2: 総本数 | AE2: 計算数 | AF2: 並び順位 | AG2: 表示順位
B3: 1 | C3: =SMALL(AG:AG, B3) -> 1 | D3: =INDEX(Z:Z,MATCH(B3,AF:AF,0)) -> 春日井A | E3: =INDEX(AA:AA,MATCH(B3,AF:AF,0)) -> 4 | F3: =INDEX(AB:AB,MATCH(B3,AF:AF,0)) -> 田井 泰 | G3: =INDEX(AC:AC,MATCH(B3,AF:AF,0)) -> 男 | H3: =IF(INDEX(AD:AD,MATCH(F3,AB:AB,0))=8,"皆中",INDEX(AD:AD,MATCH(F3,AB:AB,0))) -> 7 | I3: =IF($G3="男",ROW(),"") -> 3 | J3: =IF($G3="女",ROW(),"") | L3: =IF(O3="","",_xlfn.RANK.EQ(Q3,Q:Q)) -> 1 | M3: =IF(O3="","",INDEX(D:D,MATCH(O3,F:F,0))) -> 春日井A | N3: =IF(O3="","",INDEX(E:E,MATCH(O3,F:F,0))) -> 4 | O3: =IF(COUNT(I:I)<ROW(B1),"",INDEX(F:F,SMALL(I:I,ROW(B1)))) -> 田井 泰 | P3: =IF(O3="","",INDEX(H:H,MATCH(O3,F:F,0))) -> 7 | Q3: =IF(O3="","",INDEX(AE:AE,MATCH(O3,AB:AB,0))) -> 7.1111011 | S3: =IF(V3="","",_xlfn.RANK.EQ(X3,X:X)) -> 1 | T3: =IF(V3="","",INDEX(D:D,MATCH(V3,F:F,0))) -> 長久手B | U3: =IF(V3="","",INDEX(E:E,MATCH(V3,F:F,0))) -> 32 | V3: =IF(COUNT(J:J)<ROW(B1),"",INDEX(F:F,SMALL(J:J,ROW(B1)))) -> 野々垣 奈緒子 | W3: =IF(V3="","",INDEX(H:H,MATCH(V3,F:F,0))) -> 7 | X3: =IF(V3="","",INDEX(AE:AE,MATCH(V3,AB:AB,0))) -> 7.1011111 | Z3: =IF(選手!B2="","",選手!B2) -> 春日井A | AA3: =IF(選手!C2="","",選手!C2) -> 1 | AB3: =IF(選手!D2="","",選手!D2) -> 峯 徹 | AC3: =IF(選手!E2="","",選手!E2) -> 男 | AD3: =IF(記録!Y5=8,"皆中",記録!Y5) -> 5 | AE3: =記録!Y4 -> 5.101101 | AF3: =AG3 -> 15 | AG3: =_xlfn.RANK.EQ(AE3,AE:AE) -> 15
B4: 2 | C4: =SMALL(AG:AG, B4) -> 2 | D4: =INDEX(Z:Z,MATCH(B4,AF:AF,0)) -> 長久手A | E4: =INDEX(AA:AA,MATCH(B4,AF:AF,0)) -> 27 | F4: =INDEX(AB:AB,MATCH(B4,AF:AF,0)) -> 山本 三郎 | G4: =INDEX(AC:AC,MATCH(B4,AF:AF,0)) -> 男 | H4: =IF(INDEX(AD:AD,MATCH(F4,AB:AB,0))=8,"皆中",INDEX(AD:AD,MATCH(F4,AB:AB,0))) -> 7 | I4: =IF($G4="男",ROW(),"") -> 4 | J4: =IF($G4="女",ROW(),"") | L4: =IF(O4="","",_xlfn.RANK.EQ(Q4,Q:Q)) -> 2 | M4: =IF(O4="","",INDEX(D:D,MATCH(O4,F:F,0))) -> 長久手A | N4: =IF(O4="","",INDEX(E:E,MATCH(O4,F:F,0))) -> 27 | O4: =IF(COUNT(I:I)<ROW(B2),"",INDEX(F:F,SMALL(I:I,ROW(B2)))) -> 山本 三郎 | P4: =IF(O4="","",INDEX(H:H,MATCH(O4,F:F,0))) -> 7 | Q4: =IF(O4="","",INDEX(AE:AE,MATCH(O4,AB:AB,0))) -> 7.1101111 | S4: =IF(V4="","",_xlfn.RANK.EQ(X4,X:X)) -> 2 | T4: =IF(V4="","",INDEX(D:D,MATCH(V4,F:F,0))) -> 日進B | U4: =IF(V4="","",INDEX(E:E,MATCH(V4,F:F,0))) -> 24 | V4: =IF(COUNT(J:J)<ROW(B2),"",INDEX(F:F,SMALL(J:J,ROW(B2)))) -> 谷口 洋子 | W4: =IF(V4="","",INDEX(H:H,MATCH(V4,F:F,0))) -> 6 | X4: =IF(V4="","",INDEX(AE:AE,MATCH(V4,AB:AB,0))) -> 6.101111 | Z4: =IF(選手!B3="","",選手!B3) -> 春日井A | AA4: =IF(選手!C3="","",選手!C3) -> 2 | AB4: =IF(選手!D3="","",選手!D3) -> 伊藤 恭浩 | AC4: =IF(選手!E3="","",選手!E3) -> 男 | AD4: =記録!X5 -> 6 | AE4: =記録!X4 -> 6.1011101 | AF4: =AG4+COUNTIF(AG3:AG4,AG4)-1 -> 7 | AG4: =_xlfn.RANK.EQ(AE4,AE:AE) -> 7
B5: 3 | C5: =SMALL(AG:AG, B5) -> 3 | D5: =INDEX(Z:Z,MATCH(B5,AF:AF,0)) -> 長久手B | E5: =INDEX(AA:AA,MATCH(B5,AF:AF,0)) -> 32 | F5: =INDEX(AB:AB,MATCH(B5,AF:AF,0)) -> 野々垣 奈緒子 | G5: =INDEX(AC:AC,MATCH(B5,AF:AF,0)) -> 女 | H5: =IF(INDEX(AD:AD,MATCH(F5,AB:AB,0))=8,"皆中",INDEX(AD:AD,MATCH(F5,AB:AB,0))) -> 7 | I5: =IF($G5="男",ROW(),"") | J5: =IF($G5="女",ROW(),"") -> 5 | L5: =IF(O5="","",_xlfn.RANK.EQ(Q5,Q:Q)) -> 3 | M5: =IF(O5="","",INDEX(D:D,MATCH(O5,F:F,0))) -> 瀬戸A | N5: =IF(O5="","",INDEX(E:E,MATCH(O5,F:F,0))) -> 54 | O5: =IF(COUNT(I:I)<ROW(B3),"",INDEX(F:F,SMALL(I:I,ROW(B3)))) -> 野村 清美 | P5: =IF(O5="","",INDEX(H:H,MATCH(O5,F:F,0))) -> 6 | Q5: =IF(O5="","",INDEX(AE:AE,MATCH(O5,AB:AB,0))) -> 6.1111011 | S5: =IF(V5="","",_xlfn.RANK.EQ(X5,X:X)) -> 3 | T5: =IF(V5="","",INDEX(D:D,MATCH(V5,F:F,0))) -> 瀬戸B | U5: =IF(V5="","",INDEX(E:E,MATCH(V5,F:F,0))) -> 59 | V5: =IF(COUNT(J:J)<ROW(B3),"",INDEX(F:F,SMALL(J:J,ROW(B3)))) -> 瀬山 博子 | W5: =IF(V5="","",INDEX(H:H,MATCH(V5,F:F,0))) -> 5 | X5: =IF(V5="","",INDEX(AE:AE,MATCH(V5,AB:AB,0))) -> 5.1110101 | Z5: =IF(選手!B4="","",選手!B4) -> 春日井A | AA5: =IF(選手!C4="","",選手!C4) -> 3 | AB5: =IF(選手!D4="","",選手!D4) -> 大嶋 啓嗣 | AC5: =IF(選手!E4="","",選手!E4) -> 男 | AD5: =記録!W5 -> 3 | AE5: =記録!W4 -> 3.10101 | AF5: =AG5+COUNTIF(AG3:AG5,AG5)-1 -> 41 | AG5: =_xlfn.RANK.EQ(AE5,AE:AE) -> 41
B6: 4 | C6: =SMALL(AG:AG, B6) -> 4 | D6: =INDEX(Z:Z,MATCH(B6,AF:AF,0)) -> 瀬戸A | E6: =INDEX(AA:AA,MATCH(B6,AF:AF,0)) -> 54 | F6: =INDEX(AB:AB,MATCH(B6,AF:AF,0)) -> 野村 清美 | G6: =INDEX(AC:AC,MATCH(B6,AF:AF,0)) -> 男 | H6: =IF(INDEX(AD:AD,MATCH(F6,AB:AB,0))=8,"皆中",INDEX(AD:AD,MATCH(F6,AB:AB,0))) -> 6 | I6: =IF($G6="男",ROW(),"") -> 6 | J6: =IF($G6="女",ROW(),"") | L6: =IF(O6="","",_xlfn.RANK.EQ(Q6,Q:Q)) -> 4 | M6: =IF(O6="","",INDEX(D:D,MATCH(O6,F:F,0))) -> 愛知A | N6: =IF(O6="","",INDEX(E:E,MATCH(O6,F:F,0))) -> 52 | O6: =IF(COUNT(I:I)<ROW(B4),"",INDEX(F:F,SMALL(I:I,ROW(B4)))) -> 木村 憲司 | P6: =IF(O6="","",INDEX(H:H,MATCH(O6,F:F,0))) -> 6 | Q6: =IF(O6="","",INDEX(AE:AE,MATCH(O6,AB:AB,0))) -> 6.111101 | S6: =IF(V6="","",_xlfn.RANK.EQ(X6,X:X)) -> 4 | T6: =IF(V6="","",INDEX(D:D,MATCH(V6,F:F,0))) -> 春日井B | U6: =IF(V6="","",INDEX(E:E,MATCH(V6,F:F,0))) -> 7 | V6: =IF(COUNT(J:J)<ROW(B4),"",INDEX(F:F,SMALL(J:J,ROW(B4)))) -> 片桐 志保 | W6: =IF(V6="","",INDEX(H:H,MATCH(V6,F:F,0))) -> 5 | X6: =IF(V6="","",INDEX(AE:AE,MATCH(V6,AB:AB,0))) -> 5.1100101 | Z6: =IF(選手!B5="","",選手!B5) -> 春日井A | AA6: =IF(選手!C5="","",選手!C5) -> 4 | AB6: =IF(選手!D5="","",選手!D5) -> 田井 泰 | AC6: =IF(選手!E5="","",選手!E5) -> 男 | AD6: =記録!V5 -> 7 | AE6: =記録!V4 -> 7.1111011 | AF6: =AG6+COUNTIF(AG3:AG6,AG6)-1 -> 1 | AG6: =_xlfn.RANK.EQ(AE6,AE:AE) -> 1
B7: 5 | C7: =SMALL(AG:AG, B7) -> 5 | D7: =INDEX(Z:Z,MATCH(B7,AF:AF,0)) -> 愛知A | E7: =INDEX(AA:AA,MATCH(B7,AF:AF,0)) -> 52 | F7: =INDEX(AB:AB,MATCH(B7,AF:AF,0)) -> 木村 憲司 | G7: =INDEX(AC:AC,MATCH(B7,AF:AF,0)) -> 男 | H7: =IF(INDEX(AD:AD,MATCH(F7,AB:AB,0))=8,"皆中",INDEX(AD:AD,MATCH(F7,AB:AB,0))) -> 6 | I7: =IF($G7="男",ROW(),"") -> 7 | J7: =IF($G7="女",ROW(),"") | L7: =IF(O7="","",_xlfn.RANK.EQ(Q7,Q:Q)) -> 5 | M7: =IF(O7="","",INDEX(D:D,MATCH(O7,F:F,0))) -> 春日井A | N7: =IF(O7="","",INDEX(E:E,MATCH(O7,F:F,0))) -> 2 | O7: =IF(COUNT(I:I)<ROW(B5),"",INDEX(F:F,SMALL(I:I,ROW(B5)))) -> 伊藤 恭浩 | P7: =IF(O7="","",INDEX(H:H,MATCH(O7,F:F,0))) -> 6 | Q7: =IF(O7="","",INDEX(AE:AE,MATCH(O7,AB:AB,0))) -> 6.1011101 | S7: =IF(V7="","",_xlfn.RANK.EQ(X7,X:X)) -> 5 | T7: =IF(V7="","",INDEX(D:D,MATCH(V7,F:F,0))) -> 豊明B | U7: =IF(V7="","",INDEX(E:E,MATCH(V7,F:F,0))) -> 15 | V7: =IF(COUNT(J:J)<ROW(B5),"",INDEX(F:F,SMALL(J:J,ROW(B5)))) -> 樋田 良子 | W7: =IF(V7="","",INDEX(H:H,MATCH(V7,F:F,0))) -> 5 | X7: =IF(V7="","",INDEX(AE:AE,MATCH(V7,AB:AB,0))) -> 5.1011011 | Z7: =IF(選手!B6="","",選手!B6) -> 春日井B | AA7: =IF(選手!C6="","",選手!C6) -> 5 | AB7: =IF(選手!D6="","",選手!D6) -> 佃 弘美 | AC7: =IF(選手!E6="","",選手!E6) -> 女 | AD7: =記録!U5 -> 4 | AE7: =記録!U4 -> 4.1010101 | AF7: =AG7+COUNTIF(AG3:AG7,AG7)-1 -> 31 | AG7: =_xlfn.RANK.EQ(AE7,AE:AE) -> 31
B8: 6 | C8: =SMALL(AG:AG, B8) -> 6 | D8: =INDEX(Z:Z,MATCH(B8,AF:AF,0)) -> 日進B | E8: =INDEX(AA:AA,MATCH(B8,AF:AF,0)) -> 24 | F8: =INDEX(AB:AB,MATCH(B8,AF:AF,0)) -> 谷口 洋子 | G8: =INDEX(AC:AC,MATCH(B8,AF:AF,0)) -> 女 | H8: =IF(INDEX(AD:AD,MATCH(F8,AB:AB,0))=8,"皆中",INDEX(AD:AD,MATCH(F8,AB:AB,0))) -> 6 | I8: =IF($G8="男",ROW(),"") | J8: =IF($G8="女",ROW(),"") -> 8 | L8: =IF(O8="","",_xlfn.RANK.EQ(Q8,Q:Q)) -> 6 | M8: =IF(O8="","",INDEX(D:D,MATCH(O8,F:F,0))) -> 長久手A | N8: =IF(O8="","",INDEX(E:E,MATCH(O8,F:F,0))) -> 25 | O8: =IF(COUNT(I:I)<ROW(B6),"",INDEX(F:F,SMALL(I:I,ROW(B6)))) -> 葛西 裕文 | P8: =IF(O8="","",INDEX(H:H,MATCH(O8,F:F,0))) -> 5 | Q8: =IF(O8="","",INDEX(AE:AE,MATCH(O8,AB:AB,0))) -> 5.11011 | S8: =IF(V8="","",_xlfn.RANK.EQ(X8,X:X)) -> 6 | T8: =IF(V8="","",INDEX(D:D,MATCH(V8,F:F,0))) -> 西春日井B | U8: =IF(V8="","",INDEX(E:E,MATCH(V8,F:F,0))) -> 45 | V8: =IF(COUNT(J:J)<ROW(B6),"",INDEX(F:F,SMALL(J:J,ROW(B6)))) -> 村瀬 沙織 | W8: =IF(V8="","",INDEX(H:H,MATCH(V8,F:F,0))) -> 5 | X8: =IF(V8="","",INDEX(AE:AE,MATCH(V8,AB:AB,0))) -> 5.1001101 | Z8: =IF(選手!B7="","",選手!B7) -> 春日井B | AA8: =IF(選手!C7="","",選手!C7) -> 6 | AB8: =IF(選手!D7="","",選手!D7) -> 渡會 あすか | AC8: =IF(選手!E7="","",選手!E7) -> 女 | AD8: =記録!T5 -> 2 | AE8: =記録!T4 -> 2.1001001 | AF8: =AG8+COUNTIF(AG3:AG8,AG8)-1 -> 55 | AG8: =_xlfn.RANK.EQ(AE8,AE:AE) -> 55
B9: 7 | C9: =SMALL(AG:AG, B9) -> 7 | D9: =INDEX(Z:Z,MATCH(B9,AF:AF,0)) -> 春日井A | E9: =INDEX(AA:AA,MATCH(B9,AF:AF,0)) -> 2 | F9: =INDEX(AB:AB,MATCH(B9,AF:AF,0)) -> 伊藤 恭浩 | G9: =INDEX(AC:AC,MATCH(B9,AF:AF,0)) -> 男 | H9: =IF(INDEX(AD:AD,MATCH(F9,AB:AB,0))=8,"皆中",INDEX(AD:AD,MATCH(F9,AB:AB,0))) -> 6 | I9: =IF($G9="男",ROW(),"") -> 9 | J9: =IF($G9="女",ROW(),"") | L9: =IF(O9="","",_xlfn.RANK.EQ(Q9,Q:Q)) -> 7 | M9: =IF(O9="","",INDEX(D:D,MATCH(O9,F:F,0))) -> 日進A | N9: =IF(O9="","",INDEX(E:E,MATCH(O9,F:F,0))) -> 20 | O9: =IF(COUNT(I:I)<ROW(B7),"",INDEX(F:F,SMALL(I:I,ROW(B7)))) -> 志手 俊二 | P9: =IF(O9="","",INDEX(H:H,MATCH(O9,F:F,0))) -> 5 | Q9: =IF(O9="","",INDEX(AE:AE,MATCH(O9,AB:AB,0))) -> 5.1101011 | S9: =IF(V9="","",_xlfn.RANK.EQ(X9,X:X)) -> 7 | T9: =IF(V9="","",INDEX(D:D,MATCH(V9,F:F,0))) -> 日進B | U9: =IF(V9="","",INDEX(E:E,MATCH(V9,F:F,0))) -> 22 | V9: =IF(COUNT(J:J)<ROW(B7),"",INDEX(F:F,SMALL(J:J,ROW(B7)))) -> 越後 奈緒美 | W9: =IF(V9="","",INDEX(H:H,MATCH(V9,F:F,0))) -> 4 | X9: =IF(V9="","",INDEX(AE:AE,MATCH(V9,AB:AB,0))) -> 4.1101011 | Z9: =IF(選手!B8="","",選手!B8) -> 春日井B | AA9: =IF(選手!C8="","",選手!C8) -> 7 | AB9: =IF(選手!D8="","",選手!D8) -> 片桐 志保 | AC9: =IF(選手!E8="","",選手!E8) -> 女 | AD9: =記録!S5 -> 5 | AE9: =記録!S4 -> 5.1100101 | AF9: =AG9+COUNTIF(AG3:AG9,AG9)-1 -> 11 | AG9: =_xlfn.RANK.EQ(AE9,AE:AE) -> 11
B10: 8 | C10: =SMALL(AG:AG, B10) -> 8 | D10: =INDEX(Z:Z,MATCH(B10,AF:AF,0)) -> 瀬戸B | E10: =INDEX(AA:AA,MATCH(B10,AF:AF,0)) -> 59 | F10: =INDEX(AB:AB,MATCH(B10,AF:AF,0)) -> 瀬山 博子 | G10: =INDEX(AC:AC,MATCH(B10,AF:AF,0)) -> 女 | H10: =IF(INDEX(AD:AD,MATCH(F10,AB:AB,0))=8,"皆中",INDEX(AD:AD,MATCH(F10,AB:AB,0))) -> 5 | I10: =IF($G10="男",ROW(),"") | J10: =IF($G10="女",ROW(),"") -> 10 | L10: =IF(O10="","",_xlfn.RANK.EQ(Q10,Q:Q)) -> 8 | M10: =IF(O10="","",INDEX(D:D,MATCH(O10,F:F,0))) -> 尾張旭A | N10: =IF(O10="","",INDEX(E:E,MATCH(O10,F:F,0))) -> 33 | O10: =IF(COUNT(I:I)<ROW(B8),"",INDEX(F:F,SMALL(I:I,ROW(B8)))) -> 西尾 雅司 | P10: =IF(O10="","",INDEX(H:H,MATCH(O10,F:F,0))) -> 5 | Q10: =IF(O10="","",INDEX(AE:AE,MATCH(O10,AB:AB,0))) -> 5.101111 | S10: =IF(V10="","",_xlfn.RANK.EQ(X10,X:X)) -> 8 | T10: =IF(V10="","",INDEX(D:D,MATCH(V10,F:F,0))) -> 西春日井B | U10: =IF(V10="","",INDEX(E:E,MATCH(V10,F:F,0))) -> 47 | V10: =IF(COUNT(J:J)<ROW(B8),"",INDEX(F:F,SMALL(J:J,ROW(B8)))) -> 荒川 花子 | W10: =IF(V10="","",INDEX(H:H,MATCH(V10,F:F,0))) -> 4 | X10: =IF(V10="","",INDEX(AE:AE,MATCH(V10,AB:AB,0))) -> 4.1101001 | Z10: =IF(選手!B9="","",選手!B9) -> 春日井B | AA10: =IF(選手!C9="","",選手!C9) -> 8 | AB10: =IF(選手!D9="","",選手!D9) -> 伊藤 洋子 | AC10: =IF(選手!E9="","",選手!E9) -> 女 | AD10: =記録!R5 -> 4 | AE10: =記録!R4 -> 4.1101 | AF10: =AG10+COUNTIF(AG3:AG10,AG10)-1 -> 20 | AG10: =_xlfn.RANK.EQ(AE10,AE:AE) -> 20
B11: 9 | C11: =SMALL(AG:AG, B11) -> 9 | D11: =INDEX(Z:Z,MATCH(B11,AF:AF,0)) -> 長久手A | E11: =INDEX(AA:AA,MATCH(B11,AF:AF,0)) -> 25 | F11: =INDEX(AB:AB,MATCH(B11,AF:AF,0)) -> 葛西 裕文 | G11: =INDEX(AC:AC,MATCH(B11,AF:AF,0)) -> 男 | H11: =IF(INDEX(AD:AD,MATCH(F11,AB:AB,0))=8,"皆中",INDEX(AD:AD,MATCH(F11,AB:AB,0))) -> 5 | I11: =IF($G11="男",ROW(),"") -> 11 | J11: =IF($G11="女",ROW(),"") | L11: =IF(O11="","",_xlfn.RANK.EQ(Q11,Q:Q)) -> 9 | M11: =IF(O11="","",INDEX(D:D,MATCH(O11,F:F,0))) -> 愛知A | N11: =IF(O11="","",INDEX(E:E,MATCH(O11,F:F,0))) -> 51 | O11: =IF(COUNT(I:I)<ROW(B9),"",INDEX(F:F,SMALL(I:I,ROW(B9)))) -> 小沢 浩寿 | P11: =IF(O11="","",INDEX(H:H,MATCH(O11,F:F,0))) -> 5 | Q11: =IF(O11="","",INDEX(AE:AE,MATCH(O11,AB:AB,0))) -> 5.1011101 | S11: =IF(V11="","",_xlfn.RANK.EQ(X11,X:X)) -> 9 | T11: =IF(V11="","",INDEX(D:D,MATCH(V11,F:F,0))) -> 春日井B | U11: =IF(V11="","",INDEX(E:E,MATCH(V11,F:F,0))) -> 8 | V11: =IF(COUNT(J:J)<ROW(B9),"",INDEX(F:F,SMALL(J:J,ROW(B9)))) -> 伊藤 洋子 | W11: =IF(V11="","",INDEX(H:H,MATCH(V11,F:F,0))) -> 4 | X11: =IF(V11="","",INDEX(AE:AE,MATCH(V11,AB:AB,0))) -> 4.1101 | Z11: =IF(選手!B10="","",選手!B10) -> 豊明A | AA11: =IF(選手!C10="","",選手!C10) -> 9 | AB11: =IF(選手!D10="","",選手!D10) -> 近藤 雄介 | AC11: =IF(選手!E10="","",選手!E10) -> 男 | AD11: =記録!Q5 -> 3 | AE11: =記録!Q4 -> 3.111 | AF11: =AG11+COUNTIF(AG3:AG11,AG11)-1 -> 33 | AG11: =_xlfn.RANK.EQ(AE11,AE:AE) -> 33
B12: 10 | C12: =SMALL(AG:AG, B12) -> 10 | D12: =INDEX(Z:Z,MATCH(B12,AF:AF,0)) -> 日進A | E12: =INDEX(AA:AA,MATCH(B12,AF:AF,0)) -> 20 | F12: =INDEX(AB:AB,MATCH(B12,AF:AF,0)) -> 志手 俊二 | G12: =INDEX(AC:AC,MATCH(B12,AF:AF,0)) -> 男 | H12: =IF(INDEX(AD:AD,MATCH(F12,AB:AB,0))=8,"皆中",INDEX(AD:AD,MATCH(F12,AB:AB,0))) -> 5 | I12: =IF($G12="男",ROW(),"") -> 12 | J12: =IF($G12="女",ROW(),"") | L12: =IF(O12="","",_xlfn.RANK.EQ(Q12,Q:Q)) -> 10 | M12: =IF(O12="","",INDEX(D:D,MATCH(O12,F:F,0))) -> 春日井A | N12: =IF(O12="","",INDEX(E:E,MATCH(O12,F:F,0))) -> 1 | O12: =IF(COUNT(I:I)<ROW(B10),"",INDEX(F:F,SMALL(I:I,ROW(B10)))) -> 峯 徹 | P12: =IF(O12="","",INDEX(H:H,MATCH(O12,F:F,0))) -> 5 | Q12: =IF(O12="","",INDEX(AE:AE,MATCH(O12,AB:AB,0))) -> 5.101101 | S12: =IF(V12="","",_xlfn.RANK.EQ(X12,X:X)) -> 10 | T12: =IF(V12="","",INDEX(D:D,MATCH(V12,F:F,0))) -> 日進B | U12: =IF(V12="","",INDEX(E:E,MATCH(V12,F:F,0))) -> 21 | V12: =IF(COUNT(J:J)<ROW(B10),"",INDEX(F:F,SMALL(J:J,ROW(B10)))) -> 後藤 徳子 | W12: =IF(V12="","",INDEX(H:H,MATCH(V12,F:F,0))) -> 4 | X12: =IF(V12="","",INDEX(AE:AE,MATCH(V12,AB:AB,0))) -> 4.1100101 | Z12: =IF(選手!B11="","",選手!B11) -> 豊明A | AA12: =IF(選手!C11="","",選手!C11) -> 10 | AB12: =IF(選手!D11="","",選手!D11) -> 近藤 治 | AC12: =IF(選手!E11="","",選手!E11) -> 男 | AD12: =記録!P5 -> 3 | AE12: =記録!P4 -> 3.1010101 | AF12: =AG12+COUNTIF(AG3:AG12,AG12)-1 -> 39 | AG12: =_xlfn.RANK.EQ(AE12,AE:AE) -> 39
B13: 11 | C13: =SMALL(AG:AG, B13) -> 11 | D13: =INDEX(Z:Z,MATCH(B13,AF:AF,0)) -> 春日井B | E13: =INDEX(AA:AA,MATCH(B13,AF:AF,0)) -> 7 | F13: =INDEX(AB:AB,MATCH(B13,AF:AF,0)) -> 片桐 志保 | G13: =INDEX(AC:AC,MATCH(B13,AF:AF,0)) -> 女 | H13: =IF(INDEX(AD:AD,MATCH(F13,AB:AB,0))=8,"皆中",INDEX(AD:AD,MATCH(F13,AB:AB,0))) -> 5 | I13: =IF($G13="男",ROW(),"") | J13: =IF($G13="女",ROW(),"") -> 13 | L13: =IF(O13="","",_xlfn.RANK.EQ(Q13,Q:Q)) -> 11 | M13: =IF(O13="","",INDEX(D:D,MATCH(O13,F:F,0))) -> 愛知A | N13: =IF(O13="","",INDEX(E:E,MATCH(O13,F:F,0))) -> 50 | O13: =IF(COUNT(I:I)<ROW(B11),"",INDEX(F:F,SMALL(I:I,ROW(B11)))) -> 平野 良則 | P13: =IF(O13="","",INDEX(H:H,MATCH(O13,F:F,0))) -> 4 | Q13: =IF(O13="","",INDEX(AE:AE,MATCH(O13,AB:AB,0))) -> 4.110101 | S13: =IF(V13="","",_xlfn.RANK.EQ(X13,X:X)) -> 11 | T13: =IF(V13="","",INDEX(D:D,MATCH(V13,F:F,0))) -> 豊明B | U13: =IF(V13="","",INDEX(E:E,MATCH(V13,F:F,0))) -> 13 | V13: =IF(COUNT(J:J)<ROW(B11),"",INDEX(F:F,SMALL(J:J,ROW(B11)))) -> 堀井 恵美子 | W13: =IF(V13="","",INDEX(H:H,MATCH(V13,F:F,0))) -> 4 | X13: =IF(V13="","",INDEX(AE:AE,MATCH(V13,AB:AB,0))) -> 4.1100101 | Z13: =IF(選手!B12="","",選手!B12) -> 豊明A | AA13: =IF(選手!C12="","",選手!C12) -> 11 | AB13: =IF(選手!D12="","",選手!D12) -> 外山 康彦 | AC13: =IF(選手!E12="","",選手!E12) -> 男 | AD13: =記録!O5 -> 3 | AE13: =記録!O4 -> 3.110001 | AF13: =AG13+COUNTIF(AG3:AG13,AG13)-1 -> 36 | AG13: =_xlfn.RANK.EQ(AE13,AE:AE) -> 36
B14: 12 | C14: =SMALL(AG:AG, B14) -> 12 | D14: =INDEX(Z:Z,MATCH(B14,AF:AF,0)) -> 尾張旭A | E14: =INDEX(AA:AA,MATCH(B14,AF:AF,0)) -> 33 | F14: =INDEX(AB:AB,MATCH(B14,AF:AF,0)) -> 西尾 雅司 | G14: =INDEX(AC:AC,MATCH(B14,AF:AF,0)) -> 男 | H14: =IF(INDEX(AD:AD,MATCH(F14,AB:AB,0))=8,"皆中",INDEX(AD:AD,MATCH(F14,AB:AB,0))) -> 5 | I14: =IF($G14="男",ROW(),"") -> 14 | J14: =IF($G14="女",ROW(),"") | L14: =IF(O14="","",_xlfn.RANK.EQ(Q14,Q:Q)) -> 12 | M14: =IF(O14="","",INDEX(D:D,MATCH(O14,F:F,0))) -> 尾張旭A | N14: =IF(O14="","",INDEX(E:E,MATCH(O14,F:F,0))) -> 35 | O14: =IF(COUNT(I:I)<ROW(B12),"",INDEX(F:F,SMALL(I:I,ROW(B12)))) -> 大竹 誠 | P14: =IF(O14="","",INDEX(H:H,MATCH(O14,F:F,0))) -> 4 | Q14: =IF(O14="","",INDEX(AE:AE,MATCH(O14,AB:AB,0))) -> 4.1100101 | S14: =IF(V14="","",_xlfn.RANK.EQ(X14,X:X)) -> 11 | T14: =IF(V14="","",INDEX(D:D,MATCH(V14,F:F,0))) -> 長久手B | U14: =IF(V14="","",INDEX(E:E,MATCH(V14,F:F,0))) -> 30 | V14: =IF(COUNT(J:J)<ROW(B12),"",INDEX(F:F,SMALL(J:J,ROW(B12)))) -> 上平 佳織 | W14: =IF(V14="","",INDEX(H:H,MATCH(V14,F:F,0))) -> 4 | X14: =IF(V14="","",INDEX(AE:AE,MATCH(V14,AB:AB,0))) -> 4.1100101 | Z14: =IF(選手!B13="","",選手!B13) -> 豊明A | AA14: =IF(選手!C13="","",選手!C13) -> 12 | AB14: =IF(選手!D13="","",選手!D13) -> 榊原 隆一 | AC14: =IF(選手!E13="","",選手!E13) -> 男 | AD14: =記録!N5 -> 3 | AE14: =記録!N4 -> 3.100101 | AF14: =AG14+COUNTIF(AG3:AG14,AG14)-1 -> 47 | AG14: =_xlfn.RANK.EQ(AE14,AE:AE) -> 47
B15: 13 | C15: =SMALL(AG:AG, B15) -> 13 | D15: =INDEX(Z:Z,MATCH(B15,AF:AF,0)) -> 愛知A | E15: =INDEX(AA:AA,MATCH(B15,AF:AF,0)) -> 51 | F15: =INDEX(AB:AB,MATCH(B15,AF:AF,0)) -> 小沢 浩寿 | G15: =INDEX(AC:AC,MATCH(B15,AF:AF,0)) -> 男 | H15: =IF(INDEX(AD:AD,MATCH(F15,AB:AB,0))=8,"皆中",INDEX(AD:AD,MATCH(F15,AB:AB,0))) -> 5 | I15: =IF($G15="男",ROW(),"") -> 15 | J15: =IF($G15="女",ROW(),"") | L15: =IF(O15="","",_xlfn.RANK.EQ(Q15,Q:Q)) -> 13 | M15: =IF(O15="","",INDEX(D:D,MATCH(O15,F:F,0))) -> 尾張旭A | N15: =IF(O15="","",INDEX(E:E,MATCH(O15,F:F,0))) -> 34 | O15: =IF(COUNT(I:I)<ROW(B13),"",INDEX(F:F,SMALL(I:I,ROW(B13)))) -> 角谷 昌紀 | P15: =IF(O15="","",INDEX(H:H,MATCH(O15,F:F,0))) -> 4 | Q15: =IF(O15="","",INDEX(AE:AE,MATCH(O15,AB:AB,0))) -> 4.101101 | S15: =IF(V15="","",_xlfn.RANK.EQ(X15,X:X)) -> 13 | T15: =IF(V15="","",INDEX(D:D,MATCH(V15,F:F,0))) -> 瀬戸B | U15: =IF(V15="","",INDEX(E:E,MATCH(V15,F:F,0))) -> 58 | V15: =IF(COUNT(J:J)<ROW(B13),"",INDEX(F:F,SMALL(J:J,ROW(B13)))) -> 加藤 節子 | W15: =IF(V15="","",INDEX(H:H,MATCH(V15,F:F,0))) -> 4 | X15: =IF(V15="","",INDEX(AE:AE,MATCH(V15,AB:AB,0))) -> 4.1011001 | Z15: =IF(選手!B14="","",選手!B14) -> 豊明B | AA15: =IF(選手!C14="","",選手!C14) -> 13 | AB15: =IF(選手!D14="","",選手!D14) -> 堀井 恵美子 | AC15: =IF(選手!E14="","",選手!E14) -> 女 | AD15: =記録!M5 -> 4 | AE15: =記録!M4 -> 4.1100101 | AF15: =AG15+COUNTIF(AG3:AG15,AG15)-1 -> 23 | AG15: =_xlfn.RANK.EQ(AE15,AE:AE) -> 23
B16: 14 | C16: =SMALL(AG:AG, B16) -> 14 | D16: =INDEX(Z:Z,MATCH(B16,AF:AF,0)) -> 豊明B | E16: =INDEX(AA:AA,MATCH(B16,AF:AF,0)) -> 15 | F16: =INDEX(AB:AB,MATCH(B16,AF:AF,0)) -> 樋田 良子 | G16: =INDEX(AC:AC,MATCH(B16,AF:AF,0)) -> 女 | H16: =IF(INDEX(AD:AD,MATCH(F16,AB:AB,0))=8,"皆中",INDEX(AD:AD,MATCH(F16,AB:AB,0))) -> 5 | I16: =IF($G16="男",ROW(),"") | J16: =IF($G16="女",ROW(),"") -> 16 | L16: =IF(O16="","",_xlfn.RANK.EQ(Q16,Q:Q)) -> 14 | M16: =IF(O16="","",INDEX(D:D,MATCH(O16,F:F,0))) -> 長久手A | N16: =IF(O16="","",INDEX(E:E,MATCH(O16,F:F,0))) -> 28 | O16: =IF(COUNT(I:I)<ROW(B14),"",INDEX(F:F,SMALL(I:I,ROW(B14)))) -> 芝田 典久 | P16: =IF(O16="","",INDEX(H:H,MATCH(O16,F:F,0))) -> 4 | Q16: =IF(O16="","",INDEX(AE:AE,MATCH(O16,AB:AB,0))) -> 4.1011001 | S16: =IF(V16="","",_xlfn.RANK.EQ(X16,X:X)) -> 14 | T16: =IF(V16="","",INDEX(D:D,MATCH(V16,F:F,0))) -> 春日井B | U16: =IF(V16="","",INDEX(E:E,MATCH(V16,F:F,0))) -> 5 | V16: =IF(COUNT(J:J)<ROW(B14),"",INDEX(F:F,SMALL(J:J,ROW(B14)))) -> 佃 弘美 | W16: =IF(V16="","",INDEX(H:H,MATCH(V16,F:F,0))) -> 4 | X16: =IF(V16="","",INDEX(AE:AE,MATCH(V16,AB:AB,0))) -> 4.1010101 | Z16: =IF(選手!B15="","",選手!B15) -> 豊明B | AA16: =IF(選手!C15="","",選手!C15) -> 14 | AB16: =IF(選手!D15="","",選手!D15) -> 深見 裕子 | AC16: =IF(選手!E15="","",選手!E15) -> 女 | AD16: =記録!L5 -> 3 | AE16: =記録!L4 -> 3.10101 | AF16: =AG16+COUNTIF(AG3:AG16,AG16)-1 -> 42 | AG16: =_xlfn.RANK.EQ(AE16,AE:AE) -> 41
B17: 15 | C17: =SMALL(AG:AG, B17) -> 15 | D17: =INDEX(Z:Z,MATCH(B17,AF:AF,0)) -> 春日井A | E17: =INDEX(AA:AA,MATCH(B17,AF:AF,0)) -> 1 | F17: =INDEX(AB:AB,MATCH(B17,AF:AF,0)) -> 峯 徹 | G17: =INDEX(AC:AC,MATCH(B17,AF:AF,0)) -> 男 | H17: =IF(INDEX(AD:AD,MATCH(F17,AB:AB,0))=8,"皆中",INDEX(AD:AD,MATCH(F17,AB:AB,0))) -> 5 | I17: =IF($G17="男",ROW(),"") -> 17 | J17: =IF($G17="女",ROW(),"") | L17: =IF(O17="","",_xlfn.RANK.EQ(Q17,Q:Q)) -> 15 | M17: =IF(O17="","",INDEX(D:D,MATCH(O17,F:F,0))) -> 尾張旭A | N17: =IF(O17="","",INDEX(E:E,MATCH(O17,F:F,0))) -> 36 | O17: =IF(COUNT(I:I)<ROW(B15),"",INDEX(F:F,SMALL(I:I,ROW(B15)))) -> 山田 英治 | P17: =IF(O17="","",INDEX(H:H,MATCH(O17,F:F,0))) -> 4 | Q17: =IF(O17="","",INDEX(AE:AE,MATCH(O17,AB:AB,0))) -> 4.1011001 | S17: =IF(V17="","",_xlfn.RANK.EQ(X17,X:X)) -> 15 | T17: =IF(V17="","",INDEX(D:D,MATCH(V17,F:F,0))) -> 尾張旭B | U17: =IF(V17="","",INDEX(E:E,MATCH(V17,F:F,0))) -> 38 | V17: =IF(COUNT(J:J)<ROW(B15),"",INDEX(F:F,SMALL(J:J,ROW(B15)))) -> 北川 裕希子 | W17: =IF(V17="","",INDEX(H:H,MATCH(V17,F:F,0))) -> 3 | X17: =IF(V17="","",INDEX(AE:AE,MATCH(V17,AB:AB,0))) -> 3.1101 | Z17: =IF(選手!B16="","",選手!B16) -> 豊明B | AA17: =IF(選手!C16="","",選手!C16) -> 15 | AB17: =IF(選手!D16="","",選手!D16) -> 樋田 良子 | AC17: =IF(選手!E16="","",選手!E16) -> 女 | AD17: =記録!K5 -> 5 | AE17: =記録!K4 -> 5.1011011 | AF17: =AG17+COUNTIF(AG3:AG17,AG17)-1 -> 14 | AG17: =_xlfn.RANK.EQ(AE17,AE:AE) -> 14
B18: 16 | C18: =SMALL(AG:AG, B18) -> 16 | D18: =INDEX(Z:Z,MATCH(B18,AF:AF,0)) -> 西春日井B | E18: =INDEX(AA:AA,MATCH(B18,AF:AF,0)) -> 45 | F18: =INDEX(AB:AB,MATCH(B18,AF:AF,0)) -> 村瀬 沙織 | G18: =INDEX(AC:AC,MATCH(B18,AF:AF,0)) -> 女 | H18: =IF(INDEX(AD:AD,MATCH(F18,AB:AB,0))=8,"皆中",INDEX(AD:AD,MATCH(F18,AB:AB,0))) -> 5 | I18: =IF($G18="男",ROW(),"") | J18: =IF($G18="女",ROW(),"") -> 18 | L18: =IF(O18="","",_xlfn.RANK.EQ(Q18,Q:Q)) -> 16 | M18: =IF(O18="","",INDEX(D:D,MATCH(O18,F:F,0))) -> 愛知A | N18: =IF(O18="","",INDEX(E:E,MATCH(O18,F:F,0))) -> 49 | O18: =IF(COUNT(I:I)<ROW(B16),"",INDEX(F:F,SMALL(I:I,ROW(B16)))) -> 門矢 誠 | P18: =IF(O18="","",INDEX(H:H,MATCH(O18,F:F,0))) -> 4 | Q18: =IF(O18="","",INDEX(AE:AE,MATCH(O18,AB:AB,0))) -> 4.1010111 | S18: =IF(V18="","",_xlfn.RANK.EQ(X18,X:X)) -> 16 | T18: =IF(V18="","",INDEX(D:D,MATCH(V18,F:F,0))) -> 瀬戸B | U18: =IF(V18="","",INDEX(E:E,MATCH(V18,F:F,0))) -> 57 | V18: =IF(COUNT(J:J)<ROW(B16),"",INDEX(F:F,SMALL(J:J,ROW(B16)))) -> 谷口 弥生 | W18: =IF(V18="","",INDEX(H:H,MATCH(V18,F:F,0))) -> 3 | X18: =IF(V18="","",INDEX(AE:AE,MATCH(V18,AB:AB,0))) -> 3.110001 | Z18: =IF(選手!B17="","",選手!B17) -> 豊明B | AA18: =IF(選手!C17="","",選手!C17) -> 16 | AB18: =IF(選手!D17="","",選手!D17) -> 谷口 祥子 | AC18: =IF(選手!E17="","",選手!E17) -> 女 | AD18: =記録!J5 -> 2 | AE18: =記録!J4 -> 2.1001 | AF18: =AG18+COUNTIF(AG3:AG18,AG18)-1 -> 57 | AG18: =_xlfn.RANK.EQ(AE18,AE:AE) -> 57
B19: 17 | C19: =SMALL(AG:AG, B19) -> 17 | D19: =INDEX(Z:Z,MATCH(B19,AF:AF,0)) -> 日進B | E19: =INDEX(AA:AA,MATCH(B19,AF:AF,0)) -> 22 | F19: =INDEX(AB:AB,MATCH(B19,AF:AF,0)) -> 越後 奈緒美 | G19: =INDEX(AC:AC,MATCH(B19,AF:AF,0)) -> 女 | H19: =IF(INDEX(AD:AD,MATCH(F19,AB:AB,0))=8,"皆中",INDEX(AD:AD,MATCH(F19,AB:AB,0))) -> 4 | I19: =IF($G19="男",ROW(),"") | J19: =IF($G19="女",ROW(),"") -> 19 | L19: =IF(O19="","",_xlfn.RANK.EQ(Q19,Q:Q)) -> 17 | M19: =IF(O19="","",INDEX(D:D,MATCH(O19,F:F,0))) -> 長久手A | N19: =IF(O19="","",INDEX(E:E,MATCH(O19,F:F,0))) -> 26 | O19: =IF(COUNT(I:I)<ROW(B17),"",INDEX(F:F,SMALL(I:I,ROW(B17)))) -> 松永 安太郎 | P19: =IF(O19="","",INDEX(H:H,MATCH(O19,F:F,0))) -> 4 | Q19: =IF(O19="","",INDEX(AE:AE,MATCH(O19,AB:AB,0))) -> 4.101011 | S19: =IF(V19="","",_xlfn.RANK.EQ(X19,X:X)) -> 17 | T19: =IF(V19="","",INDEX(D:D,MATCH(V19,F:F,0))) -> 西春日井B | U19: =IF(V19="","",INDEX(E:E,MATCH(V19,F:F,0))) -> 46 | V19: =IF(COUNT(J:J)<ROW(B17),"",INDEX(F:F,SMALL(J:J,ROW(B17)))) -> 中神 佐知子 | W19: =IF(V19="","",INDEX(H:H,MATCH(V19,F:F,0))) -> 3 | X19: =IF(V19="","",INDEX(AE:AE,MATCH(V19,AB:AB,0))) -> 3.1011 | Z19: =IF(選手!B18="","",選手!B18) -> 日進A | AA19: =IF(選手!C18="","",選手!C18) -> 17 | AB19: =IF(選手!D18="","",選手!D18) -> 新美 友治 | AC19: =IF(選手!E18="","",選手!E18) -> 男 | AD19: =記録!I5 -> 4 | AE19: =記録!I4 -> 4.1001011 | AF19: =AG19+COUNTIF(AG3:AG19,AG19)-1 -> 32 | AG19: =_xlfn.RANK.EQ(AE19,AE:AE) -> 32
B20: 18 | C20: =SMALL(AG:AG, B20) -> 18 | D20: =INDEX(Z:Z,MATCH(B20,AF:AF,0)) -> 愛知A | E20: =INDEX(AA:AA,MATCH(B20,AF:AF,0)) -> 50 | F20: =INDEX(AB:AB,MATCH(B20,AF:AF,0)) -> 平野 良則 | G20: =INDEX(AC:AC,MATCH(B20,AF:AF,0)) -> 男 | H20: =IF(INDEX(AD:AD,MATCH(F20,AB:AB,0))=8,"皆中",INDEX(AD:AD,MATCH(F20,AB:AB,0))) -> 4 | I20: =IF($G20="男",ROW(),"") -> 20 | J20: =IF($G20="女",ROW(),"") | L20: =IF(O20="","",_xlfn.RANK.EQ(Q20,Q:Q)) -> 18 | M20: =IF(O20="","",INDEX(D:D,MATCH(O20,F:F,0))) -> 日進A | N20: =IF(O20="","",INDEX(E:E,MATCH(O20,F:F,0))) -> 17 | O20: =IF(COUNT(I:I)<ROW(B18),"",INDEX(F:F,SMALL(I:I,ROW(B18)))) -> 新美 友治 | P20: =IF(O20="","",INDEX(H:H,MATCH(O20,F:F,0))) -> 4 | Q20: =IF(O20="","",INDEX(AE:AE,MATCH(O20,AB:AB,0))) -> 4.1001011 | S20: =IF(V20="","",_xlfn.RANK.EQ(X20,X:X)) -> 18 | T20: =IF(V20="","",INDEX(D:D,MATCH(V20,F:F,0))) -> 尾張旭B | U20: =IF(V20="","",INDEX(E:E,MATCH(V20,F:F,0))) -> 39 | V20: =IF(COUNT(J:J)<ROW(B18),"",INDEX(F:F,SMALL(J:J,ROW(B18)))) -> 安達 初枝 | W20: =IF(V20="","",INDEX(H:H,MATCH(V20,F:F,0))) -> 3 | X20: =IF(V20="","",INDEX(AE:AE,MATCH(V20,AB:AB,0))) -> 3.1010101 | Z20: =IF(選手!B19="","",選手!B19) -> 日進A | AA20: =IF(選手!C19="","",選手!C19) -> 18 | AB20: =IF(選手!D19="","",選手!D19) -> 笠井 大督 | AC20: =IF(選手!E19="","",選手!E19) -> 男 | AD20: =記録!H5 -> 3 | AE20: =記録!H4 -> 3.100101 | AF20: =AG20+COUNTIF(AG3:AG20,AG20)-1 -> 46 | AG20: =_xlfn.RANK.EQ(AE20,AE:AE) -> 46
B21: 19 | C21: =SMALL(AG:AG, B21) -> 19 | D21: =INDEX(Z:Z,MATCH(B21,AF:AF,0)) -> 西春日井B | E21: =INDEX(AA:AA,MATCH(B21,AF:AF,0)) -> 47 | F21: =INDEX(AB:AB,MATCH(B21,AF:AF,0)) -> 荒川 花子 | G21: =INDEX(AC:AC,MATCH(B21,AF:AF,0)) -> 女 | H21: =IF(INDEX(AD:AD,MATCH(F21,AB:AB,0))=8,"皆中",INDEX(AD:AD,MATCH(F21,AB:AB,0))) -> 4 | I21: =IF($G21="男",ROW(),"") | J21: =IF($G21="女",ROW(),"") -> 21 | L21: =IF(O21="","",_xlfn.RANK.EQ(Q21,Q:Q)) -> 19 | M21: =IF(O21="","",INDEX(D:D,MATCH(O21,F:F,0))) -> 豊明A | N21: =IF(O21="","",INDEX(E:E,MATCH(O21,F:F,0))) -> 9 | O21: =IF(COUNT(I:I)<ROW(B19),"",INDEX(F:F,SMALL(I:I,ROW(B19)))) -> 近藤 雄介 | P21: =IF(O21="","",INDEX(H:H,MATCH(O21,F:F,0))) -> 3 | Q21: =IF(O21="","",INDEX(AE:AE,MATCH(O21,AB:AB,0))) -> 3.111 | S21: =IF(V21="","",_xlfn.RANK.EQ(X21,X:X)) -> 19 | T21: =IF(V21="","",INDEX(D:D,MATCH(V21,F:F,0))) -> 豊明B | U21: =IF(V21="","",INDEX(E:E,MATCH(V21,F:F,0))) -> 14 | V21: =IF(COUNT(J:J)<ROW(B19),"",INDEX(F:F,SMALL(J:J,ROW(B19)))) -> 深見 裕子 | W21: =IF(V21="","",INDEX(H:H,MATCH(V21,F:F,0))) -> 3 | X21: =IF(V21="","",INDEX(AE:AE,MATCH(V21,AB:AB,0))) -> 3.10101 | Z21: =IF(選手!B20="","",選手!B20) -> 日進A | AA21: =IF(選手!C20="","",選手!C20) -> 19 | AB21: =IF(選手!D20="","",選手!D20) -> 谷田 直樹 | AC21: =IF(選手!E20="","",選手!E20) -> 男 | AD21: =記録!G5 -> 3 | AE21: =記録!G4 -> 3.11001 | AF21: =AG21+COUNTIF(AG3:AG21,AG21)-1 -> 35 | AG21: =_xlfn.RANK.EQ(AE21,AE:AE) -> 35
