Workbook

Sheet 選手
B1: チーム | C1: No. | D1: 氏名 | E1: 性別 | G1: チーム | H1: No. | I1: 氏名 | J1: 性別 | L1: チーム | M1: No. | N1: 氏名 | O1: 性別
B2: 瀬戸A | C2: 1 | D2: 野村 清美 | E2: 男 | G2: 尾張旭A | H2: 21 | I2: 大竹 誠 | J2: 男 | L2: 長久手A | M2: 41 | N2: 柳原 啓宏 | O2: 男
B3: 瀬戸A | C3: 2 | D3: 加藤 崇文 | E3: 男 | G3: 尾張旭A | H3: 22 | I3: 阿知波 正 | J3: 男 | L3: 長久手A | M3: 42 | N3: 葛西 裕文 | O3: 男
B4: 瀬戸A | C4: 3 | D4: 谷口 弥生 | E4: 女 | G4: 尾張旭A | H4: 23 | I4: 山田 英治 | J4: 男 | L4: 長久手A | M4: 43 | N4: 芝田 典久 | O4: 男
B5: 瀬戸A | C5: 4 | D5: 森竹 結衣 | E5: 女 | G5: 尾張旭A | H5: 24 | I5: 西尾 雅司 | J5: 男 | L5: 長久手A | M5: 44 | N5: 松井 忠志 | O5: 男
B6: 瀬戸B | C6: 5 | D6: 伊藤 寿邦 | E6: 男 | G6: 尾張旭B | H6: 25 | I6: 北川 裕希子 | J6: 女 | L6: 長久手B | M6: 45 | N6: 山越 一江 | O6: 女
B7: 瀬戸B | C7: 6 | D7: 小林 都 | E7: 女 | G7: 尾張旭B | H7: 26 | I7: 安達 初枝 | J7: 女 | L7: 長久手B | M7: 46 | N7: 澤田 圭子 | O7: 女
B8: 瀬戸B | C8: 7 | D8: 瀬山 博子 | E8: 女 | G8: 尾張旭B | H8: 27 | I8: 高田 優子 | J8: 女 | L8: 長久手B | M8: 47 | N8: 水野 三穂 | O8: 女
B9: 瀬戸B | C9: 8 | D9: 加藤 広史 | E9: 男 | G9: 尾張旭B | H9: 28 | I9: 田中 沙紀子 | J9: 女 | L9: 長久手B | M9: 48 | N9: 野々垣 奈緒子 | O9: 女
B10: 西春日井A | C10: 9 | D10: 丹羽 泰生 | E10: 男 | G10: 日進A | H10: 29 | I10: 志手 俊二 | J10: 男 | L10: 豊明A | M10: 49 | N10: 榊原 隆一 | O10: 男
B11: 西春日井A | C11: 10 | D11: 大槻 成実 | E11: 男 | G11: 日進A | H11: 30 | I11: 米田 康介 | J11: 男 | L11: 豊明A | M11: 50 | N11: 堀 隆教 | O11: 男
B12: 西春日井A | C12: 11 | D12: 村瀬 沙織 | E12: 女 | G12: 日進A | H12: 31 | I12: 窪田 達也 | J12: 男 | L12: 豊明A | M12: 51 | N12: 近藤 治 | O12: 男
B13: 西春日井A | C13: 12 | D13: 加藤 忠人 | E13: 男 | G13: 日進A | H13: 32 | I13: 新美 友治 | J13: 男 | L13: 豊明A | M13: 52 | N13: 園田 敏雄 | O13: 男
... B17: 西春日井B | C17: 16 | D17: 荒川 花子 | E17: 女 | G17: 日進B | H17: 36 | I17: 赤塚 正子 | J17: 女 | L17: 豊明B | M17: 56 | N17: 堀井 恵美子 | O17: 女
B18: 春日井A | C18: 17 | D18: 小川 久生 | E18: 男 | G18: 春日井B | H18: 37 | I18: 遠藤 恵美子 | J18: 女
B19: 春日井A | C19: 18 | D19: 阿部 健二郞 | E19: 男 | G19: 春日井B | H19: 38 | I19: 山口 このみ | J19: 女
B20: 春日井A | C20: 19 | D20: 玉野 正明 | E20: 男 | G20: 春日井B | H20: 39 | I20: 片桐 志保 | J20: 女
B21: 春日井A | C21: 20 | D21: 杉山 武 | E21: 男 | G21: 春日井B | H21: 40 | I21: 佃 弘美 | J21: 女

Sheet 記録
B2: チーム | C2: =選手!B18 -> 春日井A | G2: =選手!B14 -> 西春日井B | K2: =選手!B10 -> 西春日井A | O2: =選手!B6 -> 瀬戸B | S2: =選手!B2 -> 瀬戸A | W2: チーム
B3: チーム合計 | C3: =SUM(C5:F5) -> 0 | G3: =SUM(G5:J5) -> 0 | K3: =SUM(K5:N5) -> 0 | O3: =SUM(O5:R5) -> 0 | S3: =SUM(S5:V5) -> 0 | W3: チーム合計
B4: 個人順位用 | C4: =C5+0.1+(IF(C15="〇",1,0)*0.01)+(IF(C14="〇",1,0)*0.001)+(IF(C13="〇",1,0)*0.0001)+(IF(C12="〇",1,0)*0.00001)+(IF(C10="〇",1,0)*0.000001)+(IF(C9="〇",1,0)*0.0000001)+(IF(C8="〇",1,0)*0.00000001)+(IF(C7="〇",1,0)*0.000000001) -> 0.1 | D4: =D5+0.1+(IF(D15="〇",1,0)*0.01)+(IF(D14="〇",1,0)*0.001)+(IF(D13="〇",1,0)*0.0001)+(IF(D12="〇",1,0)*0.00001)+(IF(D10="〇",1,0)*0.000001)+(IF(D9="〇",1,0)*0.0000001)+(IF(D8="〇",1,0)*0.00000001)+(IF(D7="〇",1,0)*0.000000001) -> 0.1 | E4: =E5+0.1+(IF(E15="〇",1,0)*0.01)+(IF(E14="〇",1,0)*0.001)+(IF(E13="〇",1,0)*0.0001)+(IF(E12="〇",1,0)*0.00001)+(IF(E10="〇",1,0)*0.000001)+(IF(E9="〇",1,0)*0.0000001)+(IF(E8="〇",1,0)*0.00000001)+(IF(E7="〇",1,0)*0.000000001) -> 0.1 | F4: =F5+0.1+(IF(F15="〇",1,0)*0.01)+(IF(F14="〇",1,0)*0.001)+(IF(F13="〇",1,0)*0.0001)+(IF(F12="〇",1,0)*0.00001)+(IF(F10="〇",1,0)*0.000001)+(IF(F9="〇",1,0)*0.0000001)+(IF(F8="〇",1,0)*0.00000001)+(IF(F7="〇",1,0)*0.000000001) -> 0.1 | G4: =G5+0.1+(IF(G15="〇",1,0)*0.01)+(IF(G14="〇",1,0)*0.001)+(IF(G13="〇",1,0)*0.0001)+(IF(G12="〇",1,0)*0.00001)+(IF(G10="〇",1,0)*0.000001)+(IF(G9="〇",1,0)*0.0000001)+(IF(G8="〇",1,0)*0.00000001)+(IF(G7="〇",1,0)*0.000000001) -> 0.1 | H4: =H5+0.1+(IF(H15="〇",1,0)*0.01)+(IF(H14="〇",1,0)*0.001)+(IF(H13="〇",1,0)*0.0001)+(IF(H12="〇",1,0)*0.00001)+(IF(H10="〇",1,0)*0.000001)+(IF(H9="〇",1,0)*0.0000001)+(IF(H8="〇",1,0)*0.00000001)+(IF(H7="〇",1,0)*0.000000001) -> 0.1 | I4: =I5+0.1+(IF(I15="〇",1,0)*0.01)+(IF(I14="〇",1,0)*0.001)+(IF(I13="〇",1,0)*0.0001)+(IF(I12="〇",1,0)*0.00001)+(IF(I10="〇",1,0)*0.000001)+(IF(I9="〇",1,0)*0.0000001)+(IF(I8="〇",1,0)*0.00000001)+(IF(I7="〇",1,0)*0.000000001) -> 0.1 | J4: =J5+0.1+(IF(J15="〇",1,0)*0.01)+(IF(J14="〇",1,0)*0.001)+(IF(J13="〇",1,0)*0.0001)+(IF(J12="〇",1,0)*0.00001)+(IF(J10="〇",1,0)*0.000001)+(IF(J9="〇",1,0)*0.0000001)+(IF(J8="〇",1,0)*0.00000001)+(IF(J7="〇",1,0)*0.000000001) -> 0.1 | ... V4: =V5+0.1+(IF(V15="〇",1,0)*0.01)+(IF(V14="〇",1,0)*0.001)+(IF(V13="〇",1,0)*0.0001)+(IF(V12="〇",1,0)*0.00001)+(IF(V10="〇",1,0)*0.000001)+(IF(V9="〇",1,0)*0.0000001)+(IF(V8="〇",1,0)*0.00000001)+(IF(V7="〇",1,0)*0.000000001) -> 0.1 | W4: 個人順位用
B5: 個人合計 | C5: =C6+C11 -> 0 | D5: =D6+D11 -> 0 | E5: =E6+E11 -> 0 | F5: =F6+F11 -> 0 | G5: =G6+G11 -> 0 | H5: =H6+H11 -> 0 | I5: =I6+I11 -> 0 | J5: =J6+J11 -> 0 | ... V5: =V6+V11 -> 0 | W5: 個人合計
B6: 2立目 合計 | C6: =COUNTIF(C7:C10,"〇") -> 0 | D6: =COUNTIF(D7:D10,"〇") -> 0 | E6: =COUNTIF(E7:E10,"〇") -> 0 | F6: =COUNTIF(F7:F10,"〇") -> 0 | G6: =COUNTIF(G7:G10,"〇") -> 0 | H6: =COUNTIF(H7:H10,"〇") -> 0 | I6: =COUNTIF(I7:I10,"〇") -> 0 | J6: =COUNTIF(J7:J10,"〇") -> 0 | ... V6: =COUNTIF(V7:V10,"〇") -> 0 | W6: 2立目 合計
B7: 4射 | W7: 4射
B8: 3射 | W8: 3射
B9: 2射 | W9: 2射
B10: 1射 | W10: 1射
B11: 1立目 合計 | C11: =COUNTIF(C12:C15,"〇") -> 0 | D11: =COUNTIF(D12:D15,"〇") -> 0 | E11: =COUNTIF(E12:E15,"〇") -> 0 | F11: =COUNTIF(F12:F15,"〇") -> 0 | G11: =COUNTIF(G12:G15,"〇") -> 0 | H11: =COUNTIF(H12:H15,"〇") -> 0 | I11: =COUNTIF(I12:I15,"〇") -> 0 | J11: =COUNTIF(J12:J15,"〇") -> 0 | ... V11: =COUNTIF(V12:V15,"〇") -> 0 | W11: 1立目 合計
B12: 4射 | W12: 4射
B13: 3射 | W13: 3射
B14: 2射 | W14: 2射
B15: 1射 | W15: 1射
B16: No. | C16: =IF(選手!C21<>"",選手!C21,"") -> 20 | D16: =IF(選手!C20<>"",選手!C20,"") -> 19 | E16: =IF(選手!C19<>"",選手!C19,"") -> 18 | F16: =IF(選手!C18<>"",選手!C18,"") -> 17 | G16: =IF(選手!C17<>"",選手!C17,"") -> 16 | H16: =IF(選手!C16<>"",選手!C16,"") -> 15 | I16: =IF(選手!C15<>"",選手!C15,"") -> 14 | J16: =IF(選手!C14<>"",選手!C14,"") -> 13 | K16: =IF(選手!C13<>"",選手!C13,"") -> 12 | L16: =IF(選手!C12<>"",選手!C12,"") -> 11 | M16: =IF(選手!C11<>"",選手!C11,"") -> 10 | N16: =IF(選手!C10<>"",選手!C10,"") -> 9 | O16: =IF(選手!C9<>"",選手!C9,"") -> 8 | P16: =IF(選手!C8<>"",選手!C8,"") -> 7 | Q16: =IF(選手!C7<>"",選手!C7,"") -> 6 | R16: =IF(選手!C6<>"",選手!C6,"") -> 5 | S16: =IF(選手!C5<>"",選手!C5,"") -> 4 | T16: =IF(選手!C4<>"",選手!C4,"") -> 3 | U16: =IF(選手!C3<>"",選手!C3,"") -> 2 | V16: =IF(選手!C2<>"",選手!C2,"") -> 1 | W16: No.
B17: 性別 | C17: =IF(選手!E21<>"",選手!E21,"") -> 男 | D17: =IF(選手!E20<>"",選手!E20,"") -> 男 | E17: =IF(選手!E19<>"",選手!E19,"") -> 男 | F17: =IF(選手!E18<>"",選手!E18,"") -> 男 | G17: =IF(選手!E17<>"",選手!E17,"") -> 女 | H17: =IF(選手!E16<>"",選手!E16,"") -> 男 | I17: =IF(選手!E15<>"",選手!E15,"") -> 女 | J17: =IF(選手!E14<>"",選手!E14,"") -> 男 | K17: =IF(選手!E13<>"",選手!E13,"") -> 男 | L17: =IF(選手!E12<>"",選手!E12,"") -> 女 | M17: =IF(選手!E11<>"",選手!E11,"") -> 男 | N17: =IF(選手!E10<>"",選手!E10,"") -> 男 | O17: =IF(選手!E9<>"",選手!E9,"") -> 男 | P17: =IF(選手!E8<>"",選手!E8,"") -> 女 | Q17: =IF(選手!E7<>"",選手!E7,"") -> 女 | R17: =IF(選手!E6<>"",選手!E6,"") -> 男 | S17: =IF(選手!E5<>"",選手!E5,"") -> 女 | T17: =IF(選手!E4<>"",選手!E4,"") -> 女 | U17: =IF(選手!E3<>"",選手!E3,"") -> 男 | V17: =IF(選手!E2<>"",選手!E2,"") -> 男 | W17: 性別
B18: 氏 名 | C18: =IF(選手!D21<>"",選手!D21,"") -> 杉山 武 | D18: =IF(選手!D20<>"",選手!D20,"") -> 玉野 正明 | E18: =IF(選手!D19<>"",選手!D19,"") -> 阿部 健二郞 | F18: =IF(選手!D18<>"",選手!D18,"") -> 小川 久生 | G18: =IF(選手!D17<>"",選手!D17,"") -> 荒川 花子 | H18: =IF(選手!D16<>"",選手!D16,"") -> 杉原 伸哉 | I18: =IF(選手!D15<>"",選手!D15,"") -> 渡邉 由美子 | J18: =IF(選手!D14<>"",選手!D14,"") -> 北崎 良治 | K18: =IF(選手!D13<>"",選手!D13,"") -> 加藤 忠人 | L18: =IF(選手!D12<>"",選手!D12,"") -> 村瀬 沙織 | M18: =IF(選手!D11<>"",選手!D11,"") -> 大槻 成実 | N18: =IF(選手!D10<>"",選手!D10,"") -> 丹羽 泰生 | O18: =IF(選手!D9<>"",選手!D9,"") -> 加藤 広史 | P18: =IF(選手!D8<>"",選手!D8,"") -> 瀬山 博子 | Q18: =IF(選手!D7<>"",選手!D7,"") -> 小林 都 | R18: =IF(選手!D6<>"",選手!D6,"") -> 伊藤 寿邦 | S18: =IF(選手!D5<>"",選手!D5,"") -> 森竹 結衣 | T18: =IF(選手!D4<>"",選手!D4,"") -> 谷口 弥生 | U18: =IF(選手!D3<>"",選手!D3,"") -> 加藤 崇文 | V18: =IF(選手!D2<>"",選手!D2,"") -> 野村 清美 | W18: 氏 名
B20: チーム | C20: =選手!G18 -> 春日井B | G20: =選手!G14 -> 日進B | K20: =選手!G10 -> 日進A | O20: =選手!G6 -> 尾張旭B | S20: =選手!G2 -> 尾張旭A | W20: チーム
B21: チーム合計 | C21: =SUM(C23:F23) -> 0 | G21: =SUM(G23:J23) -> 0 | K21: =SUM(K23:N23) -> 0 | O21: =SUM(O23:R23) -> 0 | S21: =SUM(S23:V23) -> 0 | W21: チーム合計
B22: 個人順位用 | C22: =C23+0.1+(IF(C33="〇",1,0)*0.01)+(IF(C32="〇",1,0)*0.001)+(IF(C31="〇",1,0)*0.0001)+(IF(C30="〇",1,0)*0.00001)+(IF(C28="〇",1,0)*0.000001)+(IF(C27="〇",1,0)*0.0000001)+(IF(C26="〇",1,0)*0.00000001)+(IF(C25="〇",1,0)*0.000000001) -> 0.1 | D22: =D23+0.1+(IF(D33="〇",1,0)*0.01)+(IF(D32="〇",1,0)*0.001)+(IF(D31="〇",1,0)*0.0001)+(IF(D30="〇",1,0)*0.00001)+(IF(D28="〇",1,0)*0.000001)+(IF(D27="〇",1,0)*0.0000001)+(IF(D26="〇",1,0)*0.00000001)+(IF(D25="〇",1,0)*0.000000001) -> 0.1 | E22: =E23+0.1+(IF(E33="〇",1,0)*0.01)+(IF(E32="〇",1,0)*0.001)+(IF(E31="〇",1,0)*0.0001)+(IF(E30="〇",1,0)*0.00001)+(IF(E28="〇",1,0)*0.000001)+(IF(E27="〇",1,0)*0.0000001)+(IF(E26="〇",1,0)*0.00000001)+(IF(E25="〇",1,0)*0.000000001) -> 0.1 | F22: =F23+0.1+(IF(F33="〇",1,0)*0.01)+(IF(F32="〇",1,0)*0.001)+(IF(F31="〇",1,0)*0.0001)+(IF(F30="〇",1,0)*0.00001)+(IF(F28="〇",1,0)*0.000001)+(IF(F27="〇",1,0)*0.0000001)+(IF(F26="〇",1,0)*0.00000001)+(IF(F25="〇",1,0)*0.000000001) -> 0.1 | G22: =G23+0.1+(IF(G33="〇",1,0)*0.01)+(IF(G32="〇",1,0)*0.001)+(IF(G31="〇",1,0)*0.0001)+(IF(G30="〇",1,0)*0.00001)+(IF(G28="〇",1,0)*0.000001)+(IF(G27="〇",1,0)*0.0000001)+(IF(G26="〇",1,0)*0.00000001)+(IF(G25="〇",1,0)*0.000000001) -> 0.1 | H22: =H23+0.1+(IF(H33="〇",1,0)*0.01)+(IF(H32="〇",1,0)*0.001)+(IF(H31="〇",1,0)*0.0001)+(IF(H30="〇",1,0)*0.00001)+(IF(H28="〇",1,0)*0.000001)+(IF(H27="〇",1,0)*0.0000001)+(IF(H26="〇",1,0)*0.00000001)+(IF(H25="〇",1,0)*0.000000001) -> 0.1 | I22: =I23+0.1+(IF(I33="〇",1,0)*0.01)+(IF(I32="〇",1,0)*0.001)+(IF(I31="〇",1,0)*0.0001)+(IF(I30="〇",1,0)*0.00001)+(IF(I28="〇",1,0)*0.000001)+(IF(I27="〇",1,0)*0.0000001)+(IF(I26="〇",1,0)*0.00000001)+(IF(I25="〇",1,0)*0.000000001) -> 0.1 | J22: =J23+0.1+(IF(J33="〇",1,0)*0.01)+(IF(J32="〇",1,0)*0.001)+(IF(J31="〇",1,0)*0.0001)+(IF(J30="〇",1,0)*0.00001)+(IF(J28="〇",1,0)*0.000001)+(IF(J27="〇",1,0)*0.0000001)+(IF(J26="〇",1,0)*0.00000001)+(IF(J25="〇",1,0)*0.000000001) -> 0.1 | ... V22: =V23+0.1+(IF(V33="〇",1,0)*0.01)+(IF(V32="〇",1,0)*0.001)+(IF(V31="〇",1,0)*0.0001)+(IF(V30="〇",1,0)*0.00001)+(IF(V28="〇",1,0)*0.000001)+(IF(V27="〇",1,0)*0.0000001)+(IF(V26="〇",1,0)*0.00000001)+(IF(V25="〇",1,0)*0.000000001) -> 0.1 | W22: 個人順位用
B23: 個人合計 | C23: =C24+C29 -> 0 | D23: =D24+D29 -> 0 | E23: =E24+E29 -> 0 | F23: =F24+F29 -> 0 | G23: =G24+G29 -> 0 | H23: =H24+H29 -> 0 | I23: =I24+I29 -> 0 | J23: =J24+J29 -> 0 | ... V23: =V24+V29 -> 0 | W23: 個人合計
B24: 2立目 合計 | C24: =COUNTIF(C25:C28,"〇") -> 0 | D24: =COUNTIF(D25:D28,"〇") -> 0 | E24: =COUNTIF(E25:E28,"〇") -> 0 | F24: =COUNTIF(F25:F28,"〇") -> 0 | G24: =COUNTIF(G25:G28,"〇") -> 0 | H24: =COUNTIF(H25:H28,"〇") -> 0 | I24: =COUNTIF(I25:I28,"〇") -> 0 | J24: =COUNTIF(J25:J28,"〇") -> 0 | ... V24: =COUNTIF(V25:V28,"〇") -> 0 | W24: 2立目 合計
B25: 4射 | W25: 4射
B26: 3射 | W26: 3射
B27: 2射 | W27: 2射
B28: 1射 | W28: 1射
B29: 1立目 合計 | C29: =COUNTIF(C30:C33,"〇") -> 0 | D29: =COUNTIF(D30:D33,"〇") -> 0 | E29: =COUNTIF(E30:E33,"〇") -> 0 | F29: =COUNTIF(F30:F33,"〇") -> 0 | G29: =COUNTIF(G30:G33,"〇") -> 0 | H29: =COUNTIF(H30:H33,"〇") -> 0 | I29: =COUNTIF(I30:I33,"〇") -> 0 | J29: =COUNTIF(J30:J33,"〇") -> 0 | ... V29: =COUNTIF(V30:V33,"〇") -> 0 | W29: 1立目 合計
B30: 4射 | W30: 4射
B31: 3射 | W31: 3射
B32: 2射 | W32: 2射
B33: 1射 | W33: 1射
B34: No. | C34: =IF(選手!H21<>"",選手!H21,"") -> 40 | D34: =IF(選手!H20<>"",選手!H20,"") -> 39 | E34: =IF(選手!H19<>"",選手!H19,"") -> 38 | F34: =IF(選手!H18<>"",選手!H18,"") -> 37 | G34: =IF(選手!H17<>"",選手!H17,"") -> 36 | H34: =IF(選手!H16<>"",選手!H16,"") -> 35 | I34: =IF(選手!H15<>"",選手!H15,"") -> 34 | J34: =IF(選手!H14<>"",選手!H14,"") -> 33 | K34: =IF(選手!H13<>"",選手!H13,"") -> 32 | L34: =IF(選手!H12<>"",選手!H12,"") -> 31 | M34: =IF(選手!H11<>"",選手!H11,"") -> 30 | N34: =IF(選手!H10<>"",選手!H10,"") -> 29 | O34: =IF(選手!H9<>"",選手!H9,"") -> 28 | P34: =IF(選手!H8<>"",選手!H8,"") -> 27 | Q34: =IF(選手!H7<>"",選手!H7,"") -> 26 | R34: =IF(選手!H6<>"",選手!H6,"") -> 25 | S34: =IF(選手!H5<>"",選手!H5,"") -> 24 | T34: =IF(選手!H4<>"",選手!H4,"") -> 23 | U34: =IF(選手!H3<>"",選手!H3,"") -> 22 | V34: =IF(選手!H2<>"",選手!H2,"") -> 21 | W34: No.
B35: 性別 | C35: =IF(選手!J21<>"",選手!J21,"") -> 女 | D35: =IF(選手!J20<>"",選手!J20,"") -> 女 | E35: =IF(選手!J19<>"",選手!J19,"") -> 女 | F35: =IF(選手!J18<>"",選手!J18,"") -> 女 | G35: =IF(選手!J17<>"",選手!J17,"") -> 女 | H35: =IF(選手!J16<>"",選手!J16,"") -> 女 | I35: =IF(選手!J15<>"",選手!J15,"") -> 女 | J35: =IF(選手!J14<>"",選手!J14,"") -> 女 | K35: =IF(選手!J13<>"",選手!J13,"") -> 男 | L35: =IF(選手!J12<>"",選手!J12,"") -> 男 | M35: =IF(選手!J11<>"",選手!J11,"") -> 男 | N35: =IF(選手!J10<>"",選手!J10,"") -> 男 | O35: =IF(選手!J9<>"",選手!J9,"") -> 女 | P35: =IF(選手!J8<>"",選手!J8,"") -> 女 | Q35: =IF(選手!J7<>"",選手!J7,"") -> 女 | R35: =IF(選手!J6<>"",選手!J6,"") -> 女 | S35: =IF(選手!J5<>"",選手!J5,"") -> 男 | T35: =IF(選手!J4<>"",選手!J4,"") -> 男 | U35: =IF(選手!J3<>"",選手!J3,"") -> 男 | V35: =IF(選手!J2<>"",選手!J2,"") -> 男 | W35: 性別
B36: 氏 名 | C36: =IF(選手!I21<>"",選手!I21,"") -> 佃 弘美 | D36: =IF(選手!I20<>"",選手!I20,"") -> 片桐 志保 | E36: =IF(選手!I19<>"",選手!I19,"") -> 山口 このみ | F36: =IF(選手!I18<>"",選手!I18,"") -> 遠藤 恵美子 | G36: =IF(選手!I17<>"",選手!I17,"") -> 赤塚 正子 | H36: =IF(選手!I16<>"",選手!I16,"") -> 谷口 洋子 | I36: =IF(選手!I15<>"",選手!I15,"") -> 浅井 明美 | J36: =IF(選手!I14<>"",選手!I14,"") -> 三田村 静子 | K36: =IF(選手!I13<>"",選手!I13,"") -> 新美 友治 | L36: =IF(選手!I12<>"",選手!I12,"") -> 窪田 達也 | M36: =IF(選手!I11<>"",選手!I11,"") -> 米田 康介 | N36: =IF(選手!I10<>"",選手!I10,"") -> 志手 俊二 | O36: =IF(選手!I7<>"",選手!I7,"") -> 安達 初枝 | P36: =IF(選手!I9<>"",選手!I9,"") -> 田中 沙紀子 | Q36: =IF(選手!I8<>"",選手!I8,"") -> 高田 優子 | R36: =IF(選手!I6<>"",選手!I6,"") -> 北川 裕希子 | S36: =IF(選手!I5<>"",選手!I5,"") -> 西尾 雅司 | T36: =IF(選手!I4<>"",選手!I4,"") -> 山田 英治 | U36: =IF(選手!I3<>"",選手!I3,"") -> 阿知波 正 | V36: =IF(選手!I2<>"",選手!I2,"") -> 大竹 誠 | W36: 氏 名
B38: チーム | C38: =選手!L14 -> 豊明B | G38: =選手!L10 -> 豊明A | K38: =選手!L6 -> 長久手B | O38: =選手!L2 -> 長久手A | S38: チーム | X38: =選手!Q6 -> 0 | AB38: =選手!Q2 -> 0
B39: チーム合計 | C39: =SUM(C41:F41) -> 0 | G39: =SUM(G41:J41) -> 0 | K39: =SUM(K41:N41) -> 0 | O39: =SUM(O41:R41) -> 0 | S39: チーム合計 | X39: =SUM(X41:AA41) -> 0 | AB39: =SUM(AB41:AE41) -> 0
B40: 個人順位用 | C40: =C41+0.1+(IF(C51="〇",1,0)*0.01)+(IF(C50="〇",1,0)*0.001)+(IF(C49="〇",1,0)*0.0001)+(IF(C48="〇",1,0)*0.00001)+(IF(C46="〇",1,0)*0.000001)+(IF(C45="〇",1,0)*0.0000001)+(IF(C44="〇",1,0)*0.00000001)+(IF(C43="〇",1,0)*0.000000001) -> 0.1 | D40: =D41+0.1+(IF(D51="〇",1,0)*0.01)+(IF(D50="〇",1,0)*0.001)+(IF(D49="〇",1,0)*0.0001)+(IF(D48="〇",1,0)*0.00001)+(IF(D46="〇",1,0)*0.000001)+(IF(D45="〇",1,0)*0.0000001)+(IF(D44="〇",1,0)*0.00000001)+(IF(D43="〇",1,0)*0.000000001) -> 0.1 | E40: =E41+0.1+(IF(E51="〇",1,0)*0.01)+(IF(E50="〇",1,0)*0.001)+(IF(E49="〇",1,0)*0.0001)+(IF(E48="〇",1,0)*0.00001)+(IF(E46="〇",1,0)*0.000001)+(IF(E45="〇",1,0)*0.0000001)+(IF(E44="〇",1,0)*0.00000001)+(IF(E43="〇",1,0)*0.000000001) -> 0.1 | F40: =F41+0.1+(IF(F51="〇",1,0)*0.01)+(IF(F50="〇",1,0)*0.001)+(IF(F49="〇",1,0)*0.0001)+(IF(F48="〇",1,0)*0.00001)+(IF(F46="〇",1,0)*0.000001)+(IF(F45="〇",1,0)*0.0000001)+(IF(F44="〇",1,0)*0.00000001)+(IF(F43="〇",1,0)*0.000000001) -> 0.1 | G40: =G41+0.1+(IF(G51="〇",1,0)*0.01)+(IF(G50="〇",1,0)*0.001)+(IF(G49="〇",1,0)*0.0001)+(IF(G48="〇",1,0)*0.00001)+(IF(G46="〇",1,0)*0.000001)+(IF(G45="〇",1,0)*0.0000001)+(IF(G44="〇",1,0)*0.00000001)+(IF(G43="〇",1,0)*0.000000001) -> 0.1 | H40: =H41+0.1+(IF(H51="〇",1,0)*0.01)+(IF(H50="〇",1,0)*0.001)+(IF(H49="〇",1,0)*0.0001)+(IF(H48="〇",1,0)*0.00001)+(IF(H46="〇",1,0)*0.000001)+(IF(H45="〇",1,0)*0.0000001)+(IF(H44="〇",1,0)*0.00000001)+(IF(H43="〇",1,0)*0.000000001) -> 0.1 | I40: =I41+0.1+(IF(I51="〇",1,0)*0.01)+(IF(I50="〇",1,0)*0.001)+(IF(I49="〇",1,0)*0.0001)+(IF(I48="〇",1,0)*0.00001)+(IF(I46="〇",1,0)*0.000001)+(IF(I45="〇",1,0)*0.0000001)+(IF(I44="〇",1,0)*0.00000001)+(IF(I43="〇",1,0)*0.000000001) -> 0.1 | J40: =J41+0.1+(IF(J51="〇",1,0)*0.01)+(IF(J50="〇",1,0)*0.001)+(IF(J49="〇",1,0)*0.0001)+(IF(J48="〇",1,0)*0.00001)+(IF(J46="〇",1,0)*0.000001)+(IF(J45="〇",1,0)*0.0000001)+(IF(J44="〇",1,0)*0.00000001)+(IF(J43="〇",1,0)*0.000000001) -> 0.1 | ... R40: =R41+0.1+(IF(R51="〇",1,0)*0.01)+(IF(R50="〇",1,0)*0.001)+(IF(R49="〇",1,0)*0.0001)+(IF(R48="〇",1,0)*0.00001)+(IF(R46="〇",1,0)*0.000001)+(IF(R45="〇",1,0)*0.0000001)+(IF(R44="〇",1,0)*0.00000001)+(IF(R43="〇",1,0)*0.000000001) -> 0.1 | S40: 個人順位用 | X40: =X41+0.1+(IF(X51="〇",1,0)*0.01)+(IF(X50="〇",1,0)*0.001)+(IF(X49="〇",1,0)*0.0001)+(IF(X48="〇",1,0)*0.00001)+(IF(X46="〇",1,0)*0.000001)+(IF(X45="〇",1,0)*0.0000001)+(IF(X44="〇",1,0)*0.00000001)+(IF(X43="〇",1,0)*0.000000001) -> 0.1 | Y40: =Y41+0.1+(IF(Y51="〇",1,0)*0.01)+(IF(Y50="〇",1,0)*0.001)+(IF(Y49="〇",1,0)*0.0001)+(IF(Y48="〇",1,0)*0.00001)+(IF(Y46="〇",1,0)*0.000001)+(IF(Y45="〇",1,0)*0.0000001)+(IF(Y44="〇",1,0)*0.00000001)+(IF(Y43="〇",1,0)*0.000000001) -> 0.1 | Z40: =Z41+0.1+(IF(Z51="〇",1,0)*0.01)+(IF(Z50="〇",1,0)*0.001)+(IF(Z49="〇",1,0)*0.0001)+(IF(Z48="〇",1,0)*0.00001)+(IF(Z46="〇",1,0)*0.000001)+(IF(Z45="〇",1,0)*0.0000001)+(IF(Z44="〇",1,0)*0.00000001)+(IF(Z43="〇",1,0)*0.000000001) -> 0.1 | AA40: =AA41+0.1+(IF(AA51="〇",1,0)*0.01)+(IF(AA50="〇",1,0)*0.001)+(IF(AA49="〇",1,0)*0.0001)+(IF(AA48="〇",1,0)*0.00001)+(IF(AA46="〇",1,0)*0.000001)+(IF(AA45="〇",1,0)*0.0000001)+(IF(AA44="〇",1,0)*0.00000001)+(IF(AA43="〇",1,0)*0.000000001) -> 0.1 | AB40: =AB41+0.1+(IF(AB51="〇",1,0)*0.01)+(IF(AB50="〇",1,0)*0.001)+(IF(AB49="〇",1,0)*0.0001)+(IF(AB48="〇",1,0)*0.00001)+(IF(AB46="〇",1,0)*0.000001)+(IF(AB45="〇",1,0)*0.0000001)+(IF(AB44="〇",1,0)*0.00000001)+(IF(AB43="〇",1,0)*0.000000001) -> 0.1 | AC40: =AC41+0.1+(IF(AC51="〇",1,0)*0.01)+(IF(AC50="〇",1,0)*0.001)+(IF(AC49="〇",1,0)*0.0001)+(IF(AC48="〇",1,0)*0.00001)+(IF(AC46="〇",1,0)*0.000001)+(IF(AC45="〇",1,0)*0.0000001)+(IF(AC44="〇",1,0)*0.00000001)+(IF(AC43="〇",1,0)*0.000000001) -> 0.1 | AD40: =AD41+0.1+(IF(AD51="〇",1,0)*0.01)+(IF(AD50="〇",1,0)*0.001)+(IF(AD49="〇",1,0)*0.0001)+(IF(AD48="〇",1,0)*0.00001)+(IF(AD46="〇",1,0)*0.000001)+(IF(AD45="〇",1,0)*0.0000001)+(IF(AD44="〇",1,0)*0.00000001)+(IF(AD43="〇",1,0)*0.000000001) -> 0.1 | AE40: =AE41+0.1+(IF(AE51="〇",1,0)*0.01)+(IF(AE50="〇",1,0)*0.001)+(IF(AE49="〇",1,0)*0.0001)+(IF(AE48="〇",1,0)*0.00001)+(IF(AE46="〇",1,0)*0.000001)+(IF(AE45="〇",1,0)*0.0000001)+(IF(AE44="〇",1,0)*0.00000001)+(IF(AE43="〇",1,0)*0.000000001) -> 0.1
B41: 個人合計 | C41: =C42+C47 -> 0 | D41: =D42+D47 -> 0 | E41: =E42+E47 -> 0 | F41: =F42+F47 -> 0 | G41: =G42+G47 -> 0 | H41: =H42+H47 -> 0 | I41: =I42+I47 -> 0 | J41: =J42+J47 -> 0 | ... R41: =R42+R47 -> 0 | S41: 個人合計 | X41: =X42+X47 -> 0 | Y41: =Y42+Y47 -> 0 | Z41: =Z42+Z47 -> 0 | AA41: =AA42+AA47 -> 0 | AB41: =AB42+AB47 -> 0 | AC41: =AC42+AC47 -> 0 | AD41: =AD42+AD47 -> 0 | AE41: =AE42+AE47 -> 0
B42: 2立目 合計 | C42: =COUNTIF(C43:C46,"〇") -> 0 | D42: =COUNTIF(D43:D46,"〇") -> 0 | E42: =COUNTIF(E43:E46,"〇") -> 0 | F42: =COUNTIF(F43:F46,"〇") -> 0 | G42: =COUNTIF(G43:G46,"〇") -> 0 | H42: =COUNTIF(H43:H46,"〇") -> 0 | I42: =COUNTIF(I43:I46,"〇") -> 0 | J42: =COUNTIF(J43:J46,"〇") -> 0 | ... R42: =COUNTIF(R43:R46,"〇") -> 0 | S42: 2立目 合計 | X42: =COUNTIF(X43:X46,"〇") -> 0 | Y42: =COUNTIF(Y43:Y46,"〇") -> 0 | Z42: =COUNTIF(Z43:Z46,"〇") -> 0 | AA42: =COUNTIF(AA43:AA46,"〇") -> 0 | AB42: =COUNTIF(AB43:AB46,"〇") -> 0 | AC42: =COUNTIF(AC43:AC46,"〇") -> 0 | AD42: =COUNTIF(AD43:AD46,"〇") -> 0 | AE42: =COUNTIF(AE43:AE46,"〇") -> 0
B43: 4射 | S43: 4射
...

Sheet 成績　団体
C2: チーム順位表：総合 | J2: チーム順位表：男子 | O2: チーム順位表：女子 | T2: チーム成績
C3: 順位 | D3: チーム名 | E3: 総本数 | F3: 男女 | G3: 列2 | H3: 列3 | J3: 順位 | K3: チーム名 | L3: 総本数 | M3: 列1 | O3: 順位 | P3: チーム名 | Q3: 総本数 | R3: 列1 | T3: チーム名 | U3: 男女区別 | V3: 並び順位 | W3: 表示順位 | X3: 総本数 | Y3: 大前 | Z3: ２的 | AA3: ３的 | AB3: 落ち | AC3: 順位計算
B4: =SMALL(V4:V19, 1) -> 1 | C4: =SMALL(W4:W19, 1) -> 1 | D4: =INDEX(T:T,MATCH(B4,V:V,0)) -> 瀬戸A | E4: =IF(D4="","",INDEX(X:X,MATCH(D4,T:T,0))) -> 0 | F4: =IF(D4="","",INDEX(U:U,MATCH(D4,T:T,0))) -> 男 | G4: =IF($F4="男",ROW(),"") -> 4 | H4: =IF($F4="女",ROW(),"") | J4: =IF(K4="","",_xlfn.RANK.EQ(M4,M4:M19)) -> 1 | K4: =IF(COUNT(G:G)<ROW(A1),"",INDEX(D:D,SMALL(G:G,ROW(A1)))) -> 瀬戸A | L4: =IF(K4="","",INDEX(E:E,MATCH(K4,D:D,0))) -> 0 | M4: =IF(K4="","",INDEX(AC:AC,MATCH(K4,T:T,0))) -> 0 | O4: =IF(P4="","",_xlfn.RANK.EQ(R4,R4:R19)) -> 1 | P4: =IF(COUNT(H:H)<ROW(A1),"",INDEX(D:D,SMALL(H:H,ROW(A1)))) -> 尾張旭B | Q4: =IF(P4="","",INDEX(E:E,MATCH(P4,D:D,0))) -> 0 | R4: =IF(P4="","",INDEX(AC:AC,MATCH(P4,T:T,0))) -> 0 | T4: =IF(選手!B2="","",選手!B2) -> 瀬戸A | U4: =IF(COUNTIF(選手!E2:E5,"男")>0,"男","女") -> 男 | V4: =W4 -> 1 | W4: =_xlfn.RANK.EQ(AC4,AC4:AC19) -> 1 | X4: =SUM(Y4:AB4) -> 0 | Y4: =記録!V5 -> 0 | Z4: =記録!U5 -> 0 | AA4: =記録!T5 -> 0 | AB4: =記録!S5 -> 0 | AC4: =X4+Y4*0.1+Z4*0.01+AA4*0.001+AB4*0.0001 -> 0
B5: =SMALL(V4:V19, 2) -> 2 | C5: =SMALL(W4:W19, 2) -> 1 | D5: =INDEX(T:T,MATCH(B5,V:V,0)) -> 瀬戸B | E5: =IF(D5="","",INDEX(X:X,MATCH(D5,T:T,0))) -> 0 | F5: =IF(D5="","",INDEX(U:U,MATCH(D5,T:T,0))) -> 男 | G5: =IF($F5="男",ROW(),"") -> 5 | H5: =IF($F5="女",ROW(),"") | J5: =IF(K5="","",_xlfn.RANK.EQ(M5,M4:M19)) -> 1 | K5: =IF(COUNT(G:G)<ROW(A2),"",INDEX(D:D,SMALL(G:G,ROW(A2)))) -> 瀬戸B | L5: =IF(K5="","",INDEX(E:E,MATCH(K5,D:D,0))) -> 0 | M5: =IF(K5="","",INDEX(AC:AC,MATCH(K5,T:T,0))) -> 0 | O5: =IF(P5="","",_xlfn.RANK.EQ(R5,R4:R19)) -> 1 | P5: =IF(COUNT(H:H)<ROW(A2),"",INDEX(D:D,SMALL(H:H,ROW(A2)))) -> 日進B | Q5: =IF(P5="","",INDEX(E:E,MATCH(P5,D:D,0))) -> 0 | R5: =IF(P5="","",INDEX(AC:AC,MATCH(P5,T:T,0))) -> 0 | T5: =IF(選手!B6="","",選手!B6) -> 瀬戸B | U5: =IF(COUNTIF(選手!E6:E9,"男")>0,"男","女") -> 男 | V5: =W5+COUNTIF(W4:W5,W5)-1 -> 2 | W5: =_xlfn.RANK.EQ(AC5,AC4:AC19) -> 1 | X5: =SUM(Y5:AB5) -> 0 | Y5: =記録!R5 -> 0 | Z5: =記録!Q5 -> 0 | AA5: =記録!P5 -> 0 | AB5: =記録!O5 -> 0 | AC5: =X5+Y5*0.1+Z5*0.01+AA5*0.001+AB5*0.0001 -> 0
B6: =SMALL(V4:V19, 3) -> 3 | C6: =SMALL(W4:W19, 3) -> 1 | D6: =INDEX(T:T,MATCH(B6,V:V,0)) -> 西春日井A | E6: =IF(D6="","",INDEX(X:X,MATCH(D6,T:T,0))) -> 0 | F6: =IF(D6="","",INDEX(U:U,MATCH(D6,T:T,0))) -> 男 | G6: =IF($F6="男",ROW(),"") -> 6 | H6: =IF($F6="女",ROW(),"") | J6: =IF(K6="","",_xlfn.RANK.EQ(M6,M4:M19)) -> 1 | K6: =IF(COUNT(G:G)<ROW(A3),"",INDEX(D:D,SMALL(G:G,ROW(A3)))) -> 西春日井A | L6: =IF(K6="","",INDEX(E:E,MATCH(K6,D:D,0))) -> 0 | M6: =IF(K6="","",INDEX(AC:AC,MATCH(K6,T:T,0))) -> 0 | O6: =IF(P6="","",_xlfn.RANK.EQ(R6,R4:R19)) -> 1 | P6: =IF(COUNT(H:H)<ROW(A3),"",INDEX(D:D,SMALL(H:H,ROW(A3)))) -> 春日井B | Q6: =IF(P6="","",INDEX(E:E,MATCH(P6,D:D,0))) -> 0 | R6: =IF(P6="","",INDEX(AC:AC,MATCH(P6,T:T,0))) -> 0 | T6: =IF(選手!B10="","",選手!B10) -> 西春日井A | U6: =IF(COUNTIF(選手!E10:E13,"男")>0,"男","女") -> 男 | V6: =W6+COUNTIF(W4:W6,W6)-1 -> 3 | W6: =_xlfn.RANK.EQ(AC6,AC4:AC19) -> 1 | X6: =SUM(Y6:AB6) -> 0 | Y6: =記録!N5 -> 0 | Z6: =記録!M5 -> 0 | AA6: =記録!L5 -> 0 | AB6: =記録!K5 -> 0 | AC6: =X6+Y6*0.1+Z6*0.01+AA6*0.001+AB6*0.0001 -> 0
B7: =SMALL(V4:V19, 4) -> 4 | C7: =SMALL(W4:W19, 4) -> 1 | D7: =INDEX(T:T,MATCH(B7,V:V,0)) -> 西春日井B | E7: =IF(D7="","",INDEX(X:X,MATCH(D7,T:T,0))) -> 0 | F7: =IF(D7="","",INDEX(U:U,MATCH(D7,T:T,0))) -> 男 | G7: =IF($F7="男",ROW(),"") -> 7 | H7: =IF($F7="女",ROW(),"") | J7: =IF(K7="","",_xlfn.RANK.EQ(M7,M4:M19)) -> 1 | K7: =IF(COUNT(G:G)<ROW(A4),"",INDEX(D:D,SMALL(G:G,ROW(A4)))) -> 西春日井B | L7: =IF(K7="","",INDEX(E:E,MATCH(K7,D:D,0))) -> 0 | M7: =IF(K7="","",INDEX(AC:AC,MATCH(K7,T:T,0))) -> 0 | O7: =IF(P7="","",_xlfn.RANK.EQ(R7,R4:R19)) -> 1 | P7: =IF(COUNT(H:H)<ROW(A4),"",INDEX(D:D,SMALL(H:H,ROW(A4)))) -> 長久手B | Q7: =IF(P7="","",INDEX(E:E,MATCH(P7,D:D,0))) -> 0 | R7: =IF(P7="","",INDEX(AC:AC,MATCH(P7,T:T,0))) -> 0 | T7: =IF(選手!B14="","",選手!B14) -> 西春日井B | U7: =IF(COUNTIF(選手!E14:E17,"男")>0,"男","女") -> 男 | V7: =W7+COUNTIF(W4:W7,W7)-1 -> 4 | W7: =_xlfn.RANK.EQ(AC7,AC4:AC19) -> 1 | X7: =SUM(Y7:AB7) -> 0 | Y7: =記録!J5 -> 0 | Z7: =記録!I5 -> 0 | AA7: =記録!H5 -> 0 | AB7: =記録!G5 -> 0 | AC7: =X7+Y7*0.1+Z7*0.01+AA7*0.001+AB7*0.0001 -> 0
B8: =SMALL(V4:V19, 5) -> 5 | C8: =SMALL(W4:W19, 5) -> 1 | D8: =INDEX(T:T,MATCH(B8,V:V,0)) -> 春日井A | E8: =IF(D8="","",INDEX(X:X,MATCH(D8,T:T,0))) -> 0 | F8: =IF(D8="","",INDEX(U:U,MATCH(D8,T:T,0))) -> 男 | G8: =IF($F8="男",ROW(),"") -> 8 | H8: =IF($F8="女",ROW(),"") | J8: =IF(K8="","",_xlfn.RANK.EQ(M8,M4:M19)) -> 1 | K8: =IF(COUNT(G:G)<ROW(A5),"",INDEX(D:D,SMALL(G:G,ROW(A5)))) -> 春日井A | L8: =IF(K8="","",INDEX(E:E,MATCH(K8,D:D,0))) -> 0 | M8: =IF(K8="","",INDEX(AC:AC,MATCH(K8,T:T,0))) -> 0 | O8: =IF(P8="","",_xlfn.RANK.EQ(R8,R4:R19)) -> 1 | P8: =IF(COUNT(H:H)<ROW(A5),"",INDEX(D:D,SMALL(H:H,ROW(A5)))) -> 豊明B | Q8: =IF(P8="","",INDEX(E:E,MATCH(P8,D:D,0))) -> 0 | R8: =IF(P8="","",INDEX(AC:AC,MATCH(P8,T:T,0))) -> 0 | T8: =IF(選手!B1="","",選手!B18) -> 春日井A | U8: =IF(COUNTIF(選手!E18:E21,"男")>0,"男","女") -> 男 | V8: =W8+COUNTIF(W4:W8,W8)-1 -> 5 | W8: =_xlfn.RANK.EQ(AC8,AC4:AC19) -> 1 | X8: =SUM(Y8:AB8) -> 0 | Y8: =記録!F5 -> 0 | Z8: =記録!E5 -> 0 | AA8: =記録!D5 -> 0 | AB8: =記録!C5 -> 0 | AC8: =X8+Y8*0.1+Z8*0.01+AA8*0.001+AB8*0.0001 -> 0
B9: =SMALL(V4:V19, 6) -> 6 | C9: =SMALL(W4:W19, 6) -> 1 | D9: =INDEX(T:T,MATCH(B9,V:V,0)) -> 尾張旭A | E9: =IF(D9="","",INDEX(X:X,MATCH(D9,T:T,0))) -> 0 | F9: =IF(D9="","",INDEX(U:U,MATCH(D9,T:T,0))) -> 男 | G9: =IF($F9="男",ROW(),"") -> 9 | H9: =IF($F9="女",ROW(),"") | J9: =IF(K9="","",_xlfn.RANK.EQ(M9,M4:M19)) -> 1 | K9: =IF(COUNT(G:G)<ROW(A6),"",INDEX(D:D,SMALL(G:G,ROW(A6)))) -> 尾張旭A | L9: =IF(K9="","",INDEX(E:E,MATCH(K9,D:D,0))) -> 0 | M9: =IF(K9="","",INDEX(AC:AC,MATCH(K9,T:T,0))) -> 0 | O9: =IF(P9="","",_xlfn.RANK.EQ(R9,R4:R19)) | P9: =IF(COUNT(H:H)<ROW(A6),"",INDEX(D:D,SMALL(H:H,ROW(A6)))) | Q9: =IF(P9="","",INDEX(E:E,MATCH(P9,D:D,0))) | R9: =IF(P9="","",INDEX(AC:AC,MATCH(P9,T:T,0))) | T9: =IF(選手!G2="","",選手!G2) -> 尾張旭A | U9: =IF(COUNTIF(選手!J2:J5,"男")>0,"男","女") -> 男 | V9: =W9+COUNTIF(W4:W9,W9)-1 -> 6 | W9: =_xlfn.RANK.EQ(AC9,AC4:AC19) -> 1 | X9: =SUM(Y9:AB9) -> 0 | Y9: =記録!V23 -> 0 | Z9: =記録!U23 -> 0 | AA9: =記録!T23 -> 0 | AB9: =記録!S23 -> 0 | AC9: =X9+Y9*0.1+Z9*0.01+AA9*0.001+AB9*0.0001 -> 0
B10: =SMALL(V4:V19, 7) -> 7 | C10: =SMALL(W4:W19, 7) -> 1 | D10: =INDEX(T:T,MATCH(B10,V:V,0)) -> 尾張旭B | E10: =IF(D10="","",INDEX(X:X,MATCH(D10,T:T,0))) -> 0 | F10: =IF(D10="","",INDEX(U:U,MATCH(D10,T:T,0))) -> 女 | G10: =IF($F10="男",ROW(),"") | H10: =IF($F10="女",ROW(),"") -> 10 | J10: =IF(K10="","",_xlfn.RANK.EQ(M10,M4:M19)) -> 1 | K10: =IF(COUNT(G:G)<ROW(A7),"",INDEX(D:D,SMALL(G:G,ROW(A7)))) -> 日進A | L10: =IF(K10="","",INDEX(E:E,MATCH(K10,D:D,0))) -> 0 | M10: =IF(K10="","",INDEX(AC:AC,MATCH(K10,T:T,0))) -> 0 | O10: =IF(P10="","",_xlfn.RANK.EQ(R10,R4:R19)) | P10: =IF(COUNT(H:H)<ROW(A7),"",INDEX(D:D,SMALL(H:H,ROW(A7)))) | Q10: =IF(P10="","",INDEX(E:E,MATCH(P10,D:D,0))) | R10: =IF(P10="","",INDEX(AC:AC,MATCH(P10,T:T,0))) | T10: =IF(選手!G6="","",選手!G6) -> 尾張旭B | U10: =IF(COUNTIF(選手!J6:J9,"男")>0,"男","女") -> 女 | V10: =W10+COUNTIF(W4:W10,W10)-1 -> 7 | W10: =_xlfn.RANK.EQ(AC10,AC4:AC19) -> 1 | X10: =SUM(Y10:AB10) -> 0 | Y10: =記録!R23 -> 0 | Z10: =記録!Q23 -> 0 | AA10: =記録!P23 -> 0 | AB10: =記録!O23 -> 0 | AC10: =X10+Y10*0.1+Z10*0.01+AA10*0.001+AB10*0.0001 -> 0
B11: =SMALL(V4:V19, 8) -> 8 | C11: =SMALL(W4:W19, 8) -> 1 | D11: =INDEX(T:T,MATCH(B11,V:V,0)) -> 日進A | E11: =IF(D11="","",INDEX(X:X,MATCH(D11,T:T,0))) -> 0 | F11: =IF(D11="","",INDEX(U:U,MATCH(D11,T:T,0))) -> 男 | G11: =IF($F11="男",ROW(),"") -> 11 | H11: =IF($F11="女",ROW(),"") | J11: =IF(K11="","",_xlfn.RANK.EQ(M11,M4:M19)) -> 1 | K11: =IF(COUNT(G:G)<ROW(A8),"",INDEX(D:D,SMALL(G:G,ROW(A8)))) -> 長久手A | L11: =IF(K11="","",INDEX(E:E,MATCH(K11,D:D,0))) -> 0 | M11: =IF(K11="","",INDEX(AC:AC,MATCH(K11,T:T,0))) -> 0 | O11: =IF(P11="","",_xlfn.RANK.EQ(R11,R4:R19)) | P11: =IF(COUNT(H:H)<ROW(A8),"",INDEX(D:D,SMALL(H:H,ROW(A8)))) | Q11: =IF(P11="","",INDEX(E:E,MATCH(P11,D:D,0))) | R11: =IF(P11="","",INDEX(AC:AC,MATCH(P11,T:T,0))) | T11: =IF(選手!G10="","",選手!G10) -> 日進A | U11: =IF(COUNTIF(選手!J10:J13,"男")>0,"男","女") -> 男 | V11: =W11+COUNTIF(W4:W11,W11)-1 -> 8 | W11: =_xlfn.RANK.EQ(AC11,AC4:AC19) -> 1 | X11: =SUM(Y11:AB11) -> 0 | Y11: =記録!N23 -> 0 | Z11: =記録!M23 -> 0 | AA11: =記録!L23 -> 0 | AB11: =記録!K23 -> 0 | AC11: =X11+Y11*0.1+Z11*0.01+AA11*0.001+AB11*0.0001 -> 0
B12: =SMALL(V4:V19, 9) -> 9 | C12: =SMALL(W4:W19, 9) -> 1 | D12: =INDEX(T:T,MATCH(B12,V:V,0)) -> 日進B | E12: =IF(D12="","",INDEX(X:X,MATCH(D12,T:T,0))) -> 0 | F12: =IF(D12="","",INDEX(U:U,MATCH(D12,T:T,0))) -> 女 | G12: =IF($F12="男",ROW(),"") | H12: =IF($F12="女",ROW(),"") -> 12 | J12: =IF(K12="","",_xlfn.RANK.EQ(M12,M4:M19)) -> 1 | K12: =IF(COUNT(G:G)<ROW(A9),"",INDEX(D:D,SMALL(G:G,ROW(A9)))) -> 豊明A | L12: =IF(K12="","",INDEX(E:E,MATCH(K12,D:D,0))) -> 0 | M12: =IF(K12="","",INDEX(AC:AC,MATCH(K12,T:T,0))) -> 0 | O12: =IF(P12="","",_xlfn.RANK.EQ(R12,R4:R19)) | P12: =IF(COUNT(H:H)<ROW(A9),"",INDEX(D:D,SMALL(H:H,ROW(A9)))) | Q12: =IF(P12="","",INDEX(E:E,MATCH(P12,D:D,0))) | R12: =IF(P12="","",INDEX(AC:AC,MATCH(P12,T:T,0))) | T12: =IF(選手!G14="","",選手!G14) -> 日進B | U12: =IF(COUNTIF(選手!J14:J17,"男")>0,"男","女") -> 女 | V12: =W12+COUNTIF(W4:W12,W12)-1 -> 9 | W12: =_xlfn.RANK.EQ(AC12,AC4:AC19) -> 1 | X12: =SUM(Y12:AB12) -> 0 | Y12: =記録!J23 -> 0 | Z12: =記録!I23 -> 0 | AA12: =記録!H23 -> 0 | AB12: =記録!G23 -> 0 | AC12: =X12+Y12*0.1+Z12*0.01+AA12*0.001+AB12*0.0001 -> 0
B13: =SMALL(V4:V19, 10) -> 10 | C13: =SMALL(W4:W19, 10) -> 1 | D13: =INDEX(T:T,MATCH(B13,V:V,0)) -> 春日井B | E13: =IF(D13="","",INDEX(X:X,MATCH(D13,T:T,0))) -> 0 | F13: =IF(D13="","",INDEX(U:U,MATCH(D13,T:T,0))) -> 女 | G13: =IF($F13="男",ROW(),"") | H13: =IF($F13="女",ROW(),"") -> 13 | J13: =IF(K13="","",_xlfn.RANK.EQ(M13,M4:M19)) | K13: =IF(COUNT(G:G)<ROW(A10),"",INDEX(D:D,SMALL(G:G,ROW(A10)))) | L13: =IF(K13="","",INDEX(E:E,MATCH(K13,D:D,0))) | M13: =IF(K13="","",INDEX(AC:AC,MATCH(K13,T:T,0))) | O13: =IF(P13="","",_xlfn.RANK.EQ(R13,R4:R19)) | P13: =IF(COUNT(H:H)<ROW(A10),"",INDEX(D:D,SMALL(H:H,ROW(A10)))) | Q13: =IF(P13="","",INDEX(E:E,MATCH(P13,D:D,0))) | R13: =IF(P13="","",INDEX(AC:AC,MATCH(P13,T:T,0))) | T13: =IF(選手!G18="","",選手!G18) -> 春日井B | U13: =IF(COUNTIF(選手!J18:J21,"男")>0,"男","女") -> 女 | V13: =W13+COUNTIF(W4:W13,W13)-1 -> 10 | W13: =_xlfn.RANK.EQ(AC13,AC4:AC19) -> 1 | X13: =SUM(Y13:AB13) -> 0 | Y13: =記録!F23 -> 0 | Z13: =記録!E23 -> 0 | AA13: =記録!D23 -> 0 | AB13: =記録!C23 -> 0 | AC13: =X13+Y13*0.1+Z13*0.01+AA13*0.001+AB13*0.0001 -> 0
B14: =SMALL(V4:V19, 11) -> 11 | C14: =SMALL(W4:W19, 11) -> 1 | D14: =INDEX(T:T,MATCH(B14,V:V,0)) -> 長久手A | E14: =IF(D14="","",INDEX(X:X,MATCH(D14,T:T,0))) -> 0 | F14: =IF(D14="","",INDEX(U:U,MATCH(D14,T:T,0))) -> 男 | G14: =IF($F14="男",ROW(),"") -> 14 | H14: =IF($F14="女",ROW(),"") | J14: =IF(K14="","",_xlfn.RANK.EQ(M14,M4:M19)) | K14: =IF(COUNT(G:G)<ROW(A11),"",INDEX(D:D,SMALL(G:G,ROW(A11)))) | L14: =IF(K14="","",INDEX(E:E,MATCH(K14,D:D,0))) | M14: =IF(K14="","",INDEX(AC:AC,MATCH(K14,T:T,0))) | O14: =IF(P14="","",_xlfn.RANK.EQ(R14,R4:R19)) | P14: =IF(COUNT(H:H)<ROW(A11),"",INDEX(D:D,SMALL(H:H,ROW(A11)))) | Q14: =IF(P14="","",INDEX(E:E,MATCH(P14,D:D,0))) | R14: =IF(P14="","",INDEX(AC:AC,MATCH(P14,T:T,0))) | T14: =IF(選手!L2="","",選手!L2) -> 長久手A | U14: =IF(COUNTIF(選手!O2:O5,"男")>0,"男","女") -> 男 | V14: =W14+COUNTIF(W4:W14,W14)-1 -> 11 | W14: =_xlfn.RANK.EQ(AC14,AC4:AC19) -> 1 | X14: =SUM(Y14:AB14) -> 0 | Y14: =記録!R41 -> 0 | Z14: =記録!Q41 -> 0 | AA14: =記録!P41 -> 0 | AB14: =記録!O41 -> 0 | AC14: =X14+Y14*0.1+Z14*0.01+AA14*0.001+AB14*0.0001 -> 0
B15: =SMALL(V4:V19, 12) -> 12 | C15: =SMALL(W4:W19, 12) -> 1 | D15: =INDEX(T:T,MATCH(B15,V:V,0)) -> 長久手B | E15: =IF(D15="","",INDEX(X:X,MATCH(D15,T:T,0))) -> 0 | F15: =IF(D15="","",INDEX(U:U,MATCH(D15,T:T,0))) -> 女 | G15: =IF($F15="男",ROW(),"") | H15: =IF($F15="女",ROW(),"") -> 15 | J15: =IF(K15="","",_xlfn.RANK.EQ(M15,M4:M19)) | K15: =IF(COUNT(G:G)<ROW(A12),"",INDEX(D:D,SMALL(G:G,ROW(A12)))) | L15: =IF(K15="","",INDEX(E:E,MATCH(K15,D:D,0))) | M15: =IF(K15="","",INDEX(AC:AC,MATCH(K15,T:T,0))) | O15: =IF(P15="","",_xlfn.RANK.EQ(R15,R4:R19)) | P15: =IF(COUNT(H:H)<ROW(A12),"",INDEX(D:D,SMALL(H:H,ROW(A12)))) | Q15: =IF(P15="","",INDEX(E:E,MATCH(P15,D:D,0))) | R15: =IF(P15="","",INDEX(AC:AC,MATCH(P15,T:T,0))) | T15: =IF(選手!L6="","",選手!L6) -> 長久手B | U15: =IF(COUNTIF(選手!O6:O9,"男")>0,"男","女") -> 女 | V15: =W15+COUNTIF(W4:W15,W15)-1 -> 12 | W15: =_xlfn.RANK.EQ(AC15,AC4:AC19) -> 1 | X15: =SUM(Y15:AB15) -> 0 | Y15: =記録!N41 -> 0 | Z15: =記録!M41 -> 0 | AA15: =記録!L41 -> 0 | AB15: =記録!K41 -> 0 | AC15: =X15+Y15*0.1+Z15*0.01+AA15*0.001+AB15*0.0001 -> 0
B16: =SMALL(V4:V19, 13) -> 13 | C16: =SMALL(W4:W19, 13) -> 1 | D16: =INDEX(T:T,MATCH(B16,V:V,0)) -> 豊明A | E16: =IF(D16="","",INDEX(X:X,MATCH(D16,T:T,0))) -> 0 | F16: =IF(D16="","",INDEX(U:U,MATCH(D16,T:T,0))) -> 男 | G16: =IF($F16="男",ROW(),"") -> 16 | H16: =IF($F16="女",ROW(),"") | J16: =IF(K16="","",_xlfn.RANK.EQ(M16,M4:M19)) | K16: =IF(COUNT(G:G)<ROW(A13),"",INDEX(D:D,SMALL(G:G,ROW(A13)))) | L16: =IF(K16="","",INDEX(E:E,MATCH(K16,D:D,0))) | M16: =IF(K16="","",INDEX(AC:AC,MATCH(K16,T:T,0))) | O16: =IF(P16="","",_xlfn.RANK.EQ(R16,R4:R19)) | P16: =IF(COUNT(H:H)<ROW(A13),"",INDEX(D:D,SMALL(H:H,ROW(A13)))) | Q16: =IF(P16="","",INDEX(E:E,MATCH(P16,D:D,0))) | R16: =IF(P16="","",INDEX(AC:AC,MATCH(P16,T:T,0))) | T16: =IF(選手!L10="","",選手!L10) -> 豊明A | U16: =IF(COUNTIF(選手!O10:O13,"男")>0,"男","女") -> 男 | V16: =W16+COUNTIF(W4:W16,W16)-1 -> 13 | W16: =_xlfn.RANK.EQ(AC16,AC4:AC19) -> 1 | X16: =SUM(Y16:AB16) -> 0 | Y16: =記録!J41 -> 0 | Z16: =記録!I41 -> 0 | AA16: =記録!H41 -> 0 | AB16: =記録!G41 -> 0 | AC16: =X16+Y16*0.1+Z16*0.01+AA16*0.001+AB16*0.0001 -> 0
B17: =SMALL(V4:V19, 14) -> 14 | C17: =SMALL(W4:W19, 14) -> 1 | D17: =INDEX(T:T,MATCH(B17,V:V,0)) -> 豊明B | E17: =IF(D17="","",INDEX(X:X,MATCH(D17,T:T,0))) -> 0 | F17: =IF(D17="","",INDEX(U:U,MATCH(D17,T:T,0))) -> 女 | G17: =IF($F17="男",ROW(),"") | H17: =IF($F17="女",ROW(),"") -> 17 | J17: =IF(K17="","",_xlfn.RANK.EQ(M17,M4:M19)) | K17: =IF(COUNT(G:G)<ROW(A14),"",INDEX(D:D,SMALL(G:G,ROW(A14)))) | L17: =IF(K17="","",INDEX(E:E,MATCH(K17,D:D,0))) | M17: =IF(K17="","",INDEX(AC:AC,MATCH(K17,T:T,0))) | O17: =IF(P17="","",_xlfn.RANK.EQ(R17,R4:R19)) | P17: =IF(COUNT(H:H)<ROW(A14),"",INDEX(D:D,SMALL(H:H,ROW(A14)))) | Q17: =IF(P17="","",INDEX(E:E,MATCH(P17,D:D,0))) | R17: =IF(P17="","",INDEX(AC:AC,MATCH(P17,T:T,0))) | T17: =IF(選手!L14="","",選手!L14) -> 豊明B | U17: =IF(COUNTIF(選手!O14:O17,"男")>0,"男","女") -> 女 | V17: =W17+COUNTIF(W4:W17,W17)-1 -> 14 | W17: =_xlfn.RANK.EQ(AC17,AC4:AC19) -> 1 | X17: =SUM(Y17:AB17) -> 0 | Y17: =記録!F41 -> 0 | Z17: =記録!E41 -> 0 | AA17: =記録!D41 -> 0 | AB17: =記録!C41 -> 0 | AC17: =X17+Y17*0.1+Z17*0.01+AA17*0.001+AB17*0.0001 -> 0
B18: =SMALL(V4:V19, 15) -> 15 | C18: =SMALL(W4:W19, 15) -> 1 | D18: =INDEX(T:T,MATCH(B18,V:V,0)) | E18: =IF(D18="","",INDEX(X:X,MATCH(D18,T:T,0))) | F18: =IF(D18="","",INDEX(U:U,MATCH(D18,T:T,0))) | G18: =IF($F18="男",ROW(),"") | H18: =IF($F18="女",ROW(),"") | J18: =IF(K18="","",_xlfn.RANK.EQ(M18,M4:M19)) | K18: =IF(COUNT(G:G)<ROW(A15),"",INDEX(D:D,SMALL(G:G,ROW(A15)))) | L18: =IF(K18="","",INDEX(E:E,MATCH(K18,D:D,0))) | M18: =IF(K18="","",INDEX(AC:AC,MATCH(K18,T:T,0))) | O18: =IF(P18="","",_xlfn.RANK.EQ(R18,R4:R19)) | P18: =IF(COUNT(H:H)<ROW(A15),"",INDEX(D:D,SMALL(H:H,ROW(A15)))) | Q18: =IF(P18="","",INDEX(E:E,MATCH(P18,D:D,0))) | R18: =IF(P18="","",INDEX(AC:AC,MATCH(P18,T:T,0))) | T18: =IF(選手!Q2="","",選手!Q2) | V18: =W18+COUNTIF(W4:W18,W18)-1 -> 15 | W18: =_xlfn.RANK.EQ(AC18,AC4:AC19) -> 1 | X18: =SUM(Y18:AB18) -> 0 | Y18: =記録!AE41 -> 0 | Z18: =記録!AD41 -> 0 | AA18: =記録!AC41 -> 0 | AB18: =記録!AB41 -> 0 | AC18: =X18+Y18*0.1+Z18*0.01+AA18*0.001+AB18*0.0001 -> 0
B19: =SMALL(V4:V19, 16) -> 16 | C19: =SMALL(W4:W19, 16) -> 1 | D19: =INDEX(T:T,MATCH(B19,V:V,0)) | E19: =IF(D19="","",INDEX(X:X,MATCH(D19,T:T,0))) | F19: =IF(D19="","",INDEX(U:U,MATCH(D19,T:T,0))) | G19: =IF($F19="男",ROW(),"") | H19: =IF($F19="女",ROW(),"") | J19: =IF(K19="","",_xlfn.RANK.EQ(M19,M4:M19)) | K19: =IF(COUNT(G:G)<ROW(A16),"",INDEX(D:D,SMALL(G:G,ROW(A16)))) | L19: =IF(K19="","",INDEX(E:E,MATCH(K19,D:D,0))) | M19: =IF(K19="","",INDEX(AC:AC,MATCH(K19,T:T,0))) | O19: =IF(P19="","",_xlfn.RANK.EQ(R19,R4:R19)) | P19: =IF(COUNT(H:H)<ROW(A16),"",INDEX(D:D,SMALL(H:H,ROW(A16)))) | Q19: =IF(P19="","",INDEX(E:E,MATCH(P19,D:D,0))) | R19: =IF(P19="","",INDEX(AC:AC,MATCH(P19,T:T,0))) | T19: =IF(選手!Q6="","",選手!Q6) | V19: =W19+COUNTIF(W4:W19,W19)-1 -> 16 | W19: =_xlfn.RANK.EQ(AC19,AC4:AC19) -> 1 | X19: =SUM(Y19:AB19) -> 0 | Y19: =記録!AA41 -> 0 | Z19: =記録!Z41 -> 0 | AA19: =記録!Y41 -> 0 | AB19: =記録!X41 -> 0 | AC19: =X19+Y19*0.1+Z19*0.01+AA19*0.001+AB19*0.0001 -> 0

Sheet 成績　個人
C1: 個人順位表：男女混合 | L1: 個人順位表：男性 | S1: 個人順位表：女性
C2: 順位 | D2: チーム | E2: No. | F2: 氏名 | G2: 性別 | H2: 総本数 | L2: 順位 | M2: チーム | N2: No. | O2: 氏名 | P2: 総本数 | S2: 順位 | T2: チーム | U2: No. | V2: 氏名 | W2: 総本数 | Z2: チーム | AA2: No. | AB2: 氏名 | AC2: 性別 | AD2: 総本数 | AE2: 計算数 | AF2: 並び順位 | AG2: 表示順位
B3: 1 | C3: =SMALL(AG:AG, B3) -> 1 | D3: =INDEX(Z:Z,MATCH(B3,AF:AF,0)) -> 瀬戸A | E3: =INDEX(AA:AA,MATCH(B3,AF:AF,0)) -> 1 | F3: =INDEX(AB:AB,MATCH(B3,AF:AF,0)) -> 野村 清美 | G3: =INDEX(AC:AC,MATCH(B3,AF:AF,0)) -> 男 | H3: =INDEX(AD:AD,MATCH(F3,AB:AB,0)) -> 0 | I3: =IF($G3="男",ROW(),"") -> 3 | J3: =IF($G3="女",ROW(),"") | L3: =IF(O3="","",_xlfn.RANK.EQ(Q3,Q:Q)) -> 1 | M3: =IF(O3="","",INDEX(D:D,MATCH(O3,F:F,0))) -> 瀬戸A | N3: =IF(O3="","",INDEX(E:E,MATCH(O3,F:F,0))) -> 1 | O3: =IF(COUNT(I:I)<ROW(B1),"",INDEX(F:F,SMALL(I:I,ROW(B1)))) -> 野村 清美 | P3: =IF(O3="","",INDEX(H:H,MATCH(O3,F:F,0))) -> 0 | Q3: =IF(O3="","",INDEX(AE:AE,MATCH(O3,AB:AB,0))) -> 0.1 | S3: =IF(V3="","",_xlfn.RANK.EQ(X3,X:X)) -> 1 | T3: =IF(V3="","",INDEX(D:D,MATCH(V3,F:F,0))) -> 瀬戸A | U3: =IF(V3="","",INDEX(E:E,MATCH(V3,F:F,0))) -> 3 | V3: =IF(COUNT(J:J)<ROW(B1),"",INDEX(F:F,SMALL(J:J,ROW(B1)))) -> 谷口 弥生 | W3: =IF(V3="","",INDEX(H:H,MATCH(V3,F:F,0))) -> 0 | X3: =IF(V3="","",INDEX(AE:AE,MATCH(V3,AB:AB,0))) -> 0.1 | Z3: =IF(選手!B2="","",選手!B2) -> 瀬戸A | AA3: =IF(選手!C2="","",選手!C2) -> 1 | AB3: =IF(選手!D2="","",選手!D2) -> 野村 清美 | AC3: =IF(選手!E2="","",選手!E2) -> 男 | AD3: =記録!V5 -> 0 | AE3: =記録!V4 -> 0.1 | AF3: =AG3 -> 1 | AG3: =_xlfn.RANK.EQ(AE3,AE:AE) -> 1
B4: 2 | C4: =SMALL(AG:AG, B4) -> 1 | D4: =INDEX(Z:Z,MATCH(B4,AF:AF,0)) -> 瀬戸A | E4: =INDEX(AA:AA,MATCH(B4,AF:AF,0)) -> 2 | F4: =INDEX(AB:AB,MATCH(B4,AF:AF,0)) -> 加藤 崇文 | G4: =INDEX(AC:AC,MATCH(B4,AF:AF,0)) -> 男 | H4: =INDEX(AD:AD,MATCH(F4,AB:AB,0)) -> 0 | I4: =IF($G4="男",ROW(),"") -> 4 | J4: =IF($G4="女",ROW(),"") | L4: =IF(O4="","",_xlfn.RANK.EQ(Q4,Q:Q)) -> 1 | M4: =IF(O4="","",INDEX(D:D,MATCH(O4,F:F,0))) -> 瀬戸A | N4: =IF(O4="","",INDEX(E:E,MATCH(O4,F:F,0))) -> 2 | O4: =IF(COUNT(I:I)<ROW(B2),"",INDEX(F:F,SMALL(I:I,ROW(B2)))) -> 加藤 崇文 | P4: =IF(O4="","",INDEX(H:H,MATCH(O4,F:F,0))) -> 0 | Q4: =IF(O4="","",INDEX(AE:AE,MATCH(O4,AB:AB,0))) -> 0.1 | S4: =IF(V4="","",_xlfn.RANK.EQ(X4,X:X)) -> 1 | T4: =IF(V4="","",INDEX(D:D,MATCH(V4,F:F,0))) -> 瀬戸A | U4: =IF(V4="","",INDEX(E:E,MATCH(V4,F:F,0))) -> 4 | V4: =IF(COUNT(J:J)<ROW(B2),"",INDEX(F:F,SMALL(J:J,ROW(B2)))) -> 森竹 結衣 | W4: =IF(V4="","",INDEX(H:H,MATCH(V4,F:F,0))) -> 0 | X4: =IF(V4="","",INDEX(AE:AE,MATCH(V4,AB:AB,0))) -> 0.1 | Z4: =IF(選手!B3="","",選手!B3) -> 瀬戸A | AA4: =IF(選手!C3="","",選手!C3) -> 2 | AB4: =IF(選手!D3="","",選手!D3) -> 加藤 崇文 | AC4: =IF(選手!E3="","",選手!E3) -> 男 | AD4: =記録!U5 -> 0 | AE4: =記録!U4 -> 0.1 | AF4: =AG4+COUNTIF(AG3:AG4,AG4)-1 -> 2 | AG4: =_xlfn.RANK.EQ(AE4,AE:AE) -> 1
B5: 3 | C5: =SMALL(AG:AG, B5) -> 1 | D5: =INDEX(Z:Z,MATCH(B5,AF:AF,0)) -> 瀬戸A | E5: =INDEX(AA:AA,MATCH(B5,AF:AF,0)) -> 3 | F5: =INDEX(AB:AB,MATCH(B5,AF:AF,0)) -> 谷口 弥生 | G5: =INDEX(AC:AC,MATCH(B5,AF:AF,0)) -> 女 | H5: =INDEX(AD:AD,MATCH(F5,AB:AB,0)) -> 0 | I5: =IF($G5="男",ROW(),"") | J5: =IF($G5="女",ROW(),"") -> 5 | L5: =IF(O5="","",_xlfn.RANK.EQ(Q5,Q:Q)) -> 1 | M5: =IF(O5="","",INDEX(D:D,MATCH(O5,F:F,0))) -> 瀬戸B | N5: =IF(O5="","",INDEX(E:E,MATCH(O5,F:F,0))) -> 5 | O5: =IF(COUNT(I:I)<ROW(B3),"",INDEX(F:F,SMALL(I:I,ROW(B3)))) -> 伊藤 寿邦 | P5: =IF(O5="","",INDEX(H:H,MATCH(O5,F:F,0))) -> 0 | Q5: =IF(O5="","",INDEX(AE:AE,MATCH(O5,AB:AB,0))) -> 0.1 | S5: =IF(V5="","",_xlfn.RANK.EQ(X5,X:X)) -> 1 | T5: =IF(V5="","",INDEX(D:D,MATCH(V5,F:F,0))) -> 瀬戸B | U5: =IF(V5="","",INDEX(E:E,MATCH(V5,F:F,0))) -> 6 | V5: =IF(COUNT(J:J)<ROW(B3),"",INDEX(F:F,SMALL(J:J,ROW(B3)))) -> 小林 都 | W5: =IF(V5="","",INDEX(H:H,MATCH(V5,F:F,0))) -> 0 | X5: =IF(V5="","",INDEX(AE:AE,MATCH(V5,AB:AB,0))) -> 0.1 | Z5: =IF(選手!B4="","",選手!B4) -> 瀬戸A | AA5: =IF(選手!C4="","",選手!C4) -> 3 | AB5: =IF(選手!D4="","",選手!D4) -> 谷口 弥生 | AC5: =IF(選手!E4="","",選手!E4) -> 女 | AD5: =記録!T5 -> 0 | AE5: =記録!T4 -> 0.1 | AF5: =AG5+COUNTIF(AG3:AG5,AG5)-1 -> 3 | AG5: =_xlfn.RANK.EQ(AE5,AE:AE) -> 1
B6: 4 | C6: =SMALL(AG:AG, B6) -> 1 | D6: =INDEX(Z:Z,MATCH(B6,AF:AF,0)) -> 瀬戸A | E6: =INDEX(AA:AA,MATCH(B6,AF:AF,0)) -> 4 | F6: =INDEX(AB:AB,MATCH(B6,AF:AF,0)) -> 森竹 結衣 | G6: =INDEX(AC:AC,MATCH(B6,AF:AF,0)) -> 女 | H6: =INDEX(AD:AD,MATCH(F6,AB:AB,0)) -> 0 | I6: =IF($G6="男",ROW(),"") | J6: =IF($G6="女",ROW(),"") -> 6 | L6: =IF(O6="","",_xlfn.RANK.EQ(Q6,Q:Q)) -> 1 | M6: =IF(O6="","",INDEX(D:D,MATCH(O6,F:F,0))) -> 瀬戸B | N6: =IF(O6="","",INDEX(E:E,MATCH(O6,F:F,0))) -> 8 | O6: =IF(COUNT(I:I)<ROW(B4),"",INDEX(F:F,SMALL(I:I,ROW(B4)))) -> 加藤 広史 | P6: =IF(O6="","",INDEX(H:H,MATCH(O6,F:F,0))) -> 0 | Q6: =IF(O6="","",INDEX(AE:AE,MATCH(O6,AB:AB,0))) -> 0.1 | S6: =IF(V6="","",_xlfn.RANK.EQ(X6,X:X)) -> 1 | T6: =IF(V6="","",INDEX(D:D,MATCH(V6,F:F,0))) -> 瀬戸B | U6: =IF(V6="","",INDEX(E:E,MATCH(V6,F:F,0))) -> 7 | V6: =IF(COUNT(J:J)<ROW(B4),"",INDEX(F:F,SMALL(J:J,ROW(B4)))) -> 瀬山 博子 | W6: =IF(V6="","",INDEX(H:H,MATCH(V6,F:F,0))) -> 0 | X6: =IF(V6="","",INDEX(AE:AE,MATCH(V6,AB:AB,0))) -> 0.1 | Z6: =IF(選手!B5="","",選手!B5) -> 瀬戸A | AA6: =IF(選手!C5="","",選手!C5) -> 4 | AB6: =IF(選手!D5="","",選手!D5) -> 森竹 結衣 | AC6: =IF(選手!E5="","",選手!E5) -> 女 | AD6: =記録!S5 -> 0 | AE6: =記録!S4 -> 0.1 | AF6: =AG6+COUNTIF(AG3:AG6,AG6)-1 -> 4 | AG6: =_xlfn.RANK.EQ(AE6,AE:AE) -> 1
B7: 5 | C7: =SMALL(AG:AG, B7) -> 1 | D7: =INDEX(Z:Z,MATCH(B7,AF:AF,0)) -> 瀬戸B | E7: =INDEX(AA:AA,MATCH(B7,AF:AF,0)) -> 5 | F7: =INDEX(AB:AB,MATCH(B7,AF:AF,0)) -> 伊藤 寿邦 | G7: =INDEX(AC:AC,MATCH(B7,AF:AF,0)) -> 男 | H7: =INDEX(AD:AD,MATCH(F7,AB:AB,0)) -> 0 | I7: =IF($G7="男",ROW(),"") -> 7 | J7: =IF($G7="女",ROW(),"") | L7: =IF(O7="","",_xlfn.RANK.EQ(Q7,Q:Q)) -> 1 | M7: =IF(O7="","",INDEX(D:D,MATCH(O7,F:F,0))) -> 西春日井A | N7: =IF(O7="","",INDEX(E:E,MATCH(O7,F:F,0))) -> 9 | O7: =IF(COUNT(I:I)<ROW(B5),"",INDEX(F:F,SMALL(I:I,ROW(B5)))) -> 丹羽 泰生 | P7: =IF(O7="","",INDEX(H:H,MATCH(O7,F:F,0))) -> 0 | Q7: =IF(O7="","",INDEX(AE:AE,MATCH(O7,AB:AB,0))) -> 0.1 | S7: =IF(V7="","",_xlfn.RANK.EQ(X7,X:X)) -> 1 | T7: =IF(V7="","",INDEX(D:D,MATCH(V7,F:F,0))) -> 西春日井A | U7: =IF(V7="","",INDEX(E:E,MATCH(V7,F:F,0))) -> 11 | V7: =IF(COUNT(J:J)<ROW(B5),"",INDEX(F:F,SMALL(J:J,ROW(B5)))) -> 村瀬 沙織 | W7: =IF(V7="","",INDEX(H:H,MATCH(V7,F:F,0))) -> 0 | X7: =IF(V7="","",INDEX(AE:AE,MATCH(V7,AB:AB,0))) -> 0.1 | Z7: =IF(選手!B6="","",選手!B6) -> 瀬戸B | AA7: =IF(選手!C6="","",選手!C6) -> 5 | AB7: =IF(選手!D6="","",選手!D6) -> 伊藤 寿邦 | AC7: =IF(選手!E6="","",選手!E6) -> 男 | AD7: =記録!R5 -> 0 | AE7: =記録!R4 -> 0.1 | AF7: =AG7+COUNTIF(AG3:AG7,AG7)-1 -> 5 | AG7: =_xlfn.RANK.EQ(AE7,AE:AE) -> 1
B8: 6 | C8: =SMALL(AG:AG, B8) -> 1 | D8: =INDEX(Z:Z,MATCH(B8,AF:AF,0)) -> 瀬戸B | E8: =INDEX(AA:AA,MATCH(B8,AF:AF,0)) -> 6 | F8: =INDEX(AB:AB,MATCH(B8,AF:AF,0)) -> 小林 都 | G8: =INDEX(AC:AC,MATCH(B8,AF:AF,0)) -> 女 | H8: =INDEX(AD:AD,MATCH(F8,AB:AB,0)) -> 0 | I8: =IF($G8="男",ROW(),"") | J8: =IF($G8="女",ROW(),"") -> 8 | L8: =IF(O8="","",_xlfn.RANK.EQ(Q8,Q:Q)) -> 1 | M8: =IF(O8="","",INDEX(D:D,MATCH(O8,F:F,0))) -> 西春日井A | N8: =IF(O8="","",INDEX(E:E,MATCH(O8,F:F,0))) -> 10 | O8: =IF(COUNT(I:I)<ROW(B6),"",INDEX(F:F,SMALL(I:I,ROW(B6)))) -> 大槻 成実 | P8: =IF(O8="","",INDEX(H:H,MATCH(O8,F:F,0))) -> 0 | Q8: =IF(O8="","",INDEX(AE:AE,MATCH(O8,AB:AB,0))) -> 0.1 | S8: =IF(V8="","",_xlfn.RANK.EQ(X8,X:X)) -> 1 | T8: =IF(V8="","",INDEX(D:D,MATCH(V8,F:F,0))) -> 西春日井B | U8: =IF(V8="","",INDEX(E:E,MATCH(V8,F:F,0))) -> 14 | V8: =IF(COUNT(J:J)<ROW(B6),"",INDEX(F:F,SMALL(J:J,ROW(B6)))) -> 渡邉 由美子 | W8: =IF(V8="","",INDEX(H:H,MATCH(V8,F:F,0))) -> 0 | X8: =IF(V8="","",INDEX(AE:AE,MATCH(V8,AB:AB,0))) -> 0.1 | Z8: =IF(選手!B7="","",選手!B7) -> 瀬戸B | AA8: =IF(選手!C7="","",選手!C7) -> 6 | AB8: =IF(選手!D7="","",選手!D7) -> 小林 都 | AC8: =IF(選手!E7="","",選手!E7) -> 女 | AD8: =記録!Q5 -> 0 | AE8: =記録!Q4 -> 0.1 | AF8: =AG8+COUNTIF(AG3:AG8,AG8)-1 -> 6 | AG8: =_xlfn.RANK.EQ(AE8,AE:AE) -> 1
B9: 7 | C9: =SMALL(AG:AG, B9) -> 1 | D9: =INDEX(Z:Z,MATCH(B9,AF:AF,0)) -> 瀬戸B | E9: =INDEX(AA:AA,MATCH(B9,AF:AF,0)) -> 7 | F9: =INDEX(AB:AB,MATCH(B9,AF:AF,0)) -> 瀬山 博子 | G9: =INDEX(AC:AC,MATCH(B9,AF:AF,0)) -> 女 | H9: =INDEX(AD:AD,MATCH(F9,AB:AB,0)) -> 0 | I9: =IF($G9="男",ROW(),"") | J9: =IF($G9="女",ROW(),"") -> 9 | L9: =IF(O9="","",_xlfn.RANK.EQ(Q9,Q:Q)) -> 1 | M9: =IF(O9="","",INDEX(D:D,MATCH(O9,F:F,0))) -> 西春日井A | N9: =IF(O9="","",INDEX(E:E,MATCH(O9,F:F,0))) -> 12 | O9: =IF(COUNT(I:I)<ROW(B7),"",INDEX(F:F,SMALL(I:I,ROW(B7)))) -> 加藤 忠人 | P9: =IF(O9="","",INDEX(H:H,MATCH(O9,F:F,0))) -> 0 | Q9: =IF(O9="","",INDEX(AE:AE,MATCH(O9,AB:AB,0))) -> 0.1 | S9: =IF(V9="","",_xlfn.RANK.EQ(X9,X:X)) -> 1 | T9: =IF(V9="","",INDEX(D:D,MATCH(V9,F:F,0))) -> 西春日井B | U9: =IF(V9="","",INDEX(E:E,MATCH(V9,F:F,0))) -> 16 | V9: =IF(COUNT(J:J)<ROW(B7),"",INDEX(F:F,SMALL(J:J,ROW(B7)))) -> 荒川 花子 | W9: =IF(V9="","",INDEX(H:H,MATCH(V9,F:F,0))) -> 0 | X9: =IF(V9="","",INDEX(AE:AE,MATCH(V9,AB:AB,0))) -> 0.1 | Z9: =IF(選手!B8="","",選手!B8) -> 瀬戸B | AA9: =IF(選手!C8="","",選手!C8) -> 7 | AB9: =IF(選手!D8="","",選手!D8) -> 瀬山 博子 | AC9: =IF(選手!E8="","",選手!E8) -> 女 | AD9: =記録!P5 -> 0 | AE9: =記録!P4 -> 0.1 | AF9: =AG9+COUNTIF(AG3:AG9,AG9)-1 -> 7 | AG9: =_xlfn.RANK.EQ(AE9,AE:AE) -> 1
B10: 8 | C10: =SMALL(AG:AG, B10) -> 1 | D10: =INDEX(Z:Z,MATCH(B10,AF:AF,0)) -> 瀬戸B | E10: =INDEX(AA:AA,MATCH(B10,AF:AF,0)) -> 8 | F10: =INDEX(AB:AB,MATCH(B10,AF:AF,0)) -> 加藤 広史 | G10: =INDEX(AC:AC,MATCH(B10,AF:AF,0)) -> 男 | H10: =INDEX(AD:AD,MATCH(F10,AB:AB,0)) -> 0 | I10: =IF($G10="男",ROW(),"") -> 10 | J10: =IF($G10="女",ROW(),"") | L10: =IF(O10="","",_xlfn.RANK.EQ(Q10,Q:Q)) -> 1 | M10: =IF(O10="","",INDEX(D:D,MATCH(O10,F:F,0))) -> 西春日井B | N10: =IF(O10="","",INDEX(E:E,MATCH(O10,F:F,0))) -> 13 | O10: =IF(COUNT(I:I)<ROW(B8),"",INDEX(F:F,SMALL(I:I,ROW(B8)))) -> 北崎 良治 | P10: =IF(O10="","",INDEX(H:H,MATCH(O10,F:F,0))) -> 0 | Q10: =IF(O10="","",INDEX(AE:AE,MATCH(O10,AB:AB,0))) -> 0.1 | S10: =IF(V10="","",_xlfn.RANK.EQ(X10,X:X)) -> 1 | T10: =IF(V10="","",INDEX(D:D,MATCH(V10,F:F,0))) -> 尾張旭B | U10: =IF(V10="","",INDEX(E:E,MATCH(V10,F:F,0))) -> 25 | V10: =IF(COUNT(J:J)<ROW(B8),"",INDEX(F:F,SMALL(J:J,ROW(B8)))) -> 北川 裕希子 | W10: =IF(V10="","",INDEX(H:H,MATCH(V10,F:F,0))) -> 0 | X10: =IF(V10="","",INDEX(AE:AE,MATCH(V10,AB:AB,0))) -> 0.1 | Z10: =IF(選手!B9="","",選手!B9) -> 瀬戸B | AA10: =IF(選手!C9="","",選手!C9) -> 8 | AB10: =IF(選手!D9="","",選手!D9) -> 加藤 広史 | AC10: =IF(選手!E9="","",選手!E9) -> 男 | AD10: =記録!O5 -> 0 | AE10: =記録!O4 -> 0.1 | AF10: =AG10+COUNTIF(AG3:AG10,AG10)-1 -> 8 | AG10: =_xlfn.RANK.EQ(AE10,AE:AE) -> 1
B11: 9 | C11: =SMALL(AG:AG, B11) -> 1 | D11: =INDEX(Z:Z,MATCH(B11,AF:AF,0)) -> 西春日井A | E11: =INDEX(AA:AA,MATCH(B11,AF:AF,0)) -> 9 | F11: =INDEX(AB:AB,MATCH(B11,AF:AF,0)) -> 丹羽 泰生 | G11: =INDEX(AC:AC,MATCH(B11,AF:AF,0)) -> 男 | H11: =INDEX(AD:AD,MATCH(F11,AB:AB,0)) -> 0 | I11: =IF($G11="男",ROW(),"") -> 11 | J11: =IF($G11="女",ROW(),"") | L11: =IF(O11="","",_xlfn.RANK.EQ(Q11,Q:Q)) -> 1 | M11: =IF(O11="","",INDEX(D:D,MATCH(O11,F:F,0))) -> 西春日井B | N11: =IF(O11="","",INDEX(E:E,MATCH(O11,F:F,0))) -> 15 | O11: =IF(COUNT(I:I)<ROW(B9),"",INDEX(F:F,SMALL(I:I,ROW(B9)))) -> 杉原 伸哉 | P11: =IF(O11="","",INDEX(H:H,MATCH(O11,F:F,0))) -> 0 | Q11: =IF(O11="","",INDEX(AE:AE,MATCH(O11,AB:AB,0))) -> 0.1 | S11: =IF(V11="","",_xlfn.RANK.EQ(X11,X:X)) -> 1 | T11: =IF(V11="","",INDEX(D:D,MATCH(V11,F:F,0))) -> 尾張旭B | U11: =IF(V11="","",INDEX(E:E,MATCH(V11,F:F,0))) -> 26 | V11: =IF(COUNT(J:J)<ROW(B9),"",INDEX(F:F,SMALL(J:J,ROW(B9)))) -> 安達 初枝 | W11: =IF(V11="","",INDEX(H:H,MATCH(V11,F:F,0))) -> 0 | X11: =IF(V11="","",INDEX(AE:AE,MATCH(V11,AB:AB,0))) -> 0.1 | Z11: =IF(選手!B10="","",選手!B10) -> 西春日井A | AA11: =IF(選手!C10="","",選手!C10) -> 9 | AB11: =IF(選手!D10="","",選手!D10) -> 丹羽 泰生 | AC11: =IF(選手!E10="","",選手!E10) -> 男 | AD11: =記録!N5 -> 0 | AE11: =記録!N4 -> 0.1 | AF11: =AG11+COUNTIF(AG3:AG11,AG11)-1 -> 9 | AG11: =_xlfn.RANK.EQ(AE11,AE:AE) -> 1
B12: 10 | C12: =SMALL(AG:AG, B12) -> 1 | D12: =INDEX(Z:Z,MATCH(B12,AF:AF,0)) -> 西春日井A | E12: =INDEX(AA:AA,MATCH(B12,AF:AF,0)) -> 10 | F12: =INDEX(AB:AB,MATCH(B12,AF:AF,0)) -> 大槻 成実 | G12: =INDEX(AC:AC,MATCH(B12,AF:AF,0)) -> 男 | H12: =INDEX(AD:AD,MATCH(F12,AB:AB,0)) -> 0 | I12: =IF($G12="男",ROW(),"") -> 12 | J12: =IF($G12="女",ROW(),"") | L12: =IF(O12="","",_xlfn.RANK.EQ(Q12,Q:Q)) -> 1 | M12: =IF(O12="","",INDEX(D:D,MATCH(O12,F:F,0))) -> 春日井A | N12: =IF(O12="","",INDEX(E:E,MATCH(O12,F:F,0))) -> 17 | O12: =IF(COUNT(I:I)<ROW(B10),"",INDEX(F:F,SMALL(I:I,ROW(B10)))) -> 小川 久生 | P12: =IF(O12="","",INDEX(H:H,MATCH(O12,F:F,0))) -> 0 | Q12: =IF(O12="","",INDEX(AE:AE,MATCH(O12,AB:AB,0))) -> 0.1 | S12: =IF(V12="","",_xlfn.RANK.EQ(X12,X:X)) -> 1 | T12: =IF(V12="","",INDEX(D:D,MATCH(V12,F:F,0))) -> 尾張旭B | U12: =IF(V12="","",INDEX(E:E,MATCH(V12,F:F,0))) -> 27 | V12: =IF(COUNT(J:J)<ROW(B10),"",INDEX(F:F,SMALL(J:J,ROW(B10)))) -> 高田 優子 | W12: =IF(V12="","",INDEX(H:H,MATCH(V12,F:F,0))) -> 0 | X12: =IF(V12="","",INDEX(AE:AE,MATCH(V12,AB:AB,0))) -> 0.1 | Z12: =IF(選手!B11="","",選手!B11) -> 西春日井A | AA12: =IF(選手!C11="","",選手!C11) -> 10 | AB12: =IF(選手!D11="","",選手!D11) -> 大槻 成実 | AC12: =IF(選手!E11="","",選手!E11) -> 男 | AD12: =記録!M5 -> 0 | AE12: =記録!M4 -> 0.1 | AF12: =AG12+COUNTIF(AG3:AG12,AG12)-1 -> 10 | AG12: =_xlfn.RANK.EQ(AE12,AE:AE) -> 1
B13: 11 | C13: =SMALL(AG:AG, B13) -> 1 | D13: =INDEX(Z:Z,MATCH(B13,AF:AF,0)) -> 西春日井A | E13: =INDEX(AA:AA,MATCH(B13,AF:AF,0)) -> 11 | F13: =INDEX(AB:AB,MATCH(B13,AF:AF,0)) -> 村瀬 沙織 | G13: =INDEX(AC:AC,MATCH(B13,AF:AF,0)) -> 女 | H13: =INDEX(AD:AD,MATCH(F13,AB:AB,0)) -> 0 | I13: =IF($G13="男",ROW(),"") | J13: =IF($G13="女",ROW(),"") -> 13 | L13: =IF(O13="","",_xlfn.RANK.EQ(Q13,Q:Q)) -> 1 | M13: =IF(O13="","",INDEX(D:D,MATCH(O13,F:F,0))) -> 春日井A | N13: =IF(O13="","",INDEX(E:E,MATCH(O13,F:F,0))) -> 18 | O13: =IF(COUNT(I:I)<ROW(B11),"",INDEX(F:F,SMALL(I:I,ROW(B11)))) -> 阿部 健二郞 | P13: =IF(O13="","",INDEX(H:H,MATCH(O13,F:F,0))) -> 0 | Q13: =IF(O13="","",INDEX(AE:AE,MATCH(O13,AB:AB,0))) -> 0.1 | S13: =IF(V13="","",_xlfn.RANK.EQ(X13,X:X)) -> 1 | T13: =IF(V13="","",INDEX(D:D,MATCH(V13,F:F,0))) -> 尾張旭B | U13: =IF(V13="","",INDEX(E:E,MATCH(V13,F:F,0))) -> 28 | V13: =IF(COUNT(J:J)<ROW(B11),"",INDEX(F:F,SMALL(J:J,ROW(B11)))) -> 田中 沙紀子 | W13: =IF(V13="","",INDEX(H:H,MATCH(V13,F:F,0))) -> 0 | X13: =IF(V13="","",INDEX(AE:AE,MATCH(V13,AB:AB,0))) -> 0.1 | Z13: =IF(選手!B12="","",選手!B12) -> 西春日井A | AA13: =IF(選手!C12="","",選手!C12) -> 11 | AB13: =IF(選手!D12="","",選手!D12) -> 村瀬 沙織 | AC13: =IF(選手!E12="","",選手!E12) -> 女 | AD13: =記録!L5 -> 0 | AE13: =記録!L4 -> 0.1 | AF13: =AG13+COUNTIF(AG3:AG13,AG13)-1 -> 11 | AG13: =_xlfn.RANK.EQ(AE13,AE:AE) -> 1
B14: 12 | C14: =SMALL(AG:AG, B14) -> 1 | D14: =INDEX(Z:Z,MATCH(B14,AF:AF,0)) -> 西春日井A | E14: =INDEX(AA:AA,MATCH(B14,AF:AF,0)) -> 12 | F14: =INDEX(AB:AB,MATCH(B14,AF:AF,0)) -> 加藤 忠人 | G14: =INDEX(AC:AC,MATCH(B14,AF:AF,0)) -> 男 | H14: =INDEX(AD:AD,MATCH(F14,AB:AB,0)) -> 0 | I14: =IF($G14="男",ROW(),"") -> 14 | J14: =IF($G14="女",ROW(),"") | L14: =IF(O14="","",_xlfn.RANK.EQ(Q14,Q:Q)) -> 1 | M14: =IF(O14="","",INDEX(D:D,MATCH(O14,F:F,0))) -> 春日井A | N14: =IF(O14="","",INDEX(E:E,MATCH(O14,F:F,0))) -> 19 | O14: =IF(COUNT(I:I)<ROW(B12),"",INDEX(F:F,SMALL(I:I,ROW(B12)))) -> 玉野 正明 | P14: =IF(O14="","",INDEX(H:H,MATCH(O14,F:F,0))) -> 0 | Q14: =IF(O14="","",INDEX(AE:AE,MATCH(O14,AB:AB,0))) -> 0.1 | S14: =IF(V14="","",_xlfn.RANK.EQ(X14,X:X)) -> 1 | T14: =IF(V14="","",INDEX(D:D,MATCH(V14,F:F,0))) -> 日進B | U14: =IF(V14="","",INDEX(E:E,MATCH(V14,F:F,0))) -> 33 | V14: =IF(COUNT(J:J)<ROW(B12),"",INDEX(F:F,SMALL(J:J,ROW(B12)))) -> 三田村 静子 | W14: =IF(V14="","",INDEX(H:H,MATCH(V14,F:F,0))) -> 0 | X14: =IF(V14="","",INDEX(AE:AE,MATCH(V14,AB:AB,0))) -> 0.1 | Z14: =IF(選手!B13="","",選手!B13) -> 西春日井A | AA14: =IF(選手!C13="","",選手!C13) -> 12 | AB14: =IF(選手!D13="","",選手!D13) -> 加藤 忠人 | AC14: =IF(選手!E13="","",選手!E13) -> 男 | AD14: =記録!K5 -> 0 | AE14: =記録!K4 -> 0.1 | AF14: =AG14+COUNTIF(AG3:AG14,AG14)-1 -> 12 | AG14: =_xlfn.RANK.EQ(AE14,AE:AE) -> 1
B15: 13 | C15: =SMALL(AG:AG, B15) -> 1 | D15: =INDEX(Z:Z,MATCH(B15,AF:AF,0)) -> 西春日井B | E15: =INDEX(AA:AA,MATCH(B15,AF:AF,0)) -> 13 | F15: =INDEX(AB:AB,MATCH(B15,AF:AF,0)) -> 北崎 良治 | G15: =INDEX(AC:AC,MATCH(B15,AF:AF,0)) -> 男 | H15: =INDEX(AD:AD,MATCH(F15,AB:AB,0)) -> 0 | I15: =IF($G15="男",ROW(),"") -> 15 | J15: =IF($G15="女",ROW(),"") | L15: =IF(O15="","",_xlfn.RANK.EQ(Q15,Q:Q)) -> 1 | M15: =IF(O15="","",INDEX(D:D,MATCH(O15,F:F,0))) -> 春日井A | N15: =IF(O15="","",INDEX(E:E,MATCH(O15,F:F,0))) -> 20 | O15: =IF(COUNT(I:I)<ROW(B13),"",INDEX(F:F,SMALL(I:I,ROW(B13)))) -> 杉山 武 | P15: =IF(O15="","",INDEX(H:H,MATCH(O15,F:F,0))) -> 0 | Q15: =IF(O15="","",INDEX(AE:AE,MATCH(O15,AB:AB,0))) -> 0.1 | S15: =IF(V15="","",_xlfn.RANK.EQ(X15,X:X)) -> 1 | T15: =IF(V15="","",INDEX(D:D,MATCH(V15,F:F,0))) -> 日進B | U15: =IF(V15="","",INDEX(E:E,MATCH(V15,F:F,0))) -> 34 | V15: =IF(COUNT(J:J)<ROW(B13),"",INDEX(F:F,SMALL(J:J,ROW(B13)))) -> 浅井 明美 | W15: =IF(V15="","",INDEX(H:H,MATCH(V15,F:F,0))) -> 0 | X15: =IF(V15="","",INDEX(AE:AE,MATCH(V15,AB:AB,0))) -> 0.1 | Z15: =IF(選手!B14="","",選手!B14) -> 西春日井B | AA15: =IF(選手!C14="","",選手!C14) -> 13 | AB15: =IF(選手!D14="","",選手!D14) -> 北崎 良治 | AC15: =IF(選手!E14="","",選手!E14) -> 男 | AD15: =記録!J5 -> 0 | AE15: =記録!J4 -> 0.1 | AF15: =AG15+COUNTIF(AG3:AG15,AG15)-1 -> 13 | AG15: =_xlfn.RANK.EQ(AE15,AE:AE) -> 1
B16: 14 | C16: =SMALL(AG:AG, B16) -> 1 | D16: =INDEX(Z:Z,MATCH(B16,AF:AF,0)) -> 西春日井B | E16: =INDEX(AA:AA,MATCH(B16,AF:AF,0)) -> 14 | F16: =INDEX(AB:AB,MATCH(B16,AF:AF,0)) -> 渡邉 由美子 | G16: =INDEX(AC:AC,MATCH(B16,AF:AF,0)) -> 女 | H16: =INDEX(AD:AD,MATCH(F16,AB:AB,0)) -> 0 | I16: =IF($G16="男",ROW(),"") | J16: =IF($G16="女",ROW(),"") -> 16 | L16: =IF(O16="","",_xlfn.RANK.EQ(Q16,Q:Q)) -> 1 | M16: =IF(O16="","",INDEX(D:D,MATCH(O16,F:F,0))) -> 尾張旭A | N16: =IF(O16="","",INDEX(E:E,MATCH(O16,F:F,0))) -> 21 | O16: =IF(COUNT(I:I)<ROW(B14),"",INDEX(F:F,SMALL(I:I,ROW(B14)))) -> 大竹 誠 | P16: =IF(O16="","",INDEX(H:H,MATCH(O16,F:F,0))) -> 0 | Q16: =IF(O16="","",INDEX(AE:AE,MATCH(O16,AB:AB,0))) -> 0.1 | S16: =IF(V16="","",_xlfn.RANK.EQ(X16,X:X)) -> 1 | T16: =IF(V16="","",INDEX(D:D,MATCH(V16,F:F,0))) -> 日進B | U16: =IF(V16="","",INDEX(E:E,MATCH(V16,F:F,0))) -> 35 | V16: =IF(COUNT(J:J)<ROW(B14),"",INDEX(F:F,SMALL(J:J,ROW(B14)))) -> 谷口 洋子 | W16: =IF(V16="","",INDEX(H:H,MATCH(V16,F:F,0))) -> 0 | X16: =IF(V16="","",INDEX(AE:AE,MATCH(V16,AB:AB,0))) -> 0.1 | Z16: =IF(選手!B15="","",選手!B15) -> 西春日井B | AA16: =IF(選手!C15="","",選手!C15) -> 14 | AB16: =IF(選手!D15="","",選手!D15) -> 渡邉 由美子 | AC16: =IF(選手!E15="","",選手!E15) -> 女 | AD16: =記録!I5 -> 0 | AE16: =記録!I4 -> 0.1 | AF16: =AG16+COUNTIF(AG3:AG16,AG16)-1 -> 14 | AG16: =_xlfn.RANK.EQ(AE16,AE:AE) -> 1
B17: 15 | C17: =SMALL(AG:AG, B17) -> 1 | D17: =INDEX(Z:Z,MATCH(B17,AF:AF,0)) -> 西春日井B | E17: =INDEX(AA:AA,MATCH(B17,AF:AF,0)) -> 15 | F17: =INDEX(AB:AB,MATCH(B17,AF:AF,0)) -> 杉原 伸哉 | G17: =INDEX(AC:AC,MATCH(B17,AF:AF,0)) -> 男 | H17: =INDEX(AD:AD,MATCH(F17,AB:AB,0)) -> 0 | I17: =IF($G17="男",ROW(),"") -> 17 | J17: =IF($G17="女",ROW(),"") | L17: =IF(O17="","",_xlfn.RANK.EQ(Q17,Q:Q)) -> 1 | M17: =IF(O17="","",INDEX(D:D,MATCH(O17,F:F,0))) -> 尾張旭A | N17: =IF(O17="","",INDEX(E:E,MATCH(O17,F:F,0))) -> 22 | O17: =IF(COUNT(I:I)<ROW(B15),"",INDEX(F:F,SMALL(I:I,ROW(B15)))) -> 阿知波 正 | P17: =IF(O17="","",INDEX(H:H,MATCH(O17,F:F,0))) -> 0 | Q17: =IF(O17="","",INDEX(AE:AE,MATCH(O17,AB:AB,0))) -> 0.1 | S17: =IF(V17="","",_xlfn.RANK.EQ(X17,X:X)) -> 1 | T17: =IF(V17="","",INDEX(D:D,MATCH(V17,F:F,0))) -> 日進B | U17: =IF(V17="","",INDEX(E:E,MATCH(V17,F:F,0))) -> 36 | V17: =IF(COUNT(J:J)<ROW(B15),"",INDEX(F:F,SMALL(J:J,ROW(B15)))) -> 赤塚 正子 | W17: =IF(V17="","",INDEX(H:H,MATCH(V17,F:F,0))) -> 0 | X17: =IF(V17="","",INDEX(AE:AE,MATCH(V17,AB:AB,0))) -> 0.1 | Z17: =IF(選手!B16="","",選手!B16) -> 西春日井B | AA17: =IF(選手!C16="","",選手!C16) -> 15 | AB17: =IF(選手!D16="","",選手!D16) -> 杉原 伸哉 | AC17: =IF(選手!E16="","",選手!E16) -> 男 | AD17: =記録!H5 -> 0 | AE17: =記録!H4 -> 0.1 | AF17: =AG17+COUNTIF(AG3:AG17,AG17)-1 -> 15 | AG17: =_xlfn.RANK.EQ(AE17,AE:AE) -> 1
B18: 16 | C18: =SMALL(AG:AG, B18) -> 1 | D18: =INDEX(Z:Z,MATCH(B18,AF:AF,0)) -> 西春日井B | E18: =INDEX(AA:AA,MATCH(B18,AF:AF,0)) -> 16 | F18: =INDEX(AB:AB,MATCH(B18,AF:AF,0)) -> 荒川 花子 | G18: =INDEX(AC:AC,MATCH(B18,AF:AF,0)) -> 女 | H18: =INDEX(AD:AD,MATCH(F18,AB:AB,0)) -> 0 | I18: =IF($G18="男",ROW(),"") | J18: =IF($G18="女",ROW(),"") -> 18 | L18: =IF(O18="","",_xlfn.RANK.EQ(Q18,Q:Q)) -> 1 | M18: =IF(O18="","",INDEX(D:D,MATCH(O18,F:F,0))) -> 尾張旭A | N18: =IF(O18="","",INDEX(E:E,MATCH(O18,F:F,0))) -> 23 | O18: =IF(COUNT(I:I)<ROW(B16),"",INDEX(F:F,SMALL(I:I,ROW(B16)))) -> 山田 英治 | P18: =IF(O18="","",INDEX(H:H,MATCH(O18,F:F,0))) -> 0 | Q18: =IF(O18="","",INDEX(AE:AE,MATCH(O18,AB:AB,0))) -> 0.1 | S18: =IF(V18="","",_xlfn.RANK.EQ(X18,X:X)) -> 1 | T18: =IF(V18="","",INDEX(D:D,MATCH(V18,F:F,0))) -> 春日井B | U18: =IF(V18="","",INDEX(E:E,MATCH(V18,F:F,0))) -> 37 | V18: =IF(COUNT(J:J)<ROW(B16),"",INDEX(F:F,SMALL(J:J,ROW(B16)))) -> 遠藤 恵美子 | W18: =IF(V18="","",INDEX(H:H,MATCH(V18,F:F,0))) -> 0 | X18: =IF(V18="","",INDEX(AE:AE,MATCH(V18,AB:AB,0))) -> 0.1 | Z18: =IF(選手!B17="","",選手!B17) -> 西春日井B | AA18: =IF(選手!C17="","",選手!C17) -> 16 | AB18: =IF(選手!D17="","",選手!D17) -> 荒川 花子 | AC18: =IF(選手!E17="","",選手!E17) -> 女 | AD18: =記録!G5 -> 0 | AE18: =記録!G4 -> 0.1 | AF18: =AG18+COUNTIF(AG3:AG18,AG18)-1 -> 16 | AG18: =_xlfn.RANK.EQ(AE18,AE:AE) -> 1
B19: 17 | C19: =SMALL(AG:AG, B19) -> 1 | D19: =INDEX(Z:Z,MATCH(B19,AF:AF,0)) -> 春日井A | E19: =INDEX(AA:AA,MATCH(B19,AF:AF,0)) -> 17 | F19: =INDEX(AB:AB,MATCH(B19,AF:AF,0)) -> 小川 久生 | G19: =INDEX(AC:AC,MATCH(B19,AF:AF,0)) -> 男 | H19: =INDEX(AD:AD,MATCH(F19,AB:AB,0)) -> 0 | I19: =IF($G19="男",ROW(),"") -> 19 | J19: =IF($G19="女",ROW(),"") | L19: =IF(O19="","",_xlfn.RANK.EQ(Q19,Q:Q)) -> 1 | M19: =IF(O19="","",INDEX(D:D,MATCH(O19,F:F,0))) -> 尾張旭A | N19: =IF(O19="","",INDEX(E:E,MATCH(O19,F:F,0))) -> 24 | O19: =IF(COUNT(I:I)<ROW(B17),"",INDEX(F:F,SMALL(I:I,ROW(B17)))) -> 西尾 雅司 | P19: =IF(O19="","",INDEX(H:H,MATCH(O19,F:F,0))) -> 0 | Q19: =IF(O19="","",INDEX(AE:AE,MATCH(O19,AB:AB,0))) -> 0.1 | S19: =IF(V19="","",_xlfn.RANK.EQ(X19,X:X)) -> 1 | T19: =IF(V19="","",INDEX(D:D,MATCH(V19,F:F,0))) -> 春日井B | U19: =IF(V19="","",INDEX(E:E,MATCH(V19,F:F,0))) -> 38 | V19: =IF(COUNT(J:J)<ROW(B17),"",INDEX(F:F,SMALL(J:J,ROW(B17)))) -> 山口 このみ | W19: =IF(V19="","",INDEX(H:H,MATCH(V19,F:F,0))) -> 0 | X19: =IF(V19="","",INDEX(AE:AE,MATCH(V19,AB:AB,0))) -> 0.1 | Z19: =IF(選手!B18="","",選手!B18) -> 春日井A | AA19: =IF(選手!C18="","",選手!C18) -> 17 | AB19: =IF(選手!D18="","",選手!D18) -> 小川 久生 | AC19: =IF(選手!E18="","",選手!E18) -> 男 | AD19: =記録!F5 -> 0 | AE19: =記録!F4 -> 0.1 | AF19: =AG19+COUNTIF(AG3:AG19,AG19)-1 -> 17 | AG19: =_xlfn.RANK.EQ(AE19,AE:AE) -> 1
B20: 18 | C20: =SMALL(AG:AG, B20) -> 1 | D20: =INDEX(Z:Z,MATCH(B20,AF:AF,0)) -> 春日井A | E20: =INDEX(AA:AA,MATCH(B20,AF:AF,0)) -> 18 | F20: =INDEX(AB:AB,MATCH(B20,AF:AF,0)) -> 阿部 健二郞 | G20: =INDEX(AC:AC,MATCH(B20,AF:AF,0)) -> 男 | H20: =INDEX(AD:AD,MATCH(F20,AB:AB,0)) -> 0 | I20: =IF($G20="男",ROW(),"") -> 20 | J20: =IF($G20="女",ROW(),"") | L20: =IF(O20="","",_xlfn.RANK.EQ(Q20,Q:Q)) -> 1 | M20: =IF(O20="","",INDEX(D:D,MATCH(O20,F:F,0))) -> 日進A | N20: =IF(O20="","",INDEX(E:E,MATCH(O20,F:F,0))) -> 29 | O20: =IF(COUNT(I:I)<ROW(B18),"",INDEX(F:F,SMALL(I:I,ROW(B18)))) -> 志手 俊二 | P20: =IF(O20="","",INDEX(H:H,MATCH(O20,F:F,0))) -> 0 | Q20: =IF(O20="","",INDEX(AE:AE,MATCH(O20,AB:AB,0))) -> 0.1 | S20: =IF(V20="","",_xlfn.RANK.EQ(X20,X:X)) -> 1 | T20: =IF(V20="","",INDEX(D:D,MATCH(V20,F:F,0))) -> 春日井B | U20: =IF(V20="","",INDEX(E:E,MATCH(V20,F:F,0))) -> 39 | V20: =IF(COUNT(J:J)<ROW(B18),"",INDEX(F:F,SMALL(J:J,ROW(B18)))) -> 片桐 志保 | W20: =IF(V20="","",INDEX(H:H,MATCH(V20,F:F,0))) -> 0 | X20: =IF(V20="","",INDEX(AE:AE,MATCH(V20,AB:AB,0))) -> 0.1 | Z20: =IF(選手!B19="","",選手!B19) -> 春日井A | AA20: =IF(選手!C19="","",選手!C19) -> 18 | AB20: =IF(選手!D19="","",選手!D19) -> 阿部 健二郞 | AC20: =IF(選手!E19="","",選手!E19) -> 男 | AD20: =記録!E5 -> 0 | AE20: =記録!E4 -> 0.1 | AF20: =AG20+COUNTIF(AG3:AG20,AG20)-1 -> 18 | AG20: =_xlfn.RANK.EQ(AE20,AE:AE) -> 1
